Workbook
Name lookup_beazley_lob: data_beazley_summary!$D$2:INDEX(data_beazley_summary!$D:$D, COUNTA(data_beazley_summary!$D:$D))
Name lookup_lloyds_lob: data_lloyds_summary!$D$2:INDEX(data_lloyds_summary!$D:$D, COUNTA(data_lloyds_summary!$D:$D))
Name lookup_own_detail_label: own_detail[Label]
Name lookup_own_lob: data_oe_summary!$BP$2:INDEX(data_oe_summary!$BP:$BP, COUNTA(data_oe_summary!$BP:$BP))
Name lookup_own_lob2: data_oe_summary!$BP$2:INDEX(data_oe_summary!$BP:$BP, COUNTA(data_oe_summary!$BP:$BP))
Name lookup_own_summary_label: own_summary[Label]
Name lst_own_detail__name: own_detail[Name]
Name summary_actuary: Summary!$C$28
Name summary_analysis: Summary!$C$31
Name summary_deal_status: Summary!$C$9
Name summary_ded_str_1: Summary!$C$19
Name summary_ded_str_2: Summary!$C$20
Name summary_ded_str_3: Summary!$C$21
Name summary_ded_str_4: Summary!$C$22
Name summary_ded_str_5: Summary!$C$23
Name summary_ded_str_6: Summary!$C$24
Name summary_ded_str_7: Summary!$C$25
Name summary_expiry_date: Summary!$C$15
Name summary_export_date: Summary!$C$29
Name summary_facility_type: Summary!$C$8
Name summary_final_bpi: Summary!$F$8
Name summary_final_gn_ulr: Summary!$F$7
Name summary_final_loadings: Summary!$F$5
Name summary_final_pc: Summary!$F$6
Name summary_final_roc: Summary!$F$10
Name summary_final_tpi: Summary!$F$9
Name summary_gn_prem: Summary!$C$18
Name summary_hx_model_ref: Summary!$C$30
Name summary_inception_date: Summary!$C$14
Name summary_insured_name: Summary!$C$5
Name summary_key_lob: Summary!$C$10
Name summary_key_uncertainty: Summary!$C$27
Name summary_line_size: Summary!$C$16
Name summary_max_avg_limit: Summary!$C$17
Name summary_pc: Summary!$C$26
Name summary_policy_reference: Summary!$C$6
Name summary_raw_bpi: Summary!$G$8
Name summary_raw_gn_ulr: Summary!$G$7
Name summary_raw_pc: Summary!$G$6
Name summary_raw_roc: Summary!$G$10
Name summary_raw_tpi: Summary!$G$9
Name summary_renewal: Summary!$C$13
Name summary_risk_codes: Summary!$C$12
Name summary_trifocus: Summary!$C$11
Name summary_underwriter: Summary!$C$7
Name table_beazley_detail: data_beazley_detail!$A$2
Name table_beazley_summary: data_beazley_summary!$A$2
Name table_deductions: SummaryTables!$B$240
Name table_deductions_basis_all: SummaryTables!$I$292
Name table_deductions_basis_consortium: SummaryTables!$D$292
Name table_deductions_basis_facility: SummaryTables!$E$292
Name table_deductions_basis_leader_fee: SummaryTables!$F$292
Name table_deductions_basis_market: SummaryTables!$C$292
Name table_deductions_basis_other: SummaryTables!$H$292
Name table_deductions_basis_service_fee: SummaryTables!$G$292
Name table_deductions_total_all: SummaryTables!$I$290
Name table_deductions_total_consortium: SummaryTables!$D$290
Name table_deductions_total_facility: SummaryTables!$E$290
Name table_deductions_total_leader_fee: SummaryTables!$F$290
Name table_deductions_total_market: SummaryTables!$C$290

Sheet Summary
A1: MAP Risks > Portfolio Underwriting > HX Model Output
B2: Pricing Note Tables
B4: Key Risk Details | C4: Comments | E4: Pricing Outputs | F4: Pricing Basis | G4: Excluding Loads
B5: Insured | E5: Anti-Selection / Uncertainty / Other Chg / UW Adj | G5: - / - / - / -
B6: Policy Reference | E6: PC impact on GN ULR
B7: Underwriter | E7: GN ULR % net of PC
B8: Facility Type | E8: BPI %
B9: Deal Status | E9: TPI %
B10: key LOB | E10: RoC %
B11: Trifocus
B12: Lloyd's Risk Codes (Top 5)
B13: Renewal?
B14: Inception
B15: Expiry
B16: % Line Size
B17: 100% Max / Average Limit
B18: 5623 GN Premium
B19: Total Deductions
B26: Profit Commission
B27: Key Uncertainties
B28: Pricing Actuary
... B31: Analysis File

Sheet SummaryTables
A1: MAP Risks > Portfolio Underwriting > HX Model Output
B5: Model GN ULR by Methodology
E7: GN ULR % by method | H7: Weightings
B8: Class of Business | C8: GN Premium (BST Share) | D8: % of Portfolio" | E8: Own Experience | F8: Lloyds Risk Code Projections | G8: Business Plan | H8: Own Experience | I8: Lloyds Risk Code Projections | J8: Business Plan | K8: Case Pricing | L8: Beazley Projection | M8: Model GN ULR%¹
B59: Total
B60: 1 Excl. NMP loadings, Anti-Selection Charge, Uncertainty Loading, UW Adjustments and impact of the profit commission
B63: Selected ULR % Final
C65: Pricing Output
B66: Class of Business | C66: Model GN ULR%1 | D66: NMP Loading | E66: Climate Change Load | F66: Selected GN ULR%² | G66: Anti-Selection | H66: Uncertainty | I66: Additional Charge | J66: PC Impact on GN ULR | K66: UW Adjustment | L66: Selected GN ULR%3
B117: Total | C117: 0.89504948 | D117: 0 | E117: 0 | F117: 0.89504948 | G117: 0 | H117: 0 | I117: 0 | J117: 0 | K117: 0 | L117: 0.89504948
B118: 1 Excl. Anti-Selection, Uncertainty and NMP/Climate loads
B119: 2 Excl. Anti-selection and Uncertainty load; and after NMP/Climate loads
B120: 3 Incl. Anti-selection, Uncertainty and NMP/Climate load, any UW Adjustments; and Impact of the profit commission
B123: Technical adequacy metrics
D125: Including Anti-Selection, Uncertainty Loading and UW Adjustment | H125: Excluding Anti-Selection & Uncertainty Load and UW Adjustment
B126: Class of Business | C126: GN Premium | D126: Selected GN ULR % | E126: BPI% | F126: TPI% | G126: RoC % | H126: GN ULR% | I126: BPI% | J126: TPI% | K126: RoC %
B177: Total
B180: Premium and Limit Profile
C182: Premium and Line Size | H182: Limit Profile
B183: Class of Business | C183: 100% GG Ultimate Premium | D183: Line Size | E183: =YEAR(summary_inception_date)&" GG Premium (BST Share)" -> 1900 GG Premium (BST Share) | F183: Total deductions % | G183: =YEAR(summary_inception_date)&" GN Premium (BST Share)" -> 1900 GN Premium (BST Share) | H183: Maximum @ 100% | I183: Average Limit @ 100% | J183: Maximum Limit @ BST Share
B234: Total
B237: Deductions
B239: Class of Business | C239: Market Deductions | D239: Consortium Managers fee / MGA fee | E239: Facility Brokerage | F239: Leaders Fee | G239: Service Fee | H239: Other | I239: Total Deductions
B290: Total deductions
B292: Premium Basis
B295: Rate change
B297: Class of Business | C297: =YEAR(summary_inception_date) -> 1900 | D297: =C297-1 -> 1899 | E297: =D297-1 -> 1898 | F297: =E297-1 -> 1897 | G297: =F297-1 -> 1896 | H297: =G297-1 -> 1895 | I297: =H297-1 -> 1894 | J297: =I297-1 -> 1893 | K297: =J297-1 -> 1892
B348: Total
B351: Own Experience Performance
B353: Class of Business | C353: CAT Basis | D353: Attritional | E353: Large | F353: CAT | G353: Total | H353: Total (Excl. CAT)
B404: Overal selected
B407: Profit Commission Structure
B409: Class of Business | C409: Interlocking? | D409: Deficit | E409: PC on underlying binders? | F409: PC Type | G409: UW Expense | H409: UW Expense Basis | I409: PC %

Sheet Own Experience Analysis
A1: delete
C2: Own Experience Summary | M2: Selected | S2: Model Default | Y2: Overrides Used?
D3: =INDEX(own_summary[Label],MATCH(D4,own_summary[Name],0)) -> Selected Line of Business | F3: =INDEX(own_summary[Label],MATCH(F4,own_summary[Name],0)) -> Claim Source | H3: =INDEX(own_summary[Label],MATCH(H4,own_summary[Name],0)) -> Claim Basis | I3: =INDEX(own_summary[Label],MATCH(I4,own_summary[Name],0)) -> Claim to Develop to Ultimate | J3: =INDEX(own_summary[Label],MATCH(J4,own_summary[Name],0)) -> Cat Basis | K3: =INDEX(own_summary[Label],MATCH(K4,own_summary[Name],0)) -> IELR Method & Weights | M3: =INDEX(own_summary[Label],MATCH(M4,own_summary[Name],0)) -> Attritional | N3: =INDEX(own_summary[Label],MATCH(N4,own_summary[Name],0)) -> Large | O3: =INDEX(own_summary[Label],MATCH(O4,own_summary[Name],0)) -> Cat (on Selected Basis) | P3: =INDEX(own_summary[Label],MATCH(P4,own_summary[Name],0)) -> Total | Q3: =INDEX(own_summary[Label],MATCH(Q4,own_summary[Name],0)) -> Total (Excl. CAT) | S3: =INDEX(own_summary[Label],MATCH(S4,own_summary[Name],0)) -> Attritional | T3: =INDEX(own_summary[Label],MATCH(T4,own_summary[Name],0)) -> Large | U3: =INDEX(own_summary[Label],MATCH(U4,own_summary[Name],0)) -> Cat (on Selected Basis) | V3: =INDEX(own_summary[Label],MATCH(V4,own_summary[Name],0)) -> Total | W3: =INDEX(own_summary[Label],MATCH(W4,own_summary[Name],0)) -> Total (Excl. CAT) | Y3: =INDEX(own_summary[Label],MATCH(Y4,own_summary[Name],0)) -> Devt | Z3: =INDEX(own_summary[Label],MATCH(Z4,own_summary[Name],0)) -> Indices | AA3: =INDEX(own_summary[Label],MATCH(AA4,own_summary[Name],0)) -> Premium | AB3: =INDEX(own_summary[Label],MATCH(AB4,own_summary[Name],0)) -> IELR Wgt | AC3: =INDEX(own_summary[Label],MATCH(AC4,own_summary[Name],0)) -> IELR | AD3: =INDEX(own_summary[Label],MATCH(AD4,own_summary[Name],0)) -> IBNR add | AF3: =INDEX(own_summary[Label],MATCH(AF4,own_summary[Name],0)) -> Ult Mtd | AG3: =INDEX(own_summary[Label],MATCH(AG4,own_summary[Name],0)) -> Ult | AH3: =INDEX(own_summary[Label],MATCH(AH4,own_summary[Name],0)) -> ULR Wgt
C4: =COUNTA(data_oe_summary!A:A)-1 -> 0 | D4: selected_lob | F4: claim_source | H4: claim_basis | I4: claim_to_develop_to_ultimate | J4: cat_basis | K4: ielr_approach | M4: selected_attr | N4: selected_large | O4: selected_cat | P4: selected_total | Q4: selected_total_excl_cat | S4: model_default_attr | T4: model_default_large | U4: model_default_cat | V4: model_default_total | W4: model_default_total_excl_cat | Y4: ovd_dev | Z4: ovd_index | AA4: ovd_premium | AB4: ovd_ielr_weights | AC4: ovd_ielr | AD4: ovd_ibnr | AF4: ovd_ultimate_method | AG4: ovd_ultimate | AH4: ovd_ulr_weights | AI4: ovd_ulr
D5: =MATCH(D4,data_oe_summary!$1:$1,0) -> 68 | F5: =MATCH(F4,data_oe_summary!$1:$1,0) -> 1 | H5: =MATCH(H4,data_oe_summary!$1:$1,0) -> 2 | I5: =MATCH(I4,data_oe_summary!$1:$1,0) -> 3 | J5: =MATCH(J4,data_oe_summary!$1:$1,0) -> 4 | K5: =MATCH(K4,data_oe_summary!$1:$1,0) -> 5 | M5: =MATCH(M4,data_oe_summary!$1:$1,0) -> 34 | N5: =MATCH(N4,data_oe_summary!$1:$1,0) -> 35 | O5: =MATCH(O4,data_oe_summary!$1:$1,0) -> 36 | P5: =MATCH(P4,data_oe_summary!$1:$1,0) -> 37 | Q5: =MATCH(Q4,data_oe_summary!$1:$1,0) -> 38 | S5: =MATCH(S4,data_oe_summary!$1:$1,0) -> 43 | T5: =MATCH(T4,data_oe_summary!$1:$1,0) -> 44 | U5: =MATCH(U4,data_oe_summary!$1:$1,0) -> 45 | V5: =MATCH(V4,data_oe_summary!$1:$1,0) -> 46 | W5: =MATCH(W4,data_oe_summary!$1:$1,0) -> 47 | Y5: =MATCH(Y4,data_oe_summary!$1:$1,0) -> 52 | Z5: =MATCH(Z4,data_oe_summary!$1:$1,0) -> 53 | AA5: =MATCH(AA4,data_oe_summary!$1:$1,0) -> 54 | AB5: =MATCH(AB4,data_oe_summary!$1:$1,0) -> 55 | AC5: =MATCH(AC4,data_oe_summary!$1:$1,0) -> 56 | AD5: =MATCH(AD4,data_oe_summary!$1:$1,0) -> 57 | AF5: =MATCH(AF4,data_oe_summary!$1:$1,0) -> 58 | AG5: =MATCH(AG4,data_oe_summary!$1:$1,0) -> 59 | AH5: =MATCH(AH4,data_oe_summary!$1:$1,0) -> 60
C6: =IF($C$4<=MAX($C$5:C5),"",SUM(C5,1)) | D6: =IF($C6="","",OFFSET(data_oe_summary!$A$1,$C6,D$5-1)) | F6: =IF($C6="","",OFFSET(data_oe_summary!$A$1,$C6,F$5-1)) | H6: =IF($C6="","",OFFSET(data_oe_summary!$A$1,$C6,H$5-1)) | I6: =IF($C6="","",OFFSET(data_oe_summary!$A$1,$C6,I$5-1)) | J6: =IF($C6="","",OFFSET(data_oe_summary!$A$1,$C6,J$5-1)) | K6: =IF($C6="","",OFFSET(data_oe_summary!$A$1,$C6,K$5-1)) | M6: =IF($C6="","",OFFSET(data_oe_summary!$A$1,$C6,M$5-1)) | N6: =IF($C6="","",OFFSET(data_oe_summary!$A$1,$C6,N$5-1)) | O6: =IF($C6="","",OFFSET(data_oe_summary!$A$1,$C6,O$5-1)) | P6: =IF($C6="","",OFFSET(data_oe_summary!$A$1,$C6,P$5-1)) | Q6: =IF($C6="","",OFFSET(data_oe_summary!$A$1,$C6,Q$5-1)) | S6: =IF($C6="","",OFFSET(data_oe_summary!$A$1,$C6,S$5-1)) | T6: =IF($C6="","",OFFSET(data_oe_summary!$A$1,$C6,T$5-1)) | U6: =IF($C6="","",OFFSET(data_oe_summary!$A$1,$C6,U$5-1)) | V6: =IF($C6="","",OFFSET(data_oe_summary!$A$1,$C6,V$5-1)) | W6: =IF($C6="","",OFFSET(data_oe_summary!$A$1,$C6,W$5-1)) | Y6: =IF($C6="","",OFFSET(data_oe_summary!$A$1,$C6,Y$5-1)) | Z6: =IF($C6="","",OFFSET(data_oe_summary!$A$1,$C6,Z$5-1)) | AA6: =IF($C6="","",OFFSET(data_oe_summary!$A$1,$C6,AA$5-1)) | AB6: =IF($C6="","",OFFSET(data_oe_summary!$A$1,$C6,AB$5-1)) | AC6: =IF($C6="","",OFFSET(data_oe_summary!$A$1,$C6,AC$5-1)) | AD6: =IF($C6="","",OFFSET(data_oe_summary!$A$1,$C6,AD$5-1)) | AF6: =IF($C6="","",OFFSET(data_oe_summary!$A$1,$C6,AF$5-1)) | AG6: =IF($C6="","",OFFSET(data_oe_summary!$A$1,$C6,AG$5-1)) | AH6: =IF($C6="","",OFFSET(data_oe_summary!$A$1,$C6,AH$5-1))
C7: =IF($C$4<=MAX($C$5:C6),"",SUM(C6,1)) | D7: =IF($C7="","",OFFSET(data_oe_summary!$A$1,$C7,D$5-1)) | F7: =IF($C7="","",OFFSET(data_oe_summary!$A$1,$C7,F$5-1)) | H7: =IF($C7="","",OFFSET(data_oe_summary!$A$1,$C7,H$5-1)) | I7: =IF($C7="","",OFFSET(data_oe_summary!$A$1,$C7,I$5-1)) | J7: =IF($C7="","",OFFSET(data_oe_summary!$A$1,$C7,J$5-1)) | K7: =IF($C7="","",OFFSET(data_oe_summary!$A$1,$C7,K$5-1)) | M7: =IF($C7="","",OFFSET(data_oe_summary!$A$1,$C7,M$5-1)) | N7: =IF($C7="","",OFFSET(data_oe_summary!$A$1,$C7,N$5-1)) | O7: =IF($C7="","",OFFSET(data_oe_summary!$A$1,$C7,O$5-1)) | P7: =IF($C7="","",OFFSET(data_oe_summary!$A$1,$C7,P$5-1)) | Q7: =IF($C7="","",OFFSET(data_oe_summary!$A$1,$C7,Q$5-1)) | S7: =IF($C7="","",OFFSET(data_oe_summary!$A$1,$C7,S$5-1)) | T7: =IF($C7="","",OFFSET(data_oe_summary!$A$1,$C7,T$5-1)) | U7: =IF($C7="","",OFFSET(data_oe_summary!$A$1,$C7,U$5-1)) | V7: =IF($C7="","",OFFSET(data_oe_summary!$A$1,$C7,V$5-1)) | W7: =IF($C7="","",OFFSET(data_oe_summary!$A$1,$C7,W$5-1)) | Y7: =IF($C7="","",OFFSET(data_oe_summary!$A$1,$C7,Y$5-1)) | Z7: =IF($C7="","",OFFSET(data_oe_summary!$A$1,$C7,Z$5-1)) | AA7: =IF($C7="","",OFFSET(data_oe_summary!$A$1,$C7,AA$5-1)) | AB7: =IF($C7="","",OFFSET(data_oe_summary!$A$1,$C7,AB$5-1)) | AC7: =IF($C7="","",OFFSET(data_oe_summary!$A$1,$C7,AC$5-1)) | AD7: =IF($C7="","",OFFSET(data_oe_summary!$A$1,$C7,AD$5-1)) | AF7: =IF($C7="","",OFFSET(data_oe_summary!$A$1,$C7,AF$5-1)) | AG7: =IF($C7="","",OFFSET(data_oe_summary!$A$1,$C7,AG$5-1)) | AH7: =IF($C7="","",OFFSET(data_oe_summary!$A$1,$C7,AH$5-1))
C8: =IF($C$4<=MAX($C$5:C7),"",SUM(C7,1)) | D8: =IF($C8="","",OFFSET(data_oe_summary!$A$1,$C8,D$5-1)) | F8: =IF($C8="","",OFFSET(data_oe_summary!$A$1,$C8,F$5-1)) | H8: =IF($C8="","",OFFSET(data_oe_summary!$A$1,$C8,H$5-1)) | I8: =IF($C8="","",OFFSET(data_oe_summary!$A$1,$C8,I$5-1)) | J8: =IF($C8="","",OFFSET(data_oe_summary!$A$1,$C8,J$5-1)) | K8: =IF($C8="","",OFFSET(data_oe_summary!$A$1,$C8,K$5-1)) | M8: =IF($C8="","",OFFSET(data_oe_summary!$A$1,$C8,M$5-1)) | N8: =IF($C8="","",OFFSET(data_oe_summary!$A$1,$C8,N$5-1)) | O8: =IF($C8="","",OFFSET(data_oe_summary!$A$1,$C8,O$5-1)) | P8: =IF($C8="","",OFFSET(data_oe_summary!$A$1,$C8,P$5-1)) | Q8: =IF($C8="","",OFFSET(data_oe_summary!$A$1,$C8,Q$5-1)) | S8: =IF($C8="","",OFFSET(data_oe_summary!$A$1,$C8,S$5-1)) | T8: =IF($C8="","",OFFSET(data_oe_summary!$A$1,$C8,T$5-1)) | U8: =IF($C8="","",OFFSET(data_oe_summary!$A$1,$C8,U$5-1)) | V8: =IF($C8="","",OFFSET(data_oe_summary!$A$1,$C8,V$5-1)) | W8: =IF($C8="","",OFFSET(data_oe_summary!$A$1,$C8,W$5-1)) | Y8: =IF($C8="","",OFFSET(data_oe_summary!$A$1,$C8,Y$5-1)) | Z8: =IF($C8="","",OFFSET(data_oe_summary!$A$1,$C8,Z$5-1)) | AA8: =IF($C8="","",OFFSET(data_oe_summary!$A$1,$C8,AA$5-1)) | AB8: =IF($C8="","",OFFSET(data_oe_summary!$A$1,$C8,AB$5-1)) | AC8: =IF($C8="","",OFFSET(data_oe_summary!$A$1,$C8,AC$5-1)) | AD8: =IF($C8="","",OFFSET(data_oe_summary!$A$1,$C8,AD$5-1)) | AF8: =IF($C8="","",OFFSET(data_oe_summary!$A$1,$C8,AF$5-1)) | AG8: =IF($C8="","",OFFSET(data_oe_summary!$A$1,$C8,AG$5-1)) | AH8: =IF($C8="","",OFFSET(data_oe_summary!$A$1,$C8,AH$5-1))
C9: =IF($C$4<=MAX($C$5:C8),"",SUM(C8,1)) | D9: =IF($C9="","",OFFSET(data_oe_summary!$A$1,$C9,D$5-1)) | F9: =IF($C9="","",OFFSET(data_oe_summary!$A$1,$C9,F$5-1)) | H9: =IF($C9="","",OFFSET(data_oe_summary!$A$1,$C9,H$5-1)) | I9: =IF($C9="","",OFFSET(data_oe_summary!$A$1,$C9,I$5-1)) | J9: =IF($C9="","",OFFSET(data_oe_summary!$A$1,$C9,J$5-1)) | K9: =IF($C9="","",OFFSET(data_oe_summary!$A$1,$C9,K$5-1)) | M9: =IF($C9="","",OFFSET(data_oe_summary!$A$1,$C9,M$5-1)) | N9: =IF($C9="","",OFFSET(data_oe_summary!$A$1,$C9,N$5-1)) | O9: =IF($C9="","",OFFSET(data_oe_summary!$A$1,$C9,O$5-1)) | P9: =IF($C9="","",OFFSET(data_oe_summary!$A$1,$C9,P$5-1)) | Q9: =IF($C9="","",OFFSET(data_oe_summary!$A$1,$C9,Q$5-1)) | S9: =IF($C9="","",OFFSET(data_oe_summary!$A$1,$C9,S$5-1)) | T9: =IF($C9="","",OFFSET(data_oe_summary!$A$1,$C9,T$5-1)) | U9: =IF($C9="","",OFFSET(data_oe_summary!$A$1,$C9,U$5-1)) | V9: =IF($C9="","",OFFSET(data_oe_summary!$A$1,$C9,V$5-1)) | W9: =IF($C9="","",OFFSET(data_oe_summary!$A$1,$C9,W$5-1)) | Y9: =IF($C9="","",OFFSET(data_oe_summary!$A$1,$C9,Y$5-1)) | Z9: =IF($C9="","",OFFSET(data_oe_summary!$A$1,$C9,Z$5-1)) | AA9: =IF($C9="","",OFFSET(data_oe_summary!$A$1,$C9,AA$5-1)) | AB9: =IF($C9="","",OFFSET(data_oe_summary!$A$1,$C9,AB$5-1)) | AC9: =IF($C9="","",OFFSET(data_oe_summary!$A$1,$C9,AC$5-1)) | AD9: =IF($C9="","",OFFSET(data_oe_summary!$A$1,$C9,AD$5-1)) | AF9: =IF($C9="","",OFFSET(data_oe_summary!$A$1,$C9,AF$5-1)) | AG9: =IF($C9="","",OFFSET(data_oe_summary!$A$1,$C9,AG$5-1)) | AH9: =IF($C9="","",OFFSET(data_oe_summary!$A$1,$C9,AH$5-1))
C10: =IF($C$4<=MAX($C$5:C9),"",SUM(C9,1)) | D10: =IF($C10="","",OFFSET(data_oe_summary!$A$1,$C10,D$5-1)) | F10: =IF($C10="","",OFFSET(data_oe_summary!$A$1,$C10,F$5-1)) | H10: =IF($C10="","",OFFSET(data_oe_summary!$A$1,$C10,H$5-1)) | I10: =IF($C10="","",OFFSET(data_oe_summary!$A$1,$C10,I$5-1)) | J10: =IF($C10="","",OFFSET(data_oe_summary!$A$1,$C10,J$5-1)) | K10: =IF($C10="","",OFFSET(data_oe_summary!$A$1,$C10,K$5-1)) | M10: =IF($C10="","",OFFSET(data_oe_summary!$A$1,$C10,M$5-1)) | N10: =IF($C10="","",OFFSET(data_oe_summary!$A$1,$C10,N$5-1)) | O10: =IF($C10="","",OFFSET(data_oe_summary!$A$1,$C10,O$5-1)) | P10: =IF($C10="","",OFFSET(data_oe_summary!$A$1,$C10,P$5-1)) | Q10: =IF($C10="","",OFFSET(data_oe_summary!$A$1,$C10,Q$5-1)) | S10: =IF($C10="","",OFFSET(data_oe_summary!$A$1,$C10,S$5-1)) | T10: =IF($C10="","",OFFSET(data_oe_summary!$A$1,$C10,T$5-1)) | U10: =IF($C10="","",OFFSET(data_oe_summary!$A$1,$C10,U$5-1)) | V10: =IF($C10="","",OFFSET(data_oe_summary!$A$1,$C10,V$5-1)) | W10: =IF($C10="","",OFFSET(data_oe_summary!$A$1,$C10,W$5-1)) | Y10: =IF($C10="","",OFFSET(data_oe_summary!$A$1,$C10,Y$5-1)) | Z10: =IF($C10="","",OFFSET(data_oe_summary!$A$1,$C10,Z$5-1)) | AA10: =IF($C10="","",OFFSET(data_oe_summary!$A$1,$C10,AA$5-1)) | AB10: =IF($C10="","",OFFSET(data_oe_summary!$A$1,$C10,AB$5-1)) | AC10: =IF($C10="","",OFFSET(data_oe_summary!$A$1,$C10,AC$5-1)) | AD10: =IF($C10="","",OFFSET(data_oe_summary!$A$1,$C10,AD$5-1)) | AE10: =IF($C10="","",OFFSET(data_oe_summary!$A$1,$C10,AE$5-1)) | AF10: =IF($C10="","",OFFSET(data_oe_summary!$A$1,$C10,AF$5-1)) | ... AH10: =IF($C10="","",OFFSET(data_oe_summary!$A$1,$C10,AH$5-1))
C11: =IF($C$4<=MAX($C$5:C10),"",SUM(C10,1)) | D11: =IF($C11="","",OFFSET(data_oe_summary!$A$1,$C11,D$5-1)) | F11: =IF($C11="","",OFFSET(data_oe_summary!$A$1,$C11,F$5-1)) | H11: =IF($C11="","",OFFSET(data_oe_summary!$A$1,$C11,H$5-1)) | I11: =IF($C11="","",OFFSET(data_oe_summary!$A$1,$C11,I$5-1)) | J11: =IF($C11="","",OFFSET(data_oe_summary!$A$1,$C11,J$5-1)) | K11: =IF($C11="","",OFFSET(data_oe_summary!$A$1,$C11,K$5-1)) | M11: =IF($C11="","",OFFSET(data_oe_summary!$A$1,$C11,M$5-1)) | N11: =IF($C11="","",OFFSET(data_oe_summary!$A$1,$C11,N$5-1)) | O11: =IF($C11="","",OFFSET(data_oe_summary!$A$1,$C11,O$5-1)) | P11: =IF($C11="","",OFFSET(data_oe_summary!$A$1,$C11,P$5-1)) | Q11: =IF($C11="","",OFFSET(data_oe_summary!$A$1,$C11,Q$5-1)) | S11: =IF($C11="","",OFFSET(data_oe_summary!$A$1,$C11,S$5-1)) | T11: =IF($C11="","",OFFSET(data_oe_summary!$A$1,$C11,T$5-1)) | U11: =IF($C11="","",OFFSET(data_oe_summary!$A$1,$C11,U$5-1)) | V11: =IF($C11="","",OFFSET(data_oe_summary!$A$1,$C11,V$5-1)) | W11: =IF($C11="","",OFFSET(data_oe_summary!$A$1,$C11,W$5-1)) | Y11: =IF($C11="","",OFFSET(data_oe_summary!$A$1,$C11,Y$5-1)) | Z11: =IF($C11="","",OFFSET(data_oe_summary!$A$1,$C11,Z$5-1)) | AA11: =IF($C11="","",OFFSET(data_oe_summary!$A$1,$C11,AA$5-1)) | AB11: =IF($C11="","",OFFSET(data_oe_summary!$A$1,$C11,AB$5-1)) | AC11: =IF($C11="","",OFFSET(data_oe_summary!$A$1,$C11,AC$5-1)) | AD11: =IF($C11="","",OFFSET(data_oe_summary!$A$1,$C11,AD$5-1)) | AE11: =IF($C11="","",OFFSET(data_oe_summary!$A$1,$C11,AE$5-1)) | AF11: =IF($C11="","",OFFSET(data_oe_summary!$A$1,$C11,AF$5-1)) | ... AH11: =IF($C11="","",OFFSET(data_oe_summary!$A$1,$C11,AH$5-1))
C12: =IF($C$4<=MAX($C$5:C11),"",SUM(C11,1)) | D12: =IF($C12="","",OFFSET(data_oe_summary!$A$1,$C12,D$5-1)) | F12: =IF($C12="","",OFFSET(data_oe_summary!$A$1,$C12,F$5-1)) | H12: =IF($C12="","",OFFSET(data_oe_summary!$A$1,$C12,H$5-1)) | I12: =IF($C12="","",OFFSET(data_oe_summary!$A$1,$C12,I$5-1)) | J12: =IF($C12="","",OFFSET(data_oe_summary!$A$1,$C12,J$5-1)) | K12: =IF($C12="","",OFFSET(data_oe_summary!$A$1,$C12,K$5-1)) | M12: =IF($C12="","",OFFSET(data_oe_summary!$A$1,$C12,M$5-1)) | N12: =IF($C12="","",OFFSET(data_oe_summary!$A$1,$C12,N$5-1)) | O12: =IF($C12="","",OFFSET(data_oe_summary!$A$1,$C12,O$5-1)) | P12: =IF($C12="","",OFFSET(data_oe_summary!$A$1,$C12,P$5-1)) | Q12: =IF($C12="","",OFFSET(data_oe_summary!$A$1,$C12,Q$5-1)) | S12: =IF($C12="","",OFFSET(data_oe_summary!$A$1,$C12,S$5-1)) | T12: =IF($C12="","",OFFSET(data_oe_summary!$A$1,$C12,T$5-1)) | U12: =IF($C12="","",OFFSET(data_oe_summary!$A$1,$C12,U$5-1)) | V12: =IF($C12="","",OFFSET(data_oe_summary!$A$1,$C12,V$5-1)) | W12: =IF($C12="","",OFFSET(data_oe_summary!$A$1,$C12,W$5-1)) | Y12: =IF($C12="","",OFFSET(data_oe_summary!$A$1,$C12,Y$5-1)) | Z12: =IF($C12="","",OFFSET(data_oe_summary!$A$1,$C12,Z$5-1)) | AA12: =IF($C12="","",OFFSET(data_oe_summary!$A$1,$C12,AA$5-1)) | AB12: =IF($C12="","",OFFSET(data_oe_summary!$A$1,$C12,AB$5-1)) | AC12: =IF($C12="","",OFFSET(data_oe_summary!$A$1,$C12,AC$5-1)) | AD12: =IF($C12="","",OFFSET(data_oe_summary!$A$1,$C12,AD$5-1)) | AE12: =IF($C12="","",OFFSET(data_oe_summary!$A$1,$C12,AE$5-1)) | AF12: =IF($C12="","",OFFSET(data_oe_summary!$A$1,$C12,AF$5-1)) | ... AH12: =IF($C12="","",OFFSET(data_oe_summary!$A$1,$C12,AH$5-1))
C13: =IF($C$4<=MAX($C$5:C12),"",SUM(C12,1)) | D13: =IF($C13="","",OFFSET(data_oe_summary!$A$1,$C13,D$5-1)) | F13: =IF($C13="","",OFFSET(data_oe_summary!$A$1,$C13,F$5-1)) | H13: =IF($C13="","",OFFSET(data_oe_summary!$A$1,$C13,H$5-1)) | I13: =IF($C13="","",OFFSET(data_oe_summary!$A$1,$C13,I$5-1)) | J13: =IF($C13="","",OFFSET(data_oe_summary!$A$1,$C13,J$5-1)) | K13: =IF($C13="","",OFFSET(data_oe_summary!$A$1,$C13,K$5-1)) | M13: =IF($C13="","",OFFSET(data_oe_summary!$A$1,$C13,M$5-1)) | N13: =IF($C13="","",OFFSET(data_oe_summary!$A$1,$C13,N$5-1)) | O13: =IF($C13="","",OFFSET(data_oe_summary!$A$1,$C13,O$5-1)) | P13: =IF($C13="","",OFFSET(data_oe_summary!$A$1,$C13,P$5-1)) | Q13: =IF($C13="","",OFFSET(data_oe_summary!$A$1,$C13,Q$5-1)) | S13: =IF($C13="","",OFFSET(data_oe_summary!$A$1,$C13,S$5-1)) | T13: =IF($C13="","",OFFSET(data_oe_summary!$A$1,$C13,T$5-1)) | U13: =IF($C13="","",OFFSET(data_oe_summary!$A$1,$C13,U$5-1)) | V13: =IF($C13="","",OFFSET(data_oe_summary!$A$1,$C13,V$5-1)) | W13: =IF($C13="","",OFFSET(data_oe_summary!$A$1,$C13,W$5-1)) | Y13: =IF($C13="","",OFFSET(data_oe_summary!$A$1,$C13,Y$5-1)) | Z13: =IF($C13="","",OFFSET(data_oe_summary!$A$1,$C13,Z$5-1)) | AA13: =IF($C13="","",OFFSET(data_oe_summary!$A$1,$C13,AA$5-1)) | AB13: =IF($C13="","",OFFSET(data_oe_summary!$A$1,$C13,AB$5-1)) | AC13: =IF($C13="","",OFFSET(data_oe_summary!$A$1,$C13,AC$5-1)) | AD13: =IF($C13="","",OFFSET(data_oe_summary!$A$1,$C13,AD$5-1)) | AE13: =IF($C13="","",OFFSET(data_oe_summary!$A$1,$C13,AE$5-1)) | AF13: =IF($C13="","",OFFSET(data_oe_summary!$A$1,$C13,AF$5-1)) | ... AH13: =IF($C13="","",OFFSET(data_oe_summary!$A$1,$C13,AH$5-1))
C14: =IF($C$4<=MAX($C$5:C13),"",SUM(C13,1)) | D14: =IF($C14="","",OFFSET(data_oe_summary!$A$1,$C14,D$5-1)) | F14: =IF($C14="","",OFFSET(data_oe_summary!$A$1,$C14,F$5-1)) | H14: =IF($C14="","",OFFSET(data_oe_summary!$A$1,$C14,H$5-1)) | I14: =IF($C14="","",OFFSET(data_oe_summary!$A$1,$C14,I$5-1)) | J14: =IF($C14="","",OFFSET(data_oe_summary!$A$1,$C14,J$5-1)) | K14: =IF($C14="","",OFFSET(data_oe_summary!$A$1,$C14,K$5-1)) | M14: =IF($C14="","",OFFSET(data_oe_summary!$A$1,$C14,M$5-1)) | N14: =IF($C14="","",OFFSET(data_oe_summary!$A$1,$C14,N$5-1)) | O14: =IF($C14="","",OFFSET(data_oe_summary!$A$1,$C14,O$5-1)) | P14: =IF($C14="","",OFFSET(data_oe_summary!$A$1,$C14,P$5-1)) | Q14: =IF($C14="","",OFFSET(data_oe_summary!$A$1,$C14,Q$5-1)) | S14: =IF($C14="","",OFFSET(data_oe_summary!$A$1,$C14,S$5-1)) | T14: =IF($C14="","",OFFSET(data_oe_summary!$A$1,$C14,T$5-1)) | U14: =IF($C14="","",OFFSET(data_oe_summary!$A$1,$C14,U$5-1)) | V14: =IF($C14="","",OFFSET(data_oe_summary!$A$1,$C14,V$5-1)) | W14: =IF($C14="","",OFFSET(data_oe_summary!$A$1,$C14,W$5-1)) | Y14: =IF($C14="","",OFFSET(data_oe_summary!$A$1,$C14,Y$5-1)) | Z14: =IF($C14="","",OFFSET(data_oe_summary!$A$1,$C14,Z$5-1)) | AA14: =IF($C14="","",OFFSET(data_oe_summary!$A$1,$C14,AA$5-1)) | AB14: =IF($C14="","",OFFSET(data_oe_summary!$A$1,$C14,AB$5-1)) | AC14: =IF($C14="","",OFFSET(data_oe_summary!$A$1,$C14,AC$5-1)) | AD14: =IF($C14="","",OFFSET(data_oe_summary!$A$1,$C14,AD$5-1)) | AE14: =IF($C14="","",OFFSET(data_oe_summary!$A$1,$C14,AE$5-1)) | AF14: =IF($C14="","",OFFSET(data_oe_summary!$A$1,$C14,AF$5-1)) | ... AH14: =IF($C14="","",OFFSET(data_oe_summary!$A$1,$C14,AH$5-1))
C15: =IF($C$4<=MAX($C$5:C14),"",SUM(C14,1)) | D15: =IF($C15="","",OFFSET(data_oe_summary!$A$1,$C15,D$5-1)) | F15: =IF($C15="","",OFFSET(data_oe_summary!$A$1,$C15,F$5-1)) | H15: =IF($C15="","",OFFSET(data_oe_summary!$A$1,$C15,H$5-1)) | I15: =IF($C15="","",OFFSET(data_oe_summary!$A$1,$C15,I$5-1)) | J15: =IF($C15="","",OFFSET(data_oe_summary!$A$1,$C15,J$5-1)) | K15: =IF($C15="","",OFFSET(data_oe_summary!$A$1,$C15,K$5-1)) | M15: =IF($C15="","",OFFSET(data_oe_summary!$A$1,$C15,M$5-1)) | N15: =IF($C15="","",OFFSET(data_oe_summary!$A$1,$C15,N$5-1)) | O15: =IF($C15="","",OFFSET(data_oe_summary!$A$1,$C15,O$5-1)) | P15: =IF($C15="","",OFFSET(data_oe_summary!$A$1,$C15,P$5-1)) | Q15: =IF($C15="","",OFFSET(data_oe_summary!$A$1,$C15,Q$5-1)) | S15: =IF($C15="","",OFFSET(data_oe_summary!$A$1,$C15,S$5-1)) | T15: =IF($C15="","",OFFSET(data_oe_summary!$A$1,$C15,T$5-1)) | U15: =IF($C15="","",OFFSET(data_oe_summary!$A$1,$C15,U$5-1)) | V15: =IF($C15="","",OFFSET(data_oe_summary!$A$1,$C15,V$5-1)) | W15: =IF($C15="","",OFFSET(data_oe_summary!$A$1,$C15,W$5-1)) | Y15: =IF($C15="","",OFFSET(data_oe_summary!$A$1,$C15,Y$5-1)) | Z15: =IF($C15="","",OFFSET(data_oe_summary!$A$1,$C15,Z$5-1)) | AA15: =IF($C15="","",OFFSET(data_oe_summary!$A$1,$C15,AA$5-1)) | AB15: =IF($C15="","",OFFSET(data_oe_summary!$A$1,$C15,AB$5-1)) | AC15: =IF($C15="","",OFFSET(data_oe_summary!$A$1,$C15,AC$5-1)) | AD15: =IF($C15="","",OFFSET(data_oe_summary!$A$1,$C15,AD$5-1)) | AE15: =IF($C15="","",OFFSET(data_oe_summary!$A$1,$C15,AE$5-1)) | AF15: =IF($C15="","",OFFSET(data_oe_summary!$A$1,$C15,AF$5-1)) | ... AH15: =IF($C15="","",OFFSET(data_oe_summary!$A$1,$C15,AH$5-1))
C20: Selected LOB | E20: =D6
C22: LOB Settings | J22: Selected IELRs | O22: Model Default - IELR Approach Analysis
A23: claim_source | B23: =MATCH(A23,$93:$93,0)-1 -> 2 | C23: =INDEX(own_summary[Label],MATCH(A23,own_summary[Name],0)) -> Claim Source | E23: =IF(ISNA(B23),"",OFFSET($B$95,0,B23-1)) -> #N/A | H23: ielr_attr | I23: =MATCH(H23,$93:$93,0)-1 -> 7 | J23: =INDEX(own_summary[Label],MATCH(H23,own_summary[Name],0)) -> Attritional IELR | L23: =IF(ISNA(I23),"",OFFSET($B$95,0,I23-1)) -> #N/A | Q23: Nominal | R23: On-level All Yr | S23: On-level CL Yr
A24: claim_basis | B24: =MATCH(A24,$93:$93,0)-1 -> 3 | C24: =INDEX(own_summary[Label],MATCH(A24,own_summary[Name],0)) -> Claim Basis | E24: =IF(ISNA(B24),"",OFFSET($B$95,0,B24-1)) -> #N/A | H24: ielr_large | I24: =MATCH(H24,$93:$93,0)-1 -> 8 | J24: =INDEX(own_summary[Label],MATCH(H24,own_summary[Name],0)) -> Large IELR | L24: =IF(ISNA(I24),"",OFFSET($B$95,0,I24-1)) -> #N/A | O24: =INDEX(own_summary[Label],MATCH(U24,own_summary[Name],0)) -> Attritional IELR | Q24: =IF(ISNA(Z24),"",OFFSET($B$95,0,Z24-1)) -> #N/A | R24: =IF(ISNA(AA24),"",OFFSET($B$95,0,AA24-1)) -> #N/A | S24: =IF(ISNA(AB24),"",OFFSET($B$95,0,AB24-1)) -> #N/A | U24: ielr_nominal_attr | V24: ielr_ol_all_yr_attr | W24: ielr_ol_cl_yr_attr | Z24: =MATCH(U24,$93:$93,0)-1 -> 20 | AA24: =MATCH(V24,$93:$93,0)-1 -> 25 | AB24: =MATCH(W24,$93:$93,0)-1 -> 30
A25: claim_to_develop_to_ultimate | B25: =MATCH(A25,$93:$93,0)-1 -> 4 | C25: =INDEX(own_summary[Label],MATCH(A25,own_summary[Name],0)) -> Claim to Develop to Ultimate | E25: =IF(ISNA(B25),"",OFFSET($B$95,0,B25-1)) -> #N/A | H25: ielr_cat | I25: =MATCH(H25,$93:$93,0)-1 -> 9 | J25: =INDEX(own_summary[Label],MATCH(H25,own_summary[Name],0)) -> CAT IELR | L25: =IF(ISNA(I25),"",OFFSET($B$95,0,I25-1)) -> #N/A | O25: =INDEX(own_summary[Label],MATCH(U25,own_summary[Name],0)) -> Large IELR | Q25: =IF(ISNA(Z25),"",OFFSET($B$95,0,Z25-1)) -> #N/A | R25: =IF(ISNA(AA25),"",OFFSET($B$95,0,AA25-1)) -> #N/A | S25: =IF(ISNA(AB25),"",OFFSET($B$95,0,AB25-1)) -> #N/A | U25: ielr_nominal_large | V25: ielr_ol_all_yr_large | W25: ielr_ol_cl_yr_large | Z25: =MATCH(U25,$93:$93,0)-1 -> 21 | AA25: =MATCH(V25,$93:$93,0)-1 -> 26 | AB25: =MATCH(W25,$93:$93,0)-1 -> 31
A26: cat_basis | B26: =MATCH(A26,$93:$93,0)-1 -> 5 | C26: =INDEX(own_summary[Label],MATCH(A26,own_summary[Name],0)) -> Cat Basis | E26: =IF(ISNA(B26),"",OFFSET($B$95,0,B26-1)) -> #N/A | H26: ielr_total | I26: =MATCH(H26,$93:$93,0)-1 -> 10 | J26: =INDEX(own_summary[Label],MATCH(H26,own_summary[Name],0)) -> Total IELR | L26: =IF(ISNA(I26),"",OFFSET($B$95,0,I26-1)) -> #N/A | O26: =INDEX(own_summary[Label],MATCH(U26,own_summary[Name],0)) -> CAT IELR | Q26: =IF(ISNA(Z26),"",OFFSET($B$95,0,Z26-1)) -> #N/A | R26: =IF(ISNA(AA26),"",OFFSET($B$95,0,AA26-1)) -> #N/A | S26: =IF(ISNA(AB26),"",OFFSET($B$95,0,AB26-1)) -> #N/A | U26: ielr_nominal_cat | V26: ielr_ol_all_yr_cat | W26: ielr_ol_cl_yr_cat | Z26: =MATCH(U26,$93:$93,0)-1 -> 22 | AA26: =MATCH(V26,$93:$93,0)-1 -> 27 | AB26: =MATCH(W26,$93:$93,0)-1 -> 32
A27: ielr_approach | B27: =MATCH(A27,$93:$93,0)-1 -> 6 | C27: =INDEX(own_summary[Label],MATCH(A27,own_summary[Name],0)) -> IELR Method & Weights | E27: =IF(ISNA(B27),"",OFFSET($B$95,0,B27-1)) -> #N/A | H27: ielr_total_excl_cat | I27: =MATCH(H27,$93:$93,0)-1 -> 11 | J27: =INDEX(own_summary[Label],MATCH(H27,own_summary[Name],0)) -> Total (Excl. CAT) IELR | L27: =IF(ISNA(I27),"",OFFSET($B$95,0,I27-1)) -> #N/A | O27: =INDEX(own_summary[Label],MATCH(U27,own_summary[Name],0)) -> Total IELR | Q27: =IF(ISNA(Z27),"",OFFSET($B$95,0,Z27-1)) -> #N/A | R27: =IF(ISNA(AA27),"",OFFSET($B$95,0,AA27-1)) -> #N/A | S27: =IF(ISNA(AB27),"",OFFSET($B$95,0,AB27-1)) -> #N/A | U27: ielr_nominal_total | V27: ielr_ol_all_yr_total | W27: ielr_ol_cl_yr_total | Z27: =MATCH(U27,$93:$93,0)-1 -> 23 | AA27: =MATCH(V27,$93:$93,0)-1 -> 28 | AB27: =MATCH(W27,$93:$93,0)-1 -> 33
H28: lloyds_selected_ielr | I28: =MATCH(H28,$93:$93,0)-1 -> 14 | J28: =INDEX(own_summary[Label],MATCH(H28,own_summary[Name],0)) -> Lloyds Selected IELR | L28: =IF(ISNA(I28),"",OFFSET($B$95,0,I28-1)) -> #N/A | O28: =INDEX(own_summary[Label],MATCH(U28,own_summary[Name],0)) -> Total (Excl. CAT) IELR | Q28: =IF(ISNA(Z28),"",OFFSET($B$95,0,Z28-1)) -> #N/A | R28: =IF(ISNA(AA28),"",OFFSET($B$95,0,AA28-1)) -> #N/A | S28: =IF(ISNA(AB28),"",OFFSET($B$95,0,AB28-1)) -> #N/A | U28: ielr_nominal_total_excl_cat | V28: ielr_ol_all_yr_total_excl_cat | W28: ielr_ol_cl_yr_total_excl_cat | Z28: =MATCH(U28,$93:$93,0)-1 -> 24 | AA28: =MATCH(V28,$93:$93,0)-1 -> 29 | AB28: =MATCH(W28,$93:$93,0)-1 -> 34
B31: hx name | C31: yoa | D31: latest_gpi | E31: latest_gnpi | F31: acquisition_costs | G31: latest_incurred_open_claims_attr | H31: latest_incurred_open_claims_large | I31: latest_incurred_open_claims_cat | J31: latest_incurred_open_claims_total | K31: latest_incurred_closed_claims_attr | L31: latest_incurred_closed_claims_large | M31: latest_incurred_closed_claims_cat | N31: latest_incurred_closed_claims_total | O31: latest_incurred_total_claims_attr | P31: latest_incurred_total_claims_large | Q31: latest_incurred_total_claims_cat | R31: latest_incurred_total_claims_total | S31: last_year_position_attr | T31: last_year_position_large | U31: last_year_position_cat | V31: last_year_position_total | W31: movement_attr | X31: movement_large | Y31: movement_cat | Z31: movement_total | AA31: gn_ilr_attr | AB31: gn_ilr_large | AC31: gn_ilr_cat | AD31: gn_ilr_total | AE31: null, | AF31: applied_rate_change | AG31: applied_inflation | AH31: applied_rate_change_cumulative | AI31: applied_inflation_cumulative | AJ31: onlevel_factor_cumulative | AK31: ul | AL31: development_pattern_premium_lloyds_unadjusted | AM31: development_pattern_paid_lloyds_unadjusted | AN31: development_pattern_incurred_lloyds_unadjusted | AO31: development_pattern_premium_lloyds | AP31: development_pattern_incurred_lloyds | AQ31: development_pattern_premium_override | AR31: development_pattern_incurred_override | AS31: development_pattern_premium_selected | AT31: development_pattern_incurred_selected | AU31: ul | AV31: ultimate_premium_selected_gnpi_cl | AW31: ultimate_premium_selected_gnpi_override | AX31: ultimate_premium_selected_gnpi_selected | AY31: ultimate_premium_selected_gnpi_selected_ol | AZ31: ultimate_incurred_cl_attr | BA31: ultimate_incurred_cl_large | BB31: ultimate_incurred_cl_cat | BC31: ultimate_incurred_cl_total | BD31: ultimate_incurred_cl_ielr | BE31: ultimate_incurred_ielr_attr | BF31: ultimate_incurred_ielr_large | BG31: ultimate_incurred_ielr_cat | BH31: ultimate_incurred_ielr_total | BI31: ultimate_incurred_bf_attr | BJ31: ultimate_incurred_bf_large | BK31: ultimate_incurred_bf_cat | BL31: ultimate_incurred_bf_total | BM31: ielr_weighting_cl_attr | BN31: ielr_weighting_cl_large | BO31: ielr_weighting_cl_cat | BP31: ielr_weighting_cl_total | BQ31: method_incurred | BR31: additional_ibnr_attr | BS31: additional_ibnr_large | BT31: additional_ibnr_cat | BU31: additional_ibnr_total | BV31: ultimate_incurred_selected_attr | BW31: ultimate_incurred_selected_large | BX31: ultimate_incurred_selected_cat | BY31: ultimate_incurred_selected_total | BZ31: ultimate_incurred_selected_total_x_cat | CA31: ultimate_ulr_selected_attr | CB31: ultimate_ulr_selected_large | CC31: ultimate_ulr_selected_cat | CD31: ultimate_ulr_selected_total | CE31: ultimate_ulr_selected_total_x_cat | CF31: ul | CG31: ultimate_ulr_on_levelled_attr | CH31: ultimate_ulr_on_levelled_large | CI31: ultimate_ulr_on_levelled_cat | CJ31: ultimate_ulr_on_levelled_total | CK31: ultimate_ulr_on_levelled_total_x_cat | CL31: ul | CM31: modelled_weighting | CN31: ielr_weighting_sel_attr | CO31: ielr_weighting_sel_large | CP31: ielr_weighting_sel_cat | CQ31: ielr_weighting_sel_total | CR31: ul | CS31: exposure_weighting_onlevel_1 | CT31: decay_ratio_weighting_2 | CU31: developed_weighting_3 | CV31: overall_weighting_onlevel | CW31: ul | CX31: exposure_weighting_nominal_1 | CY31: overall_weighting_nominal | CZ31: ul | DA31: adjustments_actual | DB31: adjustments_lower | DC31: adjustments_upper | DD31: adjustments_prem_lloyds_lower | DE31: adjustments_prem_lloyds_upper | DF31: adjustments_prem_lloyds_actual | DG31: adjustments_incurred_lloyds_lower | DH31: adjustments_incurred_lloyds_upper | DI31: adjustments_incurred_lloyds_actual | DJ31: adjustments_incurred_lloyds_actual
B32: Match Detail | C32: =MATCH(C31,99:99,0)-1 -> 4 | D32: =MATCH(D31,99:99,0)-1 -> 5 | E32: =MATCH(E31,99:99,0)-1 -> 6 | F32: =MATCH(F31,99:99,0)-1 -> 7 | G32: =MATCH(G31,99:99,0)-1 -> 21 | H32: =MATCH(H31,99:99,0)-1 -> 35 | I32: =MATCH(I31,99:99,0)-1 -> 49 | J32: =MATCH(J31,99:99,0)-1 -> 63 | ... DJ32: =MATCH(DJ31,99:99,0)-1 -> 111
B33: Match Summary | C33: =MATCH(C31,93:93,0)-1 -> 70 | D33: =MATCH(D31,93:93,0)-1 -> 71 | E33: =MATCH(E31,93:93,0)-1 -> 72 | F33: =MATCH(F31,93:93,0)-1 -> 73 | G33: =MATCH(G31,93:93,0)-1 -> 87 | H33: =MATCH(H31,93:93,0)-1 -> 99 | I33: =MATCH(I31,93:93,0)-1 -> 111 | J33: =MATCH(J31,93:93,0)-1 -> 123 | ... DJ33: =MATCH(DJ31,93:93,0)-1 -> #N/A
D35: Premium Current Position | G35: Open Incurred Claims (undeveloped) | K35: Closed Incurred Claims (undeveloped) | O35: Total Incurred Claims (undeveloped) | S35: Last Year's Position | W35: Movement | AA35: GN ILR % | AF35: Incremental Indices | AH35: Cumulative Indices | AL35: Development Pattern | AV35: Ultimate Premium - Selected | AZ35: CL - Ultimate Incurred | BE35: IELR - Ultimate Incurred | BI35: BF - Ultimate Incurred | BM35: IELR Weighting | BQ35: ="" | BR35: Additional IBNR (Additive to Ultimate Incurred - Selected) | BV35: Selected Ultimate | CA35: Selected ULR | CG35: On-Levelled | CN35: Selected Model Weighting | CS35: Weighting On-level | CX35: Weighting Nominal | DA35: Adjustments
C36: =IFERROR(INDEX(own_detail[Label],MATCH(C$31,own_detail[Name],0)),"") -> YoA | D36: =IFERROR(INDEX(own_detail[Label],MATCH(D$31,own_detail[Name],0)),"") -> Latest GPI | E36: =IFERROR(INDEX(own_detail[Label],MATCH(E$31,own_detail[Name],0)),"") -> Latest GNPI | F36: =IFERROR(INDEX(own_detail[Label],MATCH(F$31,own_detail[Name],0)),"") -> Acquisition Costs % | G36: =IFERROR(INDEX(own_detail[Label],MATCH(G$31,own_detail[Name],0)),"") -> Attritional | H36: =IFERROR(INDEX(own_detail[Label],MATCH(H$31,own_detail[Name],0)),"") -> Large | I36: =IFERROR(INDEX(own_detail[Label],MATCH(I$31,own_detail[Name],0)),"") -> Cat | J36: =IFERROR(INDEX(own_detail[Label],MATCH(J$31,own_detail[Name],0)),"") -> Total | ... DJ36: =IFERROR(INDEX(own_detail[Label],MATCH(DJ$31,own_detail[Name],0)),"") -> Incurred Lloyds Actual
B37: Detail row 1 | C37: =IF(ISNA(C$32),"",OFFSET($B101,0,C$32-1)) -> #N/A | D37: =IF(ISNA(D$32),"",OFFSET($B101,0,D$32-1)) -> #N/A | E37: =IF(ISNA(E$32),"",OFFSET($B101,0,E$32-1)) -> #N/A | F37: =IF(ISNA(F$32),"",OFFSET($B101,0,F$32-1)) -> #N/A | G37: =IF(ISNA(G$32),"",OFFSET($B101,0,G$32-1)) -> #N/A | H37: =IF(ISNA(H$32),"",OFFSET($B101,0,H$32-1)) -> #N/A | I37: =IF(ISNA(I$32),"",OFFSET($B101,0,I$32-1)) -> #N/A | J37: =IF(ISNA(J$32),"",OFFSET($B101,0,J$32-1)) -> #N/A | ... DJ37: =IF(ISNA(DJ$32),"",OFFSET($B101,0,DJ$32-1)) -> #N/A
B38: Detail row 2 | C38: =IF(ISNA(C$32),"",OFFSET($B102,0,C$32-1)) -> #N/A | D38: =IF(ISNA(D$32),"",OFFSET($B102,0,D$32-1)) -> #N/A | E38: =IF(ISNA(E$32),"",OFFSET($B102,0,E$32-1)) -> #N/A | F38: =IF(ISNA(F$32),"",OFFSET($B102,0,F$32-1)) -> #N/A | G38: =IF(ISNA(G$32),"",OFFSET($B102,0,G$32-1)) -> #N/A | H38: =IF(ISNA(H$32),"",OFFSET($B102,0,H$32-1)) -> #N/A | I38: =IF(ISNA(I$32),"",OFFSET($B102,0,I$32-1)) -> #N/A | J38: =IF(ISNA(J$32),"",OFFSET($B102,0,J$32-1)) -> #N/A | ... DJ38: =IF(ISNA(DJ$32),"",OFFSET($B102,0,DJ$32-1)) -> #N/A
B39: Detail row 3 | C39: =IF(ISNA(C$32),"",OFFSET($B103,0,C$32-1)) -> #N/A | D39: =IF(ISNA(D$32),"",OFFSET($B103,0,D$32-1)) -> #N/A | E39: =IF(ISNA(E$32),"",OFFSET($B103,0,E$32-1)) -> #N/A | F39: =IF(ISNA(F$32),"",OFFSET($B103,0,F$32-1)) -> #N/A | G39: =IF(ISNA(G$32),"",OFFSET($B103,0,G$32-1)) -> #N/A | H39: =IF(ISNA(H$32),"",OFFSET($B103,0,H$32-1)) -> #N/A | I39: =IF(ISNA(I$32),"",OFFSET($B103,0,I$32-1)) -> #N/A | J39: =IF(ISNA(J$32),"",OFFSET($B103,0,J$32-1)) -> #N/A | ... DJ39: =IF(ISNA(DJ$32),"",OFFSET($B103,0,DJ$32-1)) -> #N/A
B40: Detail row 4 | C40: =IF(ISNA(C$32),"",OFFSET($B104,0,C$32-1)) -> #N/A | D40: =IF(ISNA(D$32),"",OFFSET($B104,0,D$32-1)) -> #N/A | E40: =IF(ISNA(E$32),"",OFFSET($B104,0,E$32-1)) -> #N/A | F40: =IF(ISNA(F$32),"",OFFSET($B104,0,F$32-1)) -> #N/A | G40: =IF(ISNA(G$32),"",OFFSET($B104,0,G$32-1)) -> #N/A | H40: =IF(ISNA(H$32),"",OFFSET($B104,0,H$32-1)) -> #N/A | I40: =IF(ISNA(I$32),"",OFFSET($B104,0,I$32-1)) -> #N/A | J40: =IF(ISNA(J$32),"",OFFSET($B104,0,J$32-1)) -> #N/A | ... DJ40: =IF(ISNA(DJ$32),"",OFFSET($B104,0,DJ$32-1)) -> #N/A
B41: Detail row 5 | C41: =IF(ISNA(C$32),"",OFFSET($B105,0,C$32-1)) -> #N/A | D41: =IF(ISNA(D$32),"",OFFSET($B105,0,D$32-1)) -> #N/A | E41: =IF(ISNA(E$32),"",OFFSET($B105,0,E$32-1)) -> #N/A | F41: =IF(ISNA(F$32),"",OFFSET($B105,0,F$32-1)) -> #N/A | G41: =IF(ISNA(G$32),"",OFFSET($B105,0,G$32-1)) -> #N/A | H41: =IF(ISNA(H$32),"",OFFSET($B105,0,H$32-1)) -> #N/A | I41: =IF(ISNA(I$32),"",OFFSET($B105,0,I$32-1)) -> #N/A | J41: =IF(ISNA(J$32),"",OFFSET($B105,0,J$32-1)) -> #N/A | ... DJ41: =IF(ISNA(DJ$32),"",OFFSET($B105,0,DJ$32-1)) -> #N/A
B42: Detail row 6 | C42: =IF(ISNA(C$32),"",OFFSET($B106,0,C$32-1)) -> #N/A | D42: =IF(ISNA(D$32),"",OFFSET($B106,0,D$32-1)) -> #N/A | E42: =IF(ISNA(E$32),"",OFFSET($B106,0,E$32-1)) -> #N/A | F42: =IF(ISNA(F$32),"",OFFSET($B106,0,F$32-1)) -> #N/A | G42: =IF(ISNA(G$32),"",OFFSET($B106,0,G$32-1)) -> #N/A | H42: =IF(ISNA(H$32),"",OFFSET($B106,0,H$32-1)) -> #N/A | I42: =IF(ISNA(I$32),"",OFFSET($B106,0,I$32-1)) -> #N/A | J42: =IF(ISNA(J$32),"",OFFSET($B106,0,J$32-1)) -> #N/A | ... DJ42: =IF(ISNA(DJ$32),"",OFFSET($B106,0,DJ$32-1)) -> #N/A
B43: Detail row 7 | C43: =IF(ISNA(C$32),"",OFFSET($B107,0,C$32-1)) -> #N/A | D43: =IF(ISNA(D$32),"",OFFSET($B107,0,D$32-1)) -> #N/A | E43: =IF(ISNA(E$32),"",OFFSET($B107,0,E$32-1)) -> #N/A | F43: =IF(ISNA(F$32),"",OFFSET($B107,0,F$32-1)) -> #N/A | G43: =IF(ISNA(G$32),"",OFFSET($B107,0,G$32-1)) -> #N/A | H43: =IF(ISNA(H$32),"",OFFSET($B107,0,H$32-1)) -> #N/A | I43: =IF(ISNA(I$32),"",OFFSET($B107,0,I$32-1)) -> #N/A | J43: =IF(ISNA(J$32),"",OFFSET($B107,0,J$32-1)) -> #N/A | ... DJ43: =IF(ISNA(DJ$32),"",OFFSET($B107,0,DJ$32-1)) -> #N/A
B44: Detail row 8 | C44: =IF(ISNA(C$32),"",OFFSET($B108,0,C$32-1)) -> #N/A | D44: =IF(ISNA(D$32),"",OFFSET($B108,0,D$32-1)) -> #N/A | E44: =IF(ISNA(E$32),"",OFFSET($B108,0,E$32-1)) -> #N/A | F44: =IF(ISNA(F$32),"",OFFSET($B108,0,F$32-1)) -> #N/A | G44: =IF(ISNA(G$32),"",OFFSET($B108,0,G$32-1)) -> #N/A | H44: =IF(ISNA(H$32),"",OFFSET($B108,0,H$32-1)) -> #N/A | I44: =IF(ISNA(I$32),"",OFFSET($B108,0,I$32-1)) -> #N/A | J44: =IF(ISNA(J$32),"",OFFSET($B108,0,J$32-1)) -> #N/A | ... DJ44: =IF(ISNA(DJ$32),"",OFFSET($B108,0,DJ$32-1)) -> #N/A
B45: Detail row 9 | C45: =IF(ISNA(C$32),"",OFFSET($B109,0,C$32-1)) -> #N/A | D45: =IF(ISNA(D$32),"",OFFSET($B109,0,D$32-1)) -> #N/A | E45: =IF(ISNA(E$32),"",OFFSET($B109,0,E$32-1)) -> #N/A | F45: =IF(ISNA(F$32),"",OFFSET($B109,0,F$32-1)) -> #N/A | G45: =IF(ISNA(G$32),"",OFFSET($B109,0,G$32-1)) -> #N/A | H45: =IF(ISNA(H$32),"",OFFSET($B109,0,H$32-1)) -> #N/A | I45: =IF(ISNA(I$32),"",OFFSET($B109,0,I$32-1)) -> #N/A | J45: =IF(ISNA(J$32),"",OFFSET($B109,0,J$32-1)) -> #N/A | ... DJ45: =IF(ISNA(DJ$32),"",OFFSET($B109,0,DJ$32-1)) -> #N/A
B46: Detail row 10 | C46: =IF(ISNA(C$32),"",OFFSET($B110,0,C$32-1)) -> #N/A | D46: =IF(ISNA(D$32),"",OFFSET($B110,0,D$32-1)) -> #N/A | E46: =IF(ISNA(E$32),"",OFFSET($B110,0,E$32-1)) -> #N/A | F46: =IF(ISNA(F$32),"",OFFSET($B110,0,F$32-1)) -> #N/A | G46: =IF(ISNA(G$32),"",OFFSET($B110,0,G$32-1)) -> #N/A | H46: =IF(ISNA(H$32),"",OFFSET($B110,0,H$32-1)) -> #N/A | I46: =IF(ISNA(I$32),"",OFFSET($B110,0,I$32-1)) -> #N/A | J46: =IF(ISNA(J$32),"",OFFSET($B110,0,J$32-1)) -> #N/A | ... DJ46: =IF(ISNA(DJ$32),"",OFFSET($B110,0,DJ$32-1)) -> #N/A
B47: Detail row 11 | C47: =IF(ISNA(C$32),"",OFFSET($B111,0,C$32-1)) -> #N/A | D47: =IF(ISNA(D$32),"",OFFSET($B111,0,D$32-1)) -> #N/A | E47: =IF(ISNA(E$32),"",OFFSET($B111,0,E$32-1)) -> #N/A | F47: =IF(ISNA(F$32),"",OFFSET($B111,0,F$32-1)) -> #N/A | G47: =IF(ISNA(G$32),"",OFFSET($B111,0,G$32-1)) -> #N/A | H47: =IF(ISNA(H$32),"",OFFSET($B111,0,H$32-1)) -> #N/A | I47: =IF(ISNA(I$32),"",OFFSET($B111,0,I$32-1)) -> #N/A | J47: =IF(ISNA(J$32),"",OFFSET($B111,0,J$32-1)) -> #N/A | ... DJ47: =IF(ISNA(DJ$32),"",OFFSET($B111,0,DJ$32-1)) -> #N/A
B48: Detail row 12 | C48: =IF(ISNA(C$32),"",OFFSET($B112,0,C$32-1)) -> #N/A | D48: =IF(ISNA(D$32),"",OFFSET($B112,0,D$32-1)) -> #N/A | E48: =IF(ISNA(E$32),"",OFFSET($B112,0,E$32-1)) -> #N/A | F48: =IF(ISNA(F$32),"",OFFSET($B112,0,F$32-1)) -> #N/A | G48: =IF(ISNA(G$32),"",OFFSET($B112,0,G$32-1)) -> #N/A | H48: =IF(ISNA(H$32),"",OFFSET($B112,0,H$32-1)) -> #N/A | I48: =IF(ISNA(I$32),"",OFFSET($B112,0,I$32-1)) -> #N/A | J48: =IF(ISNA(J$32),"",OFFSET($B112,0,J$32-1)) -> #N/A | ... DJ48: =IF(ISNA(DJ$32),"",OFFSET($B112,0,DJ$32-1)) -> #N/A
...

Sheet paths
A1: own_detail | B1: lst_own_detail__name | L1: own_summary | W1: lloyds_detail | AH1: lloyds_summary | AS1: beazley_detail | BD1: beazley_summary
A2: Path | B2: Name | C2: Type | D2: Mode | E2: Optionality | F2: Label | G2: Default Value | H2: Async Input | I2: Async Output | J2: for python | L2: Path | M2: Name | N2: Type | O2: Mode | P2: Optionality | Q2: Label | R2: Default Value | S2: Async Input | T2: Async Output | U2: for python | W2: Path | X2: Name | Y2: Type | Z2: Mode | AA2: Optionality | AB2: Label | AC2: Default Value | AD2: Async Input | AE2: Async Output | AF2: for python | AH2: Path | AI2: Name | AJ2: Type | AK2: Mode | AL2: Optionality | AM2: Label | AN2: Default Value | AO2: Async Input | AP2: Async Output | AQ2: for python | AS2: Path | AT2: Name | AU2: Type | AV2: Mode | AW2: Optionality | AX2: Label | AY2: Default Value | AZ2: Async Input | BA2: Async Output | BB2: for python | BD2: Path | BE2: Name | BF2: Type | BG2: Mode | BH2: Optionality | BI2: Label | BJ2: Default Value | BK2: Async Input | BL2: Async Output | BM2: for python
A3: cds/projections_own_experience/detail_table/lob_number | B3: lob_number | C3: int | D3: output | E3: n/a | F3: Number of Line of Business | G3: n/a | H3: ['calculate_profit_commission_task'] | I3: n/a | J3: =",'"&own_detail[[#This Row],[Name]]&"'" -> ,'lob_number' | L3: cds/projections_own_experience/summary_table/claim_source | M3: claim_source | N3: str | O3: input | P3: required | Q3: Claim Source | R3: <hx_data_schema.nodes.Undefined object at 0x7f415a6cbe00> | S3: ['calculate_profit_commission_task', 'sync_lob_lists_task'] | T3: n/a | U3: =",'"&own_summary[[#This Row],[Name]]&"'" -> ,'claim_source' | W3: cds/projections_lloyds/detail_table/yoa | X3: yoa | Y3: str | Z3: output | AA3: n/a | AB3: YoA | AC3: n/a | AD3: n/a | AE3: [] | AF3: =",'"&lloyds_detail[[#This Row],[Name]]&"'" -> ,'yoa' | AH3: cds/projections_lloyds/summary_table/lob_number | AI3: lob_number | AJ3: int | AK3: output | AL3: n/a | AM3: Number of Line of Business | AN3: n/a | AO3: n/a | AP3: [] | AQ3: =",'"&lloyds_summary[[#This Row],[Name]]&"'" -> ,'lob_number' | AS3: cds/projections_beazley/detail_table/yoa | AT3: yoa | AU3: str | AV3: output | AW3: n/a | AX3: YoA | AY3: n/a | AZ3: n/a | BA3: [] | BB3: =",'"&beazley_detail[[#This Row],[Name]]&"'" -> ,'yoa' | BD3: cds/projections_beazley/summary_table/lob_number | BE3: lob_number | BF3: int | BG3: output | BH3: n/a | BI3: Number of Line of Business | BJ3: n/a | BK3: n/a | BL3: [] | BM3: =",'"&beazley_summary[[#This Row],[Name]]&"'" -> ,'lob_number'
A4: cds/projections_own_experience/detail_table/selected_lob | B4: selected_lob | C4: str | D4: output | E4: n/a | F4: Selected Line of Business | G4: n/a | H4: ['calculate_profit_commission_task'] | I4: n/a | J4: =",'"&own_detail[[#This Row],[Name]]&"'" -> ,'selected_lob' | L4: cds/projections_own_experience/summary_table/claim_basis | M4: claim_basis | N4: str | O4: input | P4: required | Q4: Claim Basis | R4: <hx_data_schema.nodes.Undefined object at 0x7f415a6cbe00> | S4: ['calculate_profit_commission_task', 'sync_lob_lists_task'] | T4: n/a | U4: =",'"&own_summary[[#This Row],[Name]]&"'" -> ,'claim_basis' | W4: cds/projections_lloyds/detail_table/latest_gpi | X4: latest_gpi | Y4: float | Z4: output | AA4: n/a | AB4: Latest GPI | AC4: n/a | AD4: n/a | AE4: [] | AF4: =",'"&lloyds_detail[[#This Row],[Name]]&"'" -> ,'latest_gpi' | AH4: cds/projections_lloyds/summary_table/risk_code | AI4: risk_code | AJ4: str | AK4: output | AL4: n/a | AM4: Risk Code | AN4: n/a | AO4: n/a | AP4: [] | AQ4: =",'"&lloyds_summary[[#This Row],[Name]]&"'" -> ,'risk_code' | AS4: cds/projections_beazley/detail_table/latest_gpi | AT4: latest_gpi | AU4: float | AV4: output | AW4: n/a | AX4: Latest GPI | AY4: n/a | AZ4: n/a | BA4: [] | BB4: =",'"&beazley_detail[[#This Row],[Name]]&"'" -> ,'latest_gpi' | BD4: cds/projections_beazley/summary_table/risk_code | BE4: risk_code | BF4: str | BG4: output | BH4: n/a | BI4: Risk Code | BJ4: n/a | BK4: n/a | BL4: [] | BM4: =",'"&beazley_summary[[#This Row],[Name]]&"'" -> ,'risk_code'
A5: cds/projections_own_experience/detail_table/yoa | B5: yoa | C5: str | D5: output | E5: n/a | F5: YoA | G5: n/a | H5: ['calculate_profit_commission_task'] | I5: n/a | J5: =",'"&own_detail[[#This Row],[Name]]&"'" -> ,'yoa' | L5: cds/projections_own_experience/summary_table/claim_to_develop_to_ultimate | M5: claim_to_develop_to_ultimate | N5: str | O5: input | P5: required | Q5: Claim to Develop to Ultimate | R5: <hx_data_schema.nodes.Undefined object at 0x7f415a6cbe00> | S5: ['calculate_profit_commission_task', 'sync_lob_lists_task'] | T5: n/a | U5: =",'"&own_summary[[#This Row],[Name]]&"'" -> ,'claim_to_develop_to_ultimate' | W5: cds/projections_lloyds/detail_table/latest_gnpi | X5: latest_gnpi | Y5: float | Z5: output | AA5: n/a | AB5: Latest GNPI | AC5: n/a | AD5: n/a | AE5: [] | AF5: =",'"&lloyds_detail[[#This Row],[Name]]&"'" -> ,'latest_gnpi' | AH5: cds/projections_lloyds/summary_table/selected_lob | AI5: selected_lob | AJ5: str | AK5: output | AL5: n/a | AM5: Selected Line of Business | AN5: n/a | AO5: n/a | AP5: [] | AQ5: =",'"&lloyds_summary[[#This Row],[Name]]&"'" -> ,'selected_lob' | AS5: cds/projections_beazley/detail_table/latest_gnpi | AT5: latest_gnpi | AU5: float | AV5: output | AW5: n/a | AX5: Latest GNPI | AY5: n/a | AZ5: n/a | BA5: [] | BB5: =",'"&beazley_detail[[#This Row],[Name]]&"'" -> ,'latest_gnpi' | BD5: cds/projections_beazley/summary_table/selected_lob | BE5: selected_lob | BF5: str | BG5: output | BH5: n/a | BI5: Selected Line of Business | BJ5: n/a | BK5: n/a | BL5: [] | BM5: =",'"&beazley_summary[[#This Row],[Name]]&"'" -> ,'selected_lob'
A6: cds/projections_own_experience/detail_table/latest_gpi | B6: latest_gpi | C6: float | D6: output | E6: n/a | F6: Latest GPI | G6: n/a | H6: ['calculate_profit_commission_task'] | I6: n/a | J6: =",'"&own_detail[[#This Row],[Name]]&"'" -> ,'latest_gpi' | L6: cds/projections_own_experience/summary_table/cat_basis | M6: cat_basis | N6: str | O6: input | P6: required | Q6: Cat Basis | R6: <hx_data_schema.nodes.Undefined object at 0x7f415a6cbe00> | S6: ['calculate_profit_commission_task', 'sync_lob_lists_task'] | T6: n/a | U6: =",'"&own_summary[[#This Row],[Name]]&"'" -> ,'cat_basis' | W6: cds/projections_lloyds/detail_table/latest_paid | X6: latest_paid | Y6: float | Z6: output | AA6: n/a | AB6: Latest Paid | AC6: n/a | AD6: n/a | AE6: [] | AF6: =",'"&lloyds_detail[[#This Row],[Name]]&"'" -> ,'latest_paid' | AH6: cds/projections_lloyds/summary_table/lookup_lob | AI6: lookup_lob | AJ6: str | AK6: output | AL6: n/a | AM6: Lookup LOB | AN6: n/a | AO6: n/a | AP6: [] | AQ6: =",'"&lloyds_summary[[#This Row],[Name]]&"'" -> ,'lookup_lob' | AS6: cds/projections_beazley/detail_table/latest_paid | AT6: latest_paid | AU6: float | AV6: output | AW6: n/a | AX6: Latest Paid | AY6: n/a | AZ6: n/a | BA6: [] | BB6: =",'"&beazley_detail[[#This Row],[Name]]&"'" -> ,'latest_paid' | BD6: cds/projections_beazley/summary_table/lookup_lob | BE6: lookup_lob | BF6: str | BG6: output | BH6: n/a | BI6: Lookup LOB | BJ6: n/a | BK6: n/a | BL6: [] | BM6: =",'"&beazley_summary[[#This Row],[Name]]&"'" -> ,'lookup_lob'
A7: cds/projections_own_experience/detail_table/latest_gnpi | B7: latest_gnpi | C7: float | D7: output | E7: n/a | F7: Latest GNPI | G7: n/a | H7: ['calculate_profit_commission_task'] | I7: n/a | J7: =",'"&own_detail[[#This Row],[Name]]&"'" -> ,'latest_gnpi' | L7: cds/projections_own_experience/summary_table/ielr_approach | M7: ielr_approach | N7: str | O7: input | P7: required | Q7: IELR Method & Weights | R7: On-level | S7: ['calculate_profit_commission_task', 'sync_lob_lists_task'] | T7: n/a | U7: =",'"&own_summary[[#This Row],[Name]]&"'" -> ,'ielr_approach' | W7: cds/projections_lloyds/detail_table/latest_incurred | X7: latest_incurred | Y7: float | Z7: output | AA7: n/a | AB7: Latest Incurred | AC7: n/a | AD7: n/a | AE7: [] | AF7: =",'"&lloyds_detail[[#This Row],[Name]]&"'" -> ,'latest_incurred' | AH7: cds/projections_lloyds/summary_table/bp_class | AI7: bp_class | AJ7: str | AK7: output | AL7: n/a | AM7: Beazley Business Plan class | AN7: n/a | AO7: n/a | AP7: [] | AQ7: =",'"&lloyds_summary[[#This Row],[Name]]&"'" -> ,'bp_class' | AS7: cds/projections_beazley/detail_table/latest_incurred | AT7: latest_incurred | AU7: float | AV7: output | AW7: n/a | AX7: Latest Incurred | AY7: n/a | AZ7: n/a | BA7: [] | BB7: =",'"&beazley_detail[[#This Row],[Name]]&"'" -> ,'latest_incurred' | BD7: cds/projections_beazley/summary_table/bp_class | BE7: bp_class | BF7: str | BG7: output | BH7: n/a | BI7: Beazley Business Plan class | BJ7: n/a | BK7: n/a | BL7: [] | BM7: =",'"&beazley_summary[[#This Row],[Name]]&"'" -> ,'bp_class'
A8: cds/projections_own_experience/detail_table/acquisition_costs | B8: acquisition_costs | C8: float | D8: output | E8: n/a | F8: Acquisition Costs % | G8: n/a | H8: ['calculate_profit_commission_task'] | I8: n/a | J8: =",'"&own_detail[[#This Row],[Name]]&"'" -> ,'acquisition_costs' | L8: cds/projections_own_experience/summary_table/ielr_attr | M8: ielr_attr | N8: float | O8: override | P8: n/a | Q8: Attritional IELR | R8: n/a | S8: ['calculate_profit_commission_task', 'sync_lob_lists_task'] | T8: n/a | U8: =",'"&own_summary[[#This Row],[Name]]&"'" -> ,'ielr_attr' | W8: cds/projections_lloyds/detail_table/acquisition_ratio | X8: acquisition_ratio | Y8: float | Z8: output | AA8: n/a | AB8: Acquisition costs % | AC8: n/a | AD8: n/a | AE8: [] | AF8: =",'"&lloyds_detail[[#This Row],[Name]]&"'" -> ,'acquisition_ratio' | AH8: cds/projections_lloyds/summary_table/tracker_class | AI8: tracker_class | AJ8: str | AK8: output | AL8: n/a | AM8: Tracker Class | AN8: n/a | AO8: n/a | AP8: [] | AQ8: =",'"&lloyds_summary[[#This Row],[Name]]&"'" -> ,'tracker_class' | AS8: cds/projections_beazley/detail_table/acquisition_ratio | AT8: acquisition_ratio | AU8: float | AV8: output | AW8: n/a | AX8: Acquisition costs % | AY8: n/a | AZ8: n/a | BA8: [] | BB8: =",'"&beazley_detail[[#This Row],[Name]]&"'" -> ,'acquisition_ratio' | BD8: cds/projections_beazley/summary_table/tracker_class | BE8: tracker_class | BF8: str | BG8: output | BH8: n/a | BI8: Tracker Class | BJ8: n/a | BK8: n/a | BL8: [] | BM8: =",'"&beazley_summary[[#This Row],[Name]]&"'" -> ,'tracker_class'
A9: cds/projections_own_experience/detail_table/ultimate_premium_selected_gnpi_cl | B9: ultimate_premium_selected_gnpi_cl | C9: float | D9: output | E9: n/a | F9: Ultimate GNPI - CL | G9: n/a | H9: ['calculate_profit_commission_task'] | I9: n/a | J9: =",'"&own_detail[[#This Row],[Name]]&"'" -> ,'ultimate_premium_selected_gnpi_cl' | L9: cds/projections_own_experience/summary_table/ielr_large | M9: ielr_large | N9: float | O9: override | P9: n/a | Q9: Large IELR | R9: n/a | S9: ['calculate_profit_commission_task', 'sync_lob_lists_task'] | T9: n/a | U9: =",'"&own_summary[[#This Row],[Name]]&"'" -> ,'ielr_large' | W9: cds/projections_lloyds/detail_table/incurred_loss_ratio | X9: incurred_loss_ratio | Y9: float | Z9: output | AA9: n/a | AB9: Incurred Loss ratio | AC9: n/a | AD9: n/a | AE9: [] | AF9: =",'"&lloyds_detail[[#This Row],[Name]]&"'" -> ,'incurred_loss_ratio' | AH9: cds/projections_lloyds/summary_table/projection_type | AI9: projection_type | AJ9: str | AK9: input | AL9: required | AM9: Projection Type | AN9: <hx_data_schema.nodes.Undefined object at 0x7f415a6cbe00> | AO9: ['sync_lob_lists_task'] | AP9: [] | AQ9: =",'"&lloyds_summary[[#This Row],[Name]]&"'" -> ,'projection_type' | AS9: cds/projections_beazley/detail_table/incurred_loss_ratio | AT9: incurred_loss_ratio | AU9: float | AV9: output | AW9: n/a | AX9: Incurred Loss ratio | AY9: n/a | AZ9: n/a | BA9: [] | BB9: =",'"&beazley_detail[[#This Row],[Name]]&"'" -> ,'incurred_loss_ratio' | BD9: cds/projections_beazley/summary_table/projection_type | BE9: projection_type | BF9: str | BG9: input | BH9: required | BI9: Projection Type | BJ9: <hx_data_schema.nodes.Undefined object at 0x7f415a6cbe00> | BK9: ['sync_lob_lists_task'] | BL9: [] | BM9: =",'"&beazley_summary[[#This Row],[Name]]&"'" -> ,'projection_type'
A10: cds/projections_own_experience/detail_table/ultimate_premium_selected_gnpi_override | B10: ultimate_premium_selected_gnpi_override | C10: float | D10: input | E10: optional | F10: Ultimate GNPI - Override | G10: None | H10: ['calculate_profit_commission_task'] | I10: n/a | J10: =",'"&own_detail[[#This Row],[Name]]&"'" -> ,'ultimate_premium_selected_gnpi_override' | L10: cds/projections_own_experience/summary_table/ielr_cat | M10: ielr_cat | N10: float | O10: override | P10: n/a | Q10: CAT IELR | R10: n/a | S10: ['calculate_profit_commission_task', 'sync_lob_lists_task'] | T10: n/a | U10: =",'"&own_summary[[#This Row],[Name]]&"'" -> ,'ielr_cat' | W10: cds/projections_lloyds/detail_table/ultimate_gnpi | X10: ultimate_gnpi | Y10: float | Z10: output | AA10: n/a | AB10: Ultimate GNPI | AC10: n/a | AD10: n/a | AE10: [] | AF10: =",'"&lloyds_detail[[#This Row],[Name]]&"'" -> ,'ultimate_gnpi' | AH10: cds/projections_lloyds/summary_table/ielr_approach | AI10: ielr_approach | AJ10: str | AK10: input | AL10: required | AM10: IELR Method & Weights | AN10: <hx_data_schema.nodes.Undefined object at 0x7f415a6cbe00> | AO10: ['sync_lob_lists_task'] | AP10: [] | AQ10: =",'"&lloyds_summary[[#This Row],[Name]]&"'" -> ,'ielr_approach' | AS10: cds/projections_beazley/detail_table/ultimate_gnpi | AT10: ultimate_gnpi | AU10: float | AV10: output | AW10: n/a | AX10: Ultimate GNPI | AY10: n/a | AZ10: n/a | BA10: [] | BB10: =",'"&beazley_detail[[#This Row],[Name]]&"'" -> ,'ultimate_gnpi' | BD10: cds/projections_beazley/summary_table/ielr_approach | BE10: ielr_approach | BF10: str | BG10: input | BH10: required | BI10: IELR Method & Weights | BJ10: <hx_data_schema.nodes.Undefined object at 0x7f415a6cbe00> | BK10: ['sync_lob_lists_task'] | BL10: [] | BM10: =",'"&beazley_summary[[#This Row],[Name]]&"'" -> ,'ielr_approach'
A11: cds/projections_own_experience/detail_table/ultimate_premium_selected_gnpi_selected | B11: ultimate_premium_selected_gnpi_selected | C11: float | D11: output | E11: n/a | F11: Ultimate GNPI - Selected | G11: n/a | H11: ['calculate_profit_commission_task'] | I11: n/a | J11: =",'"&own_detail[[#This Row],[Name]]&"'" -> ,'ultimate_premium_selected_gnpi_selected' | L11: cds/projections_own_experience/summary_table/ielr_total | M11: ielr_total | N11: float | O11: override | P11: n/a | Q11: Total IELR | R11: n/a | S11: ['calculate_profit_commission_task', 'sync_lob_lists_task'] | T11: n/a | U11: =",'"&own_summary[[#This Row],[Name]]&"'" -> ,'ielr_total' | W11: cds/projections_lloyds/detail_table/ultimate_gnpi_ol_model | X11: ultimate_gnpi_ol_model | Y11: float | Z11: output | AA11: n/a | AB11: Ultimate GNPI On-level Default | AC11: n/a | AD11: n/a | AE11: [] | AF11: =",'"&lloyds_detail[[#This Row],[Name]]&"'" -> ,'ultimate_gnpi_ol_model' | AH11: cds/projections_lloyds/summary_table/ielr_source | AI11: ielr_source | AJ11: str | AK11: input | AL11: required | AM11: Selected IELR Source | AN11: <hx_data_schema.nodes.Undefined object at 0x7f415a6cbe00> | AO11: ['sync_lob_lists_task'] | AP11: [] | AQ11: =",'"&lloyds_summary[[#This Row],[Name]]&"'" -> ,'ielr_source' | AS11: cds/projections_beazley/detail_table/ultimate_gnpi_ol_model | AT11: ultimate_gnpi_ol_model | AU11: float | AV11: output | AW11: n/a | AX11: Ultimate GNPI On-level Default | AY11: n/a | AZ11: n/a | BA11: [] | BB11: =",'"&beazley_detail[[#This Row],[Name]]&"'" -> ,'ultimate_gnpi_ol_model' | BD11: cds/projections_beazley/summary_table/ielr_source | BE11: ielr_source | BF11: str | BG11: input | BH11: required | BI11: Selected IELR Source | BJ11: <hx_data_schema.nodes.Undefined object at 0x7f415a6cbe00> | BK11: ['sync_lob_lists_task'] | BL11: [] | BM11: =",'"&beazley_summary[[#This Row],[Name]]&"'" -> ,'ielr_source'
