Workbook
Name hxd.cds.adj_base: Summary!$G$5
Name hxd.cds.broker_contact: 'Rate Change'!$B$7
Name hxd.cds.brokerage: Summary!$G$4
Name hxd.cds.calc_type: Summary!$C$11
Name hxd.cds.com_disease: 'Rate Change'!$K$9
Name hxd.cds.core_account: 'Rate Change'!$K$5
Name hxd.cds.currency: Summary!$C$9
Name hxd.cds.currency_policy_financials: Summary!$S$4
Name hxd.cds.cyber_code: 'Rate Change'!$K$7
Name hxd.cds.experience_rating.exposure.last_eight.1.gnepi_actual: Summary!$N$5
Name hxd.cds.experience_rating.exposure.last_eight.1.gnepi_projected: Summary!$O$5
Name hxd.cds.experience_rating.exposure.last_eight.1.year: Summary!$M$5
Name hxd.cds.experience_rating.exposure.last_eight.2.gnepi_actual: Summary!$N$6
Name hxd.cds.experience_rating.exposure.last_eight.2.gnepi_projected: Summary!$O$6
Name hxd.cds.experience_rating.exposure.last_eight.2.year: Summary!$M$6
Name hxd.cds.experience_rating.exposure.last_eight.3.gnepi_actual: Summary!$N$7
Name hxd.cds.experience_rating.exposure.last_eight.3.gnepi_projected: Summary!$O$7
Name hxd.cds.experience_rating.exposure.last_eight.3.year: Summary!$M$7
Name hxd.cds.experience_rating.exposure.last_eight.4.gnepi_actual: Summary!$N$8
Name hxd.cds.experience_rating.exposure.last_eight.4.gnepi_projected: Summary!$O$8
Name hxd.cds.experience_rating.exposure.last_eight.4.year: Summary!$M$8
Name hxd.cds.experience_rating.exposure.last_eight.5.gnepi_actual: Summary!$N$9
Name hxd.cds.experience_rating.exposure.last_eight.5.gnepi_projected: Summary!$O$9
Name hxd.cds.experience_rating.exposure.last_eight.5.year: Summary!$M$9
Name hxd.cds.experience_rating.exposure.last_eight.6.gnepi_actual: Summary!$N$10
Name hxd.cds.experience_rating.exposure.last_eight.6.gnepi_projected: Summary!$O$10
Name hxd.cds.experience_rating.exposure.last_eight.6.year: Summary!$M$10
Name hxd.cds.experience_rating.exposure.last_eight.7.gnepi_actual: Summary!$N$11
Name hxd.cds.experience_rating.exposure.last_eight.7.gnepi_projected: Summary!$O$11
Name hxd.cds.experience_rating.exposure.last_eight.7.year: Summary!$M$11
Name hxd.cds.experience_rating.exposure.last_eight.8.gnepi_actual: Summary!$N$12
Name hxd.cds.experience_rating.exposure.last_eight.8.gnepi_projected: Summary!$O$12
Name hxd.cds.experience_rating.exposure.last_eight.8.year: Summary!$M$12
Name hxd.cds.fx_conversion_label: Summary!$R$5
Name hxd.cds.hours_clause: Summary!$G$9
Name hxd.cds.layers.1.area_codes_perc.aal: 'Area Code'!$CD$41
Name hxd.cds.layers.1.area_codes_perc.aeg: 'Area Code'!$CD$43
Name hxd.cds.layers.1.area_codes_perc.ali: 'Area Code'!$CD$44
Name hxd.cds.layers.1.area_codes_perc.amo: 'Area Code'!$CD$42
Name hxd.cds.layers.1.area_codes_perc.amu: 'Area Code'!$CD$45
Name hxd.cds.layers.1.area_codes_perc.asa: 'Area Code'!$CD$38
Name hxd.cds.layers.1.area_codes_perc.bag: 'Area Code'!$BD$12
Name hxd.cds.layers.1.area_codes_perc.bah: 'Area Code'!$BD$13
Name hxd.cds.layers.1.area_codes_perc.ban: 'Area Code'!$BD$14
Name hxd.cds.layers.1.area_codes_perc.bbb: 'Area Code'!$BD$15
Name hxd.cds.layers.1.area_codes_perc.bbh: 'Area Code'!$BD$16
Name hxd.cds.layers.1.area_codes_perc.bbm: 'Area Code'!$BD$17
Name hxd.cds.layers.1.area_codes_perc.bcb: 'Area Code'!$BD$18
Name hxd.cds.layers.1.area_codes_perc.bcm: 'Area Code'!$BD$19
Name hxd.cds.layers.1.area_codes_perc.bcu: 'Area Code'!$BD$20
Name hxd.cds.layers.1.area_codes_perc.bdo: 'Area Code'!$BD$21
Name hxd.cds.layers.1.area_codes_perc.bdr: 'Area Code'!$BD$22
Name hxd.cds.layers.1.area_codes_perc.bgn: 'Area Code'!$BD$23
Name hxd.cds.layers.1.area_codes_perc.bgs: 'Area Code'!$BD$24
Name hxd.cds.layers.1.area_codes_perc.bgu: 'Area Code'!$BD$25
Name hxd.cds.layers.1.area_codes_perc.bht: 'Area Code'!$BD$26
Name hxd.cds.layers.1.area_codes_perc.bjm: 'Area Code'!$BD$27
Name hxd.cds.layers.1.area_codes_perc.bkn: 'Area Code'!$BD$28
Name hxd.cds.layers.1.area_codes_perc.bmq: 'Area Code'!$BD$29
Name hxd.cds.layers.1.area_codes_perc.bms: 'Area Code'!$BD$30

Sheet Modelling
A1: Treaty Model - Modelling
B4: Comments | W4: Cedant RDS Gross Loss
W6: Carolinas WS | X6: Miami-Dade WS | Y6: Gulf WS | Z6: NE WS | AA6: FL Pinnelas WS | AB6: LA EQ | AC6: NM EQ | AD6: NM Stress EQ | AE6: SF EQ
V7: Current Year (NA)
V8: Previous Year (NA)
V9: YOY growth
B10: Current Year (2025)
B11: RMS Value + NMP | E11: Unadjusted RMS Values | H11: IVOR | I11: Excludes NMP | K11: AIR Values | N11: Non model Perils | T11: AIR Values + NMP | W11: RMS Regional Entries | AP11: Treaty US marginal portfolio impact | AS11: Group US marginal portfolio impact | AV11: Treaty Intl marginal portfolio impact
W12: USA01 | X12: USA02 | Y12: USA03 | Z12: USA04 | AA12: USA05 | AB12: USA06 | AC12: USA07 | AD12: USA08 | AE12: USA09 | AF12: USA10 | AG12: USA11 | AH12: USA12 | AI12: USA15 | AJ12: USA16 | AK12: USA13 | AL12: USA14 | AM12: USA20 | AN12: USA21
B13: Total EL | C13: Total SD | E13: Gross EL | F13: Gross SD | H13: Gross EL | I13: Gross SD | K13: Gross EL | L13: Gross SD | N13: EL | O13: SD | P13: EL - Values | Q13: SD - Values | R13: Description | T13: Gross EL | U13: Gross SD | W13: NE | X13: MID ATLANTIC | Y13: CARS | Z13: FL SE | AA13: FL NON SE | AB13: AL + MISS | AC13: LOUISIANA | AD13: TX EAST | AE13: TX WEST | AF13: CAL SOUTH | AG13: CAL NORTH | AH13: PNW | AI13: NM | AJ13: HAWAII + ALASKA | AK13: MID WEST 1 | AL13: MID WEST 2 | AM13: 2ND EVENT COVER | AN13: CA WILDFIRE | AP13: 1 in 250 | AQ13: 1 in 10 | AS13: 1 in 250 | AT13: 1 in 10 | AV13: 1 in 250 | AW13: 1 in 10

Sheet Summary
A1: Treaty Rater Summary
C4: =Rationale!D4 -> 0 | F4: Brokerage | M4: Year | N4: GNEPI (Actual) | O4: GNEPI (Projected) | R4: Choose currency to view policy financials
F5: Adj Base
F6: Underwriter | G6: =hxd.cds.standard_fields.underwriter -> 0
F7: Broker
F8: Broker Contact | G8: =hxd.cds.broker_contact -> 0
F9: Hours Clause | R9: Comments
F10: Sanctions Clause:
F12: Terrorism Code: | G12: ='Rate Change'!K11 -> 0
F13: Cyber Clause: | G13: ='Rate Change'!K7 -> 0
F14: Com Disease: | G14: ='Rate Change'!K9 -> 0
C16: Multi-year Summary
C18: Written Line Exsposure | D18: Estimated Signed line Exsposure | E18: Signed Line Exsposure | F18: Written Line Premium | G18: Estimated Signed line Premium | H18: Signed Line Premium | I18: 1 in 250 | J18: PML / Estimate Prem | K18: PML / Signed Prem
B19: Current Year
B20: Previous Year
C22: Year After Next
C23: Policy Financials
C25: Policy Ref | D25: Leader | E25: Description | F25: Limit in Application Currency | G25: Retention in Application Currency | H25: Quoted ROL | I25: FOT ROL | J25: AFB Tech ROL | K25: Reinstatements | L25: ROE | M25: Rate Change | N25: BPI % | O25: AFB Tech adequacy | Q25: ULR | R25: EPI ADJ. RATE | S25: Premium | T25: Written Line % | U25: Written Line USD | V25: Estmated Signing % | W25: Estimated Line USD | X25: Signed Line % | Y25: Signed Line USD | Z25: Written EPI USD | AA25: Estimated EPI USD | AB25: Signed EPI USD | AC25: 1 in 250yr | AD25: 1 in 250 / Premium | AE25: 1 in 10yr | AF25: 1 in 10 / Premium
D26: =D52 -> 0 | E26: =E52 -> 0 | F26: =F52 -> 0 | G26: =G52 -> 0 | H26: =H52 -> 0 | I26: =I52 -> 0 | J26: =J52 -> 0 | K26: =K52 -> 0 | M26: 1 | N26: =N52 -> 0 | O26: =O52 -> 0 | Q26: =Q52 -> 0 | R26: =R52 -> 0 | S26: =S52 -> 0 | T26: =T52 -> 0 | U26: =U52 -> 0 | V26: =V52 -> 0 | W26: =W52 -> 0 | X26: =X52 -> 0 | ... AF26: =AF52 -> 0
D27: =D53 -> 0 | E27: =E53 -> 0 | F27: =F53 -> 0 | G27: =G53 -> 0 | H27: =H53 -> 0 | I27: =I53 -> 0 | J27: =J53 -> 0 | K27: =K53 -> 0 | M27: 1 | N27: =N53 -> 0 | O27: =O53 -> 0 | Q27: =Q53 -> 0 | R27: =R53 -> 0 | S27: =S53 -> 0 | T27: =T53 -> 0 | U27: =U53 -> 0 | V27: =V53 -> 0 | W27: =W53 -> 0 | X27: =X53 -> 0 | ... AF27: =AF53 -> 0
D28: =D54 -> 0 | E28: =E54 -> 0 | F28: =F54 -> 0 | G28: =G54 -> 0 | H28: =H54 -> 0 | I28: =I54 -> 0 | J28: =J54 -> 0 | K28: =K54 -> 0 | M28: 1 | N28: =N54 -> 0 | O28: =O54 -> 0 | Q28: =Q54 -> 0 | R28: =R54 -> 0 | S28: =S54 -> 0 | T28: =T54 -> 0 | U28: =U54 -> 0 | V28: =V54 -> 0 | W28: =W54 -> 0 | X28: =X54 -> 0 | ... AF28: =AF54 -> 0
D29: =D55 -> 0 | E29: =E55 -> 0 | F29: =F55 -> 0 | G29: =G55 -> 0 | H29: =H55 -> 0 | I29: =I55 -> 0 | J29: =J55 -> 0 | K29: =K55 -> 0 | M29: 1 | N29: =N55 -> 0 | O29: =O55 -> 0 | Q29: =Q55 -> 0 | R29: =R55 -> 0 | S29: =S55 -> 0 | T29: =T55 -> 0 | U29: =U55 -> 0 | V29: =V55 -> 0 | W29: =W55 -> 0 | X29: =X55 -> 0 | ... AF29: =AF55 -> 0
D30: =D56 -> 0 | E30: =E56 -> 0 | F30: =F56 -> 0 | G30: =G56 -> 0 | H30: =H56 -> 0 | I30: =I56 -> 0 | J30: =J56 -> 0 | K30: =K56 -> 0 | M30: 1 | N30: =N56 -> 0 | O30: =O56 -> 0 | Q30: =Q56 -> 0 | R30: =R56 -> 0 | S30: =S56 -> 0 | T30: =T56 -> 0 | U30: =U56 -> 0 | V30: =V56 -> 0 | W30: =W56 -> 0 | X30: =X56 -> 0 | ... AF30: =AF56 -> 0
D31: =D57 -> 0 | E31: =E57 -> 0 | F31: =F57 -> 0 | G31: =G57 -> 0 | H31: =H57 -> 0 | I31: =I57 -> 0 | J31: =J57 -> 0 | K31: =K57 -> 0 | M31: 1 | N31: =N57 -> 0 | O31: =O57 -> 0 | Q31: =Q57 -> 0 | R31: =R57 -> 0 | S31: =S57 -> 0 | T31: =T57 -> 0 | U31: =U57 -> 0 | V31: =V57 -> 0 | W31: =W57 -> 0 | X31: =X57 -> 0 | ... AF31: =AF57 -> 0
D32: =D58 -> 0 | E32: =E58 -> 0 | F32: =F58 -> 0 | G32: =G58 -> 0 | H32: =H58 -> 0 | I32: =I58 -> 0 | J32: =J58 -> 0 | K32: =K58 -> 0 | M32: 1 | N32: =N58 -> 0 | O32: =O58 -> 0 | Q32: =Q58 -> 0 | R32: =R58 -> 0 | S32: =S58 -> 0 | T32: =T58 -> 0 | U32: =U58 -> 0 | V32: =V58 -> 0 | W32: =W58 -> 0 | X32: =X58 -> 0 | ... AF32: =AF58 -> 0
D33: =D59 -> 0 | E33: =E59 -> 0 | F33: =F59 -> 0 | G33: =G59 -> 0 | H33: =H59 -> 0 | I33: =I59 -> 0 | J33: =J59 -> 0 | K33: =K59 -> 0 | M33: 1 | N33: =N59 -> 0 | O33: =O59 -> 0 | Q33: =Q59 -> 0 | R33: =R59 -> 0 | S33: =S59 -> 0 | T33: =T59 -> 0 | U33: =U59 -> 0 | V33: =V59 -> 0 | W33: =W59 -> 0 | X33: =X59 -> 0 | ... AF33: =AF59 -> 0
C35: Next Year
C36: Policy Financials
C38: Policy Ref | D38: Leader | E38: Description | F38: Limit in Application Currency | G38: Retention in Application Currency | H38: Quoted ROL | I38: FOT ROL | J38: AFB Tech ROL | K38: Reinstatements | L38: ROE | M38: Rate Change | N38: BPI % | O38: AFB Tech adequacy | Q38: ULR | R38: EPI ADJ. RATE | S38: Premium | T38: Written Line % | U38: Written Line USD | V38: Estmated Signing % | W38: Estimated Line USD | X38: Signed Line % | Y38: Signed Line USD | Z38: Written EPI USD | AA38: Estimated EPI USD | AB38: Signed EPI USD | AC38: 1 in 250yr | AD38: 1 in 250 / Premium | AE38: 1 in 10yr | AF38: 1 in 10 / Premium
D39: =D52 -> 0 | E39: =E52 -> 0 | F39: =F52 -> 0 | G39: =G52 -> 0 | H39: =H52 -> 0 | I39: =I52 -> 0 | J39: =J52 -> 0 | K39: =K52 -> 0 | M39: 1 | N39: =N52 -> 0 | O39: =O52 -> 0 | Q39: =Q52 -> 0 | R39: =R52 -> 0 | S39: =S52 -> 0 | T39: =T52 -> 0 | U39: =U52 -> 0 | V39: =V52 -> 0 | W39: =W52 -> 0 | X39: =X52 -> 0 | ... AF39: =AF52 -> 0
D40: =D53 -> 0 | E40: =E53 -> 0 | F40: =F53 -> 0 | G40: =G53 -> 0 | H40: =H53 -> 0 | I40: =I53 -> 0 | J40: =J53 -> 0 | K40: =K53 -> 0 | M40: 1 | N40: =N53 -> 0 | O40: =O53 -> 0 | Q40: =Q53 -> 0 | R40: =R53 -> 0 | S40: =S53 -> 0 | T40: =T53 -> 0 | U40: =U53 -> 0 | V40: =V53 -> 0 | W40: =W53 -> 0 | X40: =X53 -> 0 | ... AF40: =AF53 -> 0
D41: =D54 -> 0 | E41: =E54 -> 0 | F41: =F54 -> 0 | G41: =G54 -> 0 | H41: =H54 -> 0 | I41: =I54 -> 0 | J41: =J54 -> 0 | K41: =K54 -> 0 | M41: 1 | N41: =N54 -> 0 | O41: =O54 -> 0 | Q41: =Q54 -> 0 | R41: =R54 -> 0 | S41: =S54 -> 0 | T41: =T54 -> 0 | U41: =U54 -> 0 | V41: =V54 -> 0 | W41: =W54 -> 0 | X41: =X54 -> 0 | ... AF41: =AF54 -> 0
D42: =D55 -> 0 | E42: =E55 -> 0 | F42: =F55 -> 0 | G42: =G55 -> 0 | H42: =H55 -> 0 | I42: =I55 -> 0 | J42: =J55 -> 0 | K42: =K55 -> 0 | M42: 1 | N42: =N55 -> 0 | O42: =O55 -> 0 | Q42: =Q55 -> 0 | R42: =R55 -> 0 | S42: =S55 -> 0 | T42: =T55 -> 0 | U42: =U55 -> 0 | V42: =V55 -> 0 | W42: =W55 -> 0 | X42: =X55 -> 0 | ... AF42: =AF55 -> 0
D43: =D56 -> 0 | E43: =E56 -> 0 | F43: =F56 -> 0 | G43: =G56 -> 0 | H43: =H56 -> 0 | I43: =I56 -> 0 | J43: =J56 -> 0 | K43: =K56 -> 0 | M43: 1 | N43: =N56 -> 0 | O43: =O56 -> 0 | Q43: =Q56 -> 0 | R43: =R56 -> 0 | S43: =S56 -> 0 | T43: =T56 -> 0 | U43: =U56 -> 0 | V43: =V56 -> 0 | W43: =W56 -> 0 | X43: =X56 -> 0 | ... AF43: =AF56 -> 0
D44: =D57 -> 0 | E44: =E57 -> 0 | F44: =F57 -> 0 | G44: =G57 -> 0 | H44: =H57 -> 0 | I44: =I57 -> 0 | J44: =J57 -> 0 | K44: =K57 -> 0 | M44: 1 | N44: =N57 -> 0 | O44: =O57 -> 0 | Q44: =Q57 -> 0 | R44: =R57 -> 0 | S44: =S57 -> 0 | T44: =T57 -> 0 | U44: =U57 -> 0 | V44: =V57 -> 0 | W44: =W57 -> 0 | X44: =X57 -> 0 | ... AF44: =AF57 -> 0
D45: =D58 -> 0 | E45: =E58 -> 0 | F45: =F58 -> 0 | G45: =G58 -> 0 | H45: =H58 -> 0 | I45: =I58 -> 0 | J45: =J58 -> 0 | K45: =K58 -> 0 | M45: 1 | N45: =N58 -> 0 | O45: =O58 -> 0 | Q45: =Q58 -> 0 | R45: =R58 -> 0 | S45: =S58 -> 0 | T45: =T58 -> 0 | U45: =U58 -> 0 | V45: =V58 -> 0 | W45: =W58 -> 0 | X45: =X58 -> 0 | ... AF45: =AF58 -> 0
D46: =D59 -> 0 | E46: =E59 -> 0 | F46: =F59 -> 0 | G46: =G59 -> 0 | H46: =H59 -> 0 | I46: =I59 -> 0 | J46: =J59 -> 0 | K46: =K59 -> 0 | M46: 1 | N46: =N59 -> 0 | O46: =O59 -> 0 | Q46: =Q59 -> 0 | R46: =R59 -> 0 | S46: =S59 -> 0 | T46: =T59 -> 0 | U46: =U59 -> 0 | V46: =V59 -> 0 | W46: =W59 -> 0 | X46: =X59 -> 0 | ... AF46: =AF59 -> 0
C48: Current Year
C49: Policy Financials
B51: Multi-year Period | C51: Policy Ref | D51: Leader | E51: Description | F51: Limit in Application Currency | G51: Retention in Application Currency | H51: Quoted ROL | I51: FOT ROL | J51: AFB Tech ROL | K51: Reinstatements | L51: ROE | M51: Rate Change | N51: BPI % | O51: AFB Tech adequacy | P51: RMS Adequacy | Q51: ULR | R51: EPI ADJ. RATE | S51: Premium | T51: Written Line % | U51: ="Written Line " & hxd.cds.currency_policy_financials -> Written Line | V51: Estmated Signing % | W51: ="Estimated Line " & hxd.cds.currency_policy_financials -> Estimated Line | X51: Signed Line % | Y51: ="Signed Line " & hxd.cds.currency_policy_financials -> Signed Line | Z51: ="Written EPI " & hxd.cds.currency_policy_financials -> Written EPI | AA51: ="Estimated EPI " & hxd.cds.currency_policy_financials -> Estimated EPI | AB51: ="Signed EPI " & hxd.cds.currency_policy_financials -> Signed EPI | AC51: 1 in 250yr | AD51: 1 in 250 / Premium | AE51: 1 in 10yr | AF51: 1 in 10 / Premium
...

Sheet Rate Change
A1: Rate change
A3: Please fill in COLOURED boxes
A5: Account Name: | I5: Core Account: | U5: Date: | V5: =TODAY() -> 46147
A7: Broker contact: | I7: Cyber Code:
A9: Underwriter: | I9: Com Disease:
A11: Underwriter Sign-Off | I11: Terrorism Code
C14: Layer Ref: | I14: Layer Ref: | O14: Layer Ref: | U14: Layer Ref: | AA14: Layer Ref: | AG14: Layer Ref: | AM14: Layer Ref: | AS14: Layer Ref:
C16: Structure: | E16: xs | I16: Structure: | K16: xs | O16: Structure: | Q16: xs | U16: Structrue: | W16: xs | AA16: Structrue: | AC16: xs | AG16: Structrue: | AI16: xs | AM16: Structrue: | AO16: xs | AS16: Structrue: | AU16: xs
C18: Description | I18: Description | O18: Description | U18: Description | AA18: Description | AG18: Description | AM18: Description | AS18: Description
A20: (£/$/€/etc) | AC20: Please Select
A21: a) Annualised expiring Rate | E21: Rate | K21: =E21 -> Rate | Q21: =E21 -> Rate | W21: =E21 -> Rate | AC21: =E21 -> Rate | AI21: =E21 -> Rate | AO21: =E21 -> Rate | AU21: =E21 -> Rate
A24: b) Exposure Change dictates change of
B25: (%)
A28: c) Risk characteristics change dictates change of
B29: (%)
A32: d) Deductible change dictates change of
B33: (%)
A36: e) Limit and Retention changes dictates change of
B37: (%)
A40: f) Terms and conditions change dictates change of
B41: (%)
A44: g) Other (e.g., brokerage) change dictates change of
B45: (%)
A48: h) New calculated Premium/Rate
A51: i) New Rate
A53: Rate change therefore
A55: Estimated signing %:
A57: ULR
A59: Benchmarking: | E59: N/A | K59: N/A | Q59: N/A | W59: N/A | AC59: N/A | AI59: N/A | AO59: N/A | AU59: N/A
A61: Rationale if outside business plan: | I61: NOT MAPPED | O61: NOT MAPPED | U61: NOT MAPPED
C68: 1 | I68: 2 | O68: 3 | U68: 4 | AA68: 5 | AG68: 6 | AM68: 7 | AS68: 8

Sheet Rationale
A1: Treaty Model - Rationale
B4: Account Name | D4: ='Rate Change'!B5 -> 0
B6: Knowledge of the reinsured
B13: Portfolio fit
B20: Basis of risk selection
B27: Any unusual or complex considerations
B34: Facts which affect the underwriter's decision

Sheet Pre Bind
A1: Account name: | C1: ='Rate Change'!B5 -> 0
A2: Underwriter: | C2: ='Rate Change'!B9 -> 0
A4: By signing below I confirm that the answer to all of the following questions is "Yes":
A6: Question | K6: Answer
A7: Does there exist, attached to the risk at time of bind, a contract or wording on which we can base a judgement of a claim?
A8: Are the key parties (insured, reinsured) identified on the slip, including corporate contact information?
A9: Are the key components of the contract clearly identified, including : class of insurance, period of coverage, limits of cover provided, territorial limits and choice of law & jurisdiction.
A10: Are we licensed to do this class / type of business in the jurisdiction(s) stated in the contract?
A11: Does the contract / wording meet any specific regulatory requirements for the jurisdiction / type of business.
A12: Have you confirmed that the contract is not in breach of any requirements or prohibitions on economic, trade and financial sanctions?
A13: Have you confirmed that all appropriate taxes and responsibility for paying them is detailed in the contract or wording?
A16: Underwriter Signature:
A18: Date (must be pre-bind or on day of binding the contract):

Sheet Post Bind
A1: Account name: | C1: ='Rate Change'!B5 -> 0
A2: Underwriter: | C2: ='Rate Change'!B9 -> 0
A4: By signing below I confirm that the answer to all of the following questions is "Yes":
A6: Question | K6: Answer | L6: Comments
A7: APPLICABLE TO ALL SLIP HEADINGS WITHIN THIS SLIP SECTION:
A8: Have the wordings and all clauses been attached / referenced in the slip?
A9: Where a wording is dependent on another wording (for example, "as expiring" or "as original"), is the latter either attached or identified?
A10: Are all broker/insurer arrangements stated?
A12: APPLICABLE TO WHOLE SLIP:
A13: Are all currencies referenced e.g. via use of three letter ISO currency codes?
A14: Are all provisions relevant to the risk and its administration to ensure that the contract is clear and unambiguous?
A15: Ensure that there are no terms to be agreed (TBAs) or other terms remaining undefined.
A17: CONDITIONS
A18: Where the perils of radioactive contamination and/or nuclear incident are considered to be relevant to the scope of coverage, and it is the intention not to cover them, check that an appropriate exclusion clause has been included.
A19: Some clauses and wordings contain set deductibles and limits. Where this is the case ensure that the currency is consistent with the rest of the contract.
A21: SUBJECTIVITIES:
... A85: Have you confirmed that a section on the regulatory risk location appears in the contract and that it has been completely corrected?

Sheet Area Code
A1: Treaty Model - Area Code
A4: Account Name: | C4: =Rationale!D4 -> 0
A6: References: | C6: Layer 1: | F6: Layer 2: | I6: Layer 3: | L6: Layer 4: | O6: Layer 5: | R6: Layer 6: | U6: Layer 7: | X6: Layer 8: | AC6: % box is for the proportion of premium allocated to that area (excluding US)
C7: ='Rate Change'!D14 -> 0 | F7: ='Rate Change'!J14 -> 0 | I7: ='Rate Change'!P14 -> 0 | L7: ='Rate Change'!V14 -> 0 | O7: ='Rate Change'!AB14 -> 0 | R7: ='Rate Change'!AH14 -> 0 | U7: ='Rate Change'!AN14 -> 0 | X7: ='Rate Change'!AT14 -> 0
AC8: 1 | AD8: 1 | AF8: 2 | AG8: 2 | AI8: 3 | AJ8: 3 | AL8: 4 | AM8: 4 | AO8: 5 | AP8: 5 | AR8: 6 | AS8: 6 | AU8: 7 | AV8: 7 | AX8: 8 | AY8: 8 | BC8: 1 | BD8: 1 | BF8: 2 | BG8: 2 | BI8: 3 | BJ8: 3 | BL8: 4 | BM8: 4 | BO8: 5 | BP8: 5 | BR8: 6 | BS8: 6 | BU8: 7 | BV8: 7 | BX8: 8 | BY8: 8 | CC8: 1 | CD8: 1 | CF8: 2 | CG8: 2 | CI8: 3 | CJ8: 3 | CL8: 4 | CM8: 4 | CO8: 5 | CP8: 5 | CR8: 6 | CS8: 6 | CU8: 7 | CV8: 7 | CX8: 8 | CY8: 8
C9: =A11&", "&A29&" and "&A37 -> Northern Europe, Southern Europe and CEE | AC9: =AA11&", "&AA32&" and "&AA53 -> US, Latin America and Australia | BC9: =BA11&" and "&BA39 -> Caribbean and Canada | CC9: =CA11&" and "&CA35 -> Far East and AMEI
A11: Northern Europe | C11: L1 | D11: % | F11: L2 | G11: % | I11: L3 | J11: % | L11: L4 | M11: % | O11: L5 | P11: % | R11: L6 | S11: % | U11: L7 | V11: % | X11: L8 | Y11: % | AA11: US | AC11: L1 | AD11: % | AF11: L2 | AG11: % | AI11: L3 | AJ11: % | AL11: L4 | AM11: % | AO11: L5 | AP11: % | AR11: L6 | AS11: % | AU11: L7 | AV11: % | AX11: L8 | AY11: % | BA11: Caribbean | BC11: L1 | BD11: % | BF11: L2 | BG11: % | BI11: L3 | BJ11: % | BL11: L4 | BM11: % | BO11: L5 | BP11: % | BR11: L6 | BS11: % | BU11: L7 | BV11: % | BX11: L8 | BY11: % | CA11: Far East | CC11: L1 | CD11: % | CF11: L2 | CG11: % | CI11: L3 | CJ11: % | CL11: L4 | CM11: % | CO11: L5 | CP11: % | CR11: L6 | CS11: % | CU11: L7 | CV11: % | CX11: L8 | CY11: %
A12: Austria | B12: EAT | AA12: North East | AB12: USA01 | BA12: Antigua & Barbuda | BB12: BAG | CA12: China Typhoon | CB12: FCT
A13: Belgium | B13: EBE | AA13: Mid Atlantic | AB13: USA02 | BA13: Bahamas | BB13: BAH | CA13: China Earthquake | CB13: FCQ
A14: Switzerland | B14: ECH | AA14: Carolinas + Georgia | AB14: USA03 | BA14: Anquilla | BB14: BAN | CA14: Korea | CB14: FKR
A15: Denmark | B15: EDK | AA15: Florida South East | AB15: USA04 | BA15: Barbados | BB15: BBB | CA15: Hong Kong | CB15: FHK
A16: Europe Multi zone | B16: EMZ | AA16: Florida North East | AB16: USA05 | BA16: Turks & Caicos | BB16: BBH | CA16: Indonesia | CB16: FIA
A17: Finland | B17: EFI | AA17: AL + MS | AB17: USA06 | BA17: Bermuda | BB17: BBM | CA17: Philippines | CB17: OPH
A18: France | B18: EFR | AA18: Louisiana | AB18: USA07 | BA18: Cuba | BB18: BCB | CA18: Singapore | CB18: FSP
A19: Germany | B19: EGE | AA19: Texas East | AB19: USA08 | BA19: Grand Cayman | BB19: BCM | CA19: Sri Lanka | CB19: FSK
A20: Iceland | B20: EIC | AA20: Texas West | AB20: USA09 | BA20: Curacao & Aruba | BB20: BCU | CA20: Taiwan | CB20: FTA
A21: Ireland | B21: EIE | AA21: Los Angeles | AB21: USA10 | BA21: Dominica | BB21: BDO | CA21: Japan Quake | CB21: FJQ
A22: Netherlands | B22: ENL | AA22: San Francisco | AB22: USA11 | BA22: Dominican Republic | BB22: BDR | CA22: Japan Wind | CB22: FJW
A23: Norway | B23: ENO | AA23: Pacific NW | AB23: USA12 | BA23: Greneda | BB23: BGN | CA23: Bangladesh | CB23: MBD
... A27: UK Flood | B27: EUF | AA27: Hawaii + Alaska | AB27: USA16 | BA27: Jamaica | BB27: BJM | CA27: Maldives | CB27: MMA
AA28: 2nd event cover | AB28: USA20 | BA28: St Kitts & Nevis | BB28: BKN | CA28: Myanmar | CB28: FBY
A29: Southern Europe | C29: L1 | D29: % | F29: L2 | G29: % | I29: L3 | J29: % | L29: L4 | M29: % | O29: L5 | P29: % | R29: L6 | S29: % | U29: L7 | V29: % | X29: L8 | Y29: % | AA29: Wildfire | AB29: USA21 | BA29: Martinique | BB29: BMQ | CA29: Nepal | CB29: FNP
A30: Spain | B30: EES | AA30: Flood | AB30: USA22 | BA30: Montserrat | BB30: BMS | CA30: Pakistan | CB30: MPK
A31: Greece | B31: EGR | BA31: Bonaire | BB31: BON | CA31: Papua New Guinea | CB31: OPG
A32: Italy | B32: EIT | AA32: Latin America | AC32: L1 | AD32: % | AF32: L2 | AG32: % | AI32: L3 | AJ32: % | AL32: L4 | AM32: % | AO32: L5 | AP32: % | AR32: L6 | AS32: % | AU32: L7 | AV32: % | AX32: L8 | AY32: % | BA32: Puerto Rico | BB32: BPR | CA32: Thailand | CB32: FTH
A33: Portugal | B33: EPT | AA33: Argentina | AB33: SAR | BA33: St Lucia | BB33: BSL | CA33: Vietnam | CB33: FVN
A34: Turkey | B34: ETU | AA34: Belize | AB34: SBZ | BA34: St Vincent | BB34: BSV
AA35: Bolivia | AB35: SBV | BA35: Virgin Islands (UK) | BB35: BV1 | CA35: AMEI | CC35: L1 | CD35: % | CF35: L2 | CG35: % | CI35: L3 | CJ35: % | CL35: L4 | CM35: % | CO35: L5 | CP35: % | CR35: L6 | CS35: % | CU35: L7 | CV35: % | CX35: L8 | CY35: %
AA36: Brazil | AB36: SBR | BA36: Virgin Islands (US) | BB36: BVS | CA36: Israel | CB36: MIS
A37: CEE | C37: L1 | D37: % | F37: L2 | G37: % | I37: L3 | J37: % | L37: L4 | M37: % | O37: L5 | P37: % | R37: L6 | S37: % | U37: L7 | V37: % | X37: L8 | Y37: % | AA37: Chile | AB37: SCL | BA37: Trinidad & Tobago | BB37: BX7 | CA37: India | CB37: MIN
A38: Bulgaria | B38: EBG | AA38: Colombia | AB38: SCO | CA38: South Africa | CB38: ASA
A39: CEE Flood | B39: CEF | AA39: Costa Rica | AB39: SCR | BA39: Canada | BC39: L1 | BD39: % | BF39: L2 | BG39: % | BI39: L3 | BJ39: % | BL39: L4 | BM39: % | BO39: L5 | BP39: % | BR39: L6 | BS39: % | BU39: L7 | BV39: % | BX39: L8 | BY39: % | CA39: United Arab Emirates | CB39: MAE
A40: Croatia | B40: ECX | AA40: Ecuador | AB40: SEC | BA40: British Columbia | BB40: CBC | CA40: Bahrain | CB40: MBA
A41: Czech Republic | B41: ECZ | AA41: El Salvador | AB41: SEL | BA41: Quebec | BB41: CQU | CA41: Algeria | CB41: AAL
A42: Hungary | B42: EHU | AA42: Guatemala | AB42: SGT | BA42: Ontario | BB42: CON | CA42: Morocco | CB42: AMO
A43: Poland | B43: EPL | AA43: Guyana | AB43: SGY | BA43: Prairies | BB43: CPR | CA43: Egypt | CB43: AEG
A44: Romania | B44: ERO | AA44: Honduras | AB44: SHN | BA44: Atlantic | BB44: CAT | CA44: Libya | CB44: ALI
A45: Russia | B45: ERU | AA45: Mexico | AB45: SMX | CA45: Mauritius | CB45: AMU
A46: Slovenia | B46: ESB | AA46: Nicaragua | AB46: SNQ | CA46: Jordan | CB46: MJO
A47: Slovakia | B47: ESC | AA47: Panama | AB47: SPA | CA47: Oman | CB47: MOM
...
