Workbook
Name AggregatePolicyClaims.UniqueMapping: #REF!
Name anti_selection_total: 'Note Tables'!$G$152
Name anti_selection_uncertainty: 'Note Tables'!$C$29
Name avg_limit: 'Note Tables'!$C$17
Name BeazleyProjections.SummaryTable.OffsetFormulasCustom: #REF!,#REF!
Name Behavior.Inputs.KVRange: OFFSET(#REF!,0,0,COUNTA(#REF!),1),OFFSET(#REF!,0,0,COUNTA(#REF!),1)
Name best_estimate_excl_loads: 'Note Tables'!$E$31
Name best_estimate_gn_total: 'Note Tables'!$K$152
Name best_estimate_total: 'Note Tables'!$F$152
Name BI_SaveColumn: #REF!
Name bp_gn_ulr_total: 'Note Tables'!$G$94
Name bp_proj_total: 'Note Tables'!$J$94
Name bpi_excl_loads: 'Note Tables'!$E$32
Name bpi_final: 'Note Tables'!$E$212
Name bpi_pre_adj: 'Note Tables'!$I$212
Name ClassLookup: OFFSET(#REF!,0,0,COUNTA(#REF!),1)
Name climate_change_total: 'Note Tables'!$E$152
Name CoverDetails.tbl1_forProjectionsShts: #REF!
Name DB.AggregatePolicyClaims.AsAtDate: #REF!
Name DB.AggregatePolicyClaims.PriceAttritionalClaimsUpTo: #REF!
Name DB.ApplicationID: #REF!
Name DB.BzlProj.tbl1_IELROption1: #REF!
Name DB.BzlProj.tbl2_IELROption1: #REF!
Name DB.CatIndicator: #REF!
Name DB.Claim.ClaimDate: #REF!
Name DB.Claim.NetOfRetentions: #REF!
Name DB.CoverDetails.AggregatePolicyandClaimsIndicator: #REF!
Name DB.CoverDetails.Benchmarktrifocus1: #REF!
Name DB.CoverDetails.Benchmarktrifocus10: #REF!
Name DB.CoverDetails.Benchmarktrifocus2: #REF!
Name DB.CoverDetails.Benchmarktrifocus3: #REF!
Name DB.CoverDetails.Benchmarktrifocus4: #REF!
Name DB.CoverDetails.Benchmarktrifocus5: #REF!
Name DB.CoverDetails.Benchmarktrifocus6: #REF!
Name DB.CoverDetails.Benchmarktrifocus7: #REF!
Name DB.CoverDetails.Benchmarktrifocus8: #REF!
Name DB.CoverDetails.Benchmarktrifocus9: #REF!
Name DB.CoverDetails.Brokerage: #REF!
Name DB.CoverDetails.ClassOfBusiness1: #REF!
Name DB.CoverDetails.ClassOfBusiness10: #REF!
Name DB.CoverDetails.ClassOfBusiness2: #REF!
Name DB.CoverDetails.ClassOfBusiness3: #REF!
Name DB.CoverDetails.ClassOfBusiness4: #REF!
Name DB.CoverDetails.ClassOfBusiness5: #REF!
Name DB.CoverDetails.ClassOfBusiness6: #REF!
Name DB.CoverDetails.ClassOfBusiness7: #REF!
Name DB.CoverDetails.ClassOfBusiness8: #REF!
Name DB.CoverDetails.ClassOfBusiness9: #REF!
Name DB.CoverDetails.COBLineSize1: #REF!
Name DB.CoverDetails.COBLineSize10: #REF!
Name DB.CoverDetails.COBLineSize2: #REF!
Name DB.CoverDetails.COBLineSize3: #REF!
Name DB.CoverDetails.COBLineSize4: #REF!
Name DB.CoverDetails.COBLineSize5: #REF!
Name DB.CoverDetails.COBLineSize6: #REF!
Name DB.CoverDetails.COBLineSize7: #REF!
Name DB.CoverDetails.COBLineSize8: #REF!
Name DB.CoverDetails.COBLineSize9: #REF!
Name DB.CoverDetails.Commission: #REF!
Name DB.CoverDetails.ExpensesorFees: #REF!

Sheet LOG
A1: Version Control Log
B5: Index | C5: Version Name | D5: File Name | E5: Version Index | F5: Date | G5: Modified By | H5: Sheet | I5: Range | J5: Details
B6: 1 | C6: Initial version provided to Hx | D6: HX - Portfolio Underwriting MOCK RATER - v8 | E6: Initial version | F6: 45674 | G6: Dimitri Lyulik / Rita Zannetou | H6: Multiple | I6: Multiple | J6: Multiple
H7: Risk Information | J7: Brought in drop downs for currency, status, account type, insured name, broker name
J8: Adjusted settings section
H9: Policy Level Data | J9: Adjusted how the FX conversion works
H10: Claim Level Data | J10: Adjusted how the FX conversion works
H11: Rate Change | J11: Changed formula to pick up dominat risk code and remove depdendent on pivot table
H12: Premium and Limit profil | J12: Added ranking so that most material classes appear first from left to right on final selections
H13: RMS | J13: Changed lable to CAT
J14: Adjusted how the FX conversion works
H15: Own Experience | J15: Removed override of Large / Cat from LoB projection section -- override in summary available at the top
J16: Correction to Latest Incurred formula -- toggles werent working correctly
H17: PC | J17: Added COV basis separate for Attr / Lrg / Cat + total re-scaling depending on selection
J18: Adjust r Code for changed name ranges
J19: Corrected ULR input from final selections
H20: PC (BBT) | J20: Added PC calculation tab for if following BBT pricing
H21: Antiselection | J21: moved reference tables
H22: Uncertainty | J22: moved reference tables
H23: Final Selections | J23: Corrected formulas for some cells
J24: Added Trifocus Level summary at the bottom
B25: 2 | C25: =D25 -> HX - Portfolio Underwriting MOCK RATER - v9 | D25: HX - Portfolio Underwriting MOCK RATER - v9 | E25: =D25 -> HX - Portfolio Underwriting MOCK RATER - v9 | F25: 45681 | G25: Rita Zannetou | H25: Risk Code Composition | I25: Column W, Columns AD:AS | J25: In cases where certain risk codes are excluded (Model = No), the Final Selected Composition table should display only the 'modelled' risk codes along with their compositions. I modified the formulas and added additional calculation columns to support this adjustment. No change to UI.
B26: 3 | C26: =D26 -> HX - Portfolio Underwriting MOCK RATER - v10 | D26: HX - Portfolio Underwriting MOCK RATER - v10 | E26: =D26 -> HX - Portfolio Underwriting MOCK RATER - v10 | F26: 45687 | G26: Rita Zannetou | H26: Multiple | I26: Multiple | J26: Multiple
H27: Risk Code Composition | J27: Modified formula in cells AJ46:AJ65, to handle index match for risk codes with the same compositon percentage
J28: Connect the toggle in cell C5 to Risk Information tab: If Premium Data available = "Yes", set to "Data"; but allow for manual entry override. Manually overriding the value in cell C5 would replace any formula currently
J29: Modified the formula in columns O and U, "Exists in Data?" for both Data and Manual sections
H30: Risk Code Library | J30: Several changes to the Assigned Tracker Class and Assigned BP Class columns
J31: Adjusted the forumla for the "Do We Model?" column. The formula now results in "Yes" if the risk code is found in the Lloyds Risk Code Data tab and if the number of years of data is greater than 3. Added an additional helper column to support this adjustment.
H32: Policy Level Data | J32: Adjusted how the formulas in columns AT and AU work
H33: Claim Level Data | J33: Adjusted how the formulas in columns X and Y work
H34: Own Experience | J34: Correction to Latest Incurred formula - CLOSED CLAIMS
H35: Rate Change | J35: Added "Blend" method in Source dropdown and changed the formula for the selected rate change in 2025 to pick up values from the helper column if Blend is selected.
H36: BP Projections | I36: V31:V45 | J36: We have added a calculation and made these cells overridable. The formula checks for the 2025 rate change source. If 'Facility' is selected, it picks up the Selected Rate Change from the rate change tab; otherwise, it remains blank.
B37: 4 | C37: =D37 -> HX - Portfolio Underwriting MOCK RATER - v11 | D37: HX - Portfolio Underwriting MOCK RATER - v11 | E37: =D37 -> HX - Portfolio Underwriting MOCK RATER - v11 | F37: 45698 | G37: Rita Zannetou | H37: Deductions | I37: C5 | J37: Added a dropdown in cell C5 for Data/Manual options
H38: Risk Code Library | I38: Column BU | J38: Corrected the formula in column U (number of years of data) so that it counts the number of years with premium data looking up from the risk codes in column C.
H39: Inflation | I39: Column F | J39: Updated the column heading from 'Inflation Class' to 'BP Class'
I40: G21:AF40 | J40: Updated the formula to reference the latest inflation tables (R.Base.Inf and R.Excess.Inf)
H41: BP Projections | J41: Adjusted how the formula works in range V31:45. The formula checks for the 2025 rate change source. If 'Facility' OR ' Blend' is selected, it picks up the Selected Rate Change from the rate change tab; otherwise, it remains blank.
H42: R.Base.Inf | J42: Updated the inflation rates in the Base Inf table and removed the unnecessary columns
H43: R.Excess.Inf | J43: Updated the inflation rates in the Excess Inf table and removed the unnecessary columns
...

Sheet Schematic
S22: Open "Expiring Option" hidden section

Sheet Note Tables
A1: Pricing Note Tables | AJ1: 1
AJ2: 1 | AK2: 1 | AL2: start
AJ3: 1 | AK3: =COUNT(AJ1:AJ757) -> 358 | AL3: end
B4: Key Risk Details | C4: Comments | AJ4: 1
B5: Insured | AJ5: 1
B6: Policy Reference | AJ6: 1
B7: Underwriter | AJ7: 1
B8: Facility Type | AJ8: 1
B9: Deal Status
B10: key LOB | AJ10: 1
B11: Trifocus | AJ11: 1
B12: Lloyd's Risk Codes (Top 5) | AJ12: 1
B13: New Business / Renewal | AJ13: 1
B14: Inception | AJ14: 1
B15: Expiry
B16: % Line Size | AJ16: 1
B17: 100% Max / Average Limit | AJ17: 1
B18: 5623 GN Premium | AJ18: 1
B19: Total Deductions | AJ19: =IF(C368=0,0,1) -> 0
AJ20: =IF(D368=0,0,1) -> 0
AJ21: =IF(E368=0,0,1) -> 0
AJ22: =IF(F368=0,0,1) -> 0
AJ23: =IF(G368=0,0,1) -> 0
AJ24: =IF(H368=0,0,1) -> 0
B25: Profit Commission | AJ25: 1
AJ26: 1
AJ27: 1
B28: Pricing Outputs | C28: Pricing Basis | E28: Excluding A-S & Uncertainty Loads | AJ28: 1
B29: Anti-Selection / Uncertainty | E29: - / - | AJ29: 1
B30: PC impact on GN ULR | AJ30: 1
B31: GN ULR % net of PC | AJ31: 1
B32: BPI % | AJ32: 1
B33: TPI % | AJ33: 1
B34: RoC % | AJ34: 1
B35: Key Uncertainties | AJ35: 1
AJ36: 1
AJ37: 1
AJ38: 1
B39: Model GN ULR by Methodology | AJ39: 1
E40: Methodology 1 | F40: Methodology 2 | G40: Methodology 3 | H40: Weight 1 | I40: Weight 2 | J40: Weight 3 | AJ40: 1 | AO40: Methodology 1 | AP40: Methodology 2 | AQ40: Methodology 3 | AR40: Methodology 4 | AS40: Methodology 5 | AT40: Weight 1 | AU40: Weight 2 | AV40: Weight 3 | AW40: Weight 4 | AX40: Weight 5
...

Sheet PC (BBT)
A1: PROFIT COMMISSION CALCS -- IF BENCHMARKING AGAINST 2623 / BBT
B3: PC Type | E3: Deficit Carry forward Option
B4: Standard | E4: $ Amount | G4: Input
B8: $ Amount | C8: Basis
B9: 10000 | C9: Total Contract | D9: Input
C18: 1 | F18: Total
B19: Line of Business | C19: =#REF! -> #REF!
E20: calculated
B21: 5623 GWP | C21: =C23/(1-C22) -> #REF! | E21: calculated | F21: =SUM(C21:D21) -> #REF!
B22: Total Deductions | C22: =#REF! -> #REF! | E22: calculated | F22: =1-F23/F21 -> #REF! | W22: R INPUTS | AI22: R OUTPUTS
B23: 5623 NWP | C23: =#REF! -> #REF! | E23: calculated | F23: =SUM(C23:D23) -> #REF!
W24: PC Options | AA24: distribution params | AE24: premium info
B25: Benchmark Class Auto | C25: =#REF! -> #REF! | I25: CoV Calibration and GN ULR Allocation | R25: Deficit Carry-forward calculation
B26: Benchmark Class Override | C26: Open Market | E26: Input | W26: option | X26: lob_1 | Y26: lob_2 | AE26: option | AF26: lob_1 | AG26: lob_2 | AI26: LoB | AJ26: avg_contract_attr | AK26: avg_contract_lrg | AL26: avg_contract_cat | AM26: avg_contract_total | AN26: avg_contract_p_l | AO26: avg_binder_total | AP26: avg_binder_p_l | AQ26: avg_binder_pc | AR26: avg_contract_pc | AS26: avg_total_pc | AT26: avg_gnp_less_pc | AU26: pc_impact | AV26: pc_impact_tot_ind | AW26: pc_impact_tot_interlock | AX26: pc_impact_scaled | AY26: avg_total_pc_scaled | AZ26: avg_gnp_less_pc_scaled
B27: Benchmark Class Applied | C27: =IF(C26="",C25,C26) -> Open Market | I27: SELECTED GN ULR Allocation | L27: BBT Parametrisation | O27: Experience Parametrisation | R27: Type | S27: =IF($E$4="Experience","Years",IF($E$4="$ Amount","$ Amount","")) -> $ Amount | T27: =IF($E$4="Experience",E9,IF($E$4="$ Amount",B9,"")) -> 10000 | U27: =F9 -> 0 | W27: pc_type | X27: =$B$4 -> Standard | Y27: =$B$4 -> Standard | AE27: gwp | AF27: =C21 -> #REF! | AG27: =D21 -> 0 | AI27: Lob_1 | AJ27: 376139.05 | AK27: 225274.12 | AL27: 315825.94 | AM27: 917239.11 | AN27: 110664.11 | AO27: 0 | AP27: 0 | AQ27: 0 | AR27: 44257.948 | AS27: 44257.948 | AT27: 1255742.1 | AU27: 0.024867381 | AV27: 0.024867381 | AW27: 0.024867381 | AX27: 0.024867381 | AY27: 44257.948 | AZ27: 1255742.1
B28: CoV Basis: Attritional | C28: BBT | E28: calculated | I28: =$C$27 -> Open Market | L28: =$C$27 -> Open Market | R28: LoB 1 Gross Premium | S28: =IF($S$27="Years", IF($U$27="Incurred",SUM(OFFSET(#REF!,0,0,1,-'PC (BBT)'!$T$27)),SUM(OFFSET(#REF!,0,0,-'PC (BBT)'!$T$27))/(1-C22)),"") | W28: pc_interlock | X28: No | Y28: No | AE28: deduct_perc | AF28: =C22 -> #REF! | AG28: =D22 -> 0 | AI28: Lob_2 | AJ28: 0 | AK28: 0 | AL28: 0 | AM28: 0 | AN28: 0 | AO28: 0 | AP28: 0 | AQ28: 0 | AR28: 0 | AS28: 0 | AT28: 0 | AU28: 0 | AV28: 0 | AW28: 0 | AX28: 0 | AY28: 0 | AZ28: 0
B29: CoV Basis: Large | C29: BBT | E29: calculated | I29: =IF(C28="Experience",O29,L29) -> #REF! | L29: =INDEX(#REF!,MATCH(L$28,#REF!,0))/L$32 -> #REF! | R29: LoB 2 Gross Premium | S29: =IF($S$27="Years", IF($U$27="Incurred",SUM(OFFSET(#REF!,0,0,1,-'PC (BBT)'!$T$27)),SUM(OFFSET(#REF!,0,0,-'PC (BBT)'!$T$27))/(1-C22)),"") | W29: underlying_pc | X29: No | Y29: No | AA29: param | AB29: lob_1 | AC29: lob_2 | AE29: nwp | AF29: =C23 -> #REF! | AG29: =D23 -> 0
B30: CoV Basis: CAT | C30: BBT | E30: calculated | I30: =IF(C29="Experience",O30,L30) -> #REF! | L30: =INDEX(#REF!,MATCH(L$28,#REF!,0))/L$32 -> #REF! | W30: prop_underlying | X30: 0 | Y30: 0 | AA30: rms | AB30: =IF(C43>0,"Yes","No") -> #REF! | AC30: =IF(D43>0,"Yes","No") -> No
B31: Attritional GG ULR % | C31: =C$34*(I29/I$32) -> #REF! | E31: calculated | F31: =SUMPRODUCT(C31:D31,$C$21:$D$21)/SUM($C$21:$D$21) -> #REF! | I31: =IF(C30="Experience",O31,L31) -> #REF! | L31: =INDEX(#REF!,MATCH(L$28,#REF!,0))/L$32 -> #REF! | R31: LoB 1 Market Brokerage | S31: =IF($S$27="Years",IF($U$27="Incurred",S28-SUM(OFFSET(#REF!,0,0,1,-'PC (BBT)'!$T$27)),""),"") | W31: underlying_pc_exp | X31: No | Y31: No | AA31: =K41 -> attr_mu | AB31: =IF(L41="",0,L41) -> #REF! | AC31: =IF(M41="",0,M41) -> 0
B32: Large GG ULR % | C32: =C$34*(I30/I$32) -> #REF! | E32: calculated | F32: =SUMPRODUCT(C32:D32,$C$21:$D$21)/SUM($C$21:$D$21) -> #REF! | I32: =SUM(I29:I31) -> #REF! | L32: =INDEX(#REF!,MATCH(L$28,#REF!,0))+INDEX(#REF!,MATCH(L$28,#REF!,0))+INDEX(#REF!,MATCH(L$28,#REF!,0)) -> #REF! | R32: LoB 2 Market Brokerage | S32: =IF($S$27="Years",IF($U$27="Incurred",S29-SUM(OFFSET(#REF!,0,0,1,-'PC (BBT)'!$T$27)),""),"") | AA32: =K42 -> attr_sigma | AB32: =IF(L42="",0,L42) -> #REF! | AC32: =IF(M42="",0,M42) -> 0 | AE32: EL Scale
B33: CAT GG ULR % | C33: =C$34*(I31/I$32) -> #REF! | E33: calculated | F33: =SUMPRODUCT(C33:D33,$C$21:$D$21)/SUM($C$21:$D$21) -> #REF! | W33: DCF | AA33: =K43 -> lrg_alpha | AB33: =IF(L43="",0,L43) -> #REF! | AC33: =IF(M43="",0,M43) -> 0
B34: Total GG ULR % | C34: =#REF!*(1-C22) -> #REF! | E34: calculated | F34: =SUMPRODUCT(C34:D34,$C$21:$D$21)/SUM($C$21:$D$21) -> #REF! | L34: =INDEX(#REF!,MATCH(L$28,#REF!,0)) -> #REF! | R34: LoB 1 Fees | S34: =IF($S$27="Years",IF($U$27="Incurred",S28*SUM(#REF!),""),"") | W34: option | X34: lob_1 | Y34: lob_2 | AA34: =K44 -> lrg_beta | AB34: =IF(L44="",0,L44) -> #REF! | AC34: =IF(M44="",0,M44) -> 0 | AE34: option | AF34: lob_1 | AG34: lob_2
L35: =INDEX(#REF!,MATCH(L$28,#REF!,0)) -> #REF! | R35: LoB 2 Fees | S35: =IF($S$27="Years",IF($U$27="Incurred",S29*SUM(#REF!),""),"") | W35: dcf | X35: =S52 -> #REF! | Y35: =S53 -> #REF! | AA35: =K45 -> cat_alpha | AB35: =IF(L45="",0,L45) -> 0 | AC35: =IF(M45="",0,M45) -> 0 | AE35: attr_scale | AF35: =C40 -> #REF! | AG35: =D40 -> 0
B36: Attritional CoV | C36: =IF(C28="Experience",O34,L34) -> #REF! | E36: calculated | F36: =SUMPRODUCT(C36:D36,$C$21:$D$21)/SUM($C$21:$D$21) -> #REF! | L36: =INDEX(#REF!,MATCH(L$28,#REF!,0)) -> #REF! | AA36: =K46 -> cat_beta | AB36: =IF(L46="",0,L46) -> 0 | AC36: =IF(M46="",0,M46) -> 0 | AE36: lrg_scale | AF36: =C41 -> #REF! | AG36: =D41 -> 0
B37: Large CoV | C37: =IF(C29="Experience",O35,L35) -> #REF! | E37: calculated | F37: =SUMPRODUCT(C37:D37,$C$21:$D$21)/SUM($C$21:$D$21) -> #REF! | R37: LoB 1 Gross Net Premium | S37: =IF($S$27="Years", IF($U$27="Incurred",S28-S31-S34, SUM(OFFSET(#REF!,0,0,-'PC (BBT)'!$T$27))),"") | W37: PC structure standard | AA37: =K47 -> cat_w_p1 | AB37: =IF(L47="",0,L47) -> #REF! | AC37: =IF(M47="",0,M47) -> 0 | AE37: cat_scale | AF37: =IF(C42=0,C43,C42) -> #REF! | AG37: =IF(D42=0,D43,D42) -> 0
B38: CAT CoV | C38: =IF(C30="Experience",O36,L36) -> #REF! | E38: calculated | F38: =SUMPRODUCT(C38:D38,$C$21:$D$21)/SUM($C$21:$D$21) -> #REF! | R38: LoB 2 Gross Net Premium | S38: =IF($S$27="Years", IF(U27="Incurred", S29-S32-S35,SUM(OFFSET(#REF!,0,0,-'PC (BBT)'!$T$27))),"") | AA38: =K48 -> cat_w_p2 | AB38: =IF(L48="",0,L48) -> #REF! | AC38: =IF(M48="",0,M48) -> 0
I39: Distribution Parameter Fitting | W39: option | X39: lob_1 | Y39: lob_2
B40: Attritional EL | C40: =C31*C$21 -> #REF! | E40: calculated | F40: =SUM(C40:D40) -> #REF! | L40: lob 1 | M40: lob 2 | R40: LoB 1 UW Expenses | S40: =IFERROR(IF(C74="Gross Premium",C73*S28,C73*S37),"") | W40: ew_exp | X40: =C73 -> 0.15 | Y40: =D73 -> 0 | AA40: correlation matrix
B41: Large EL | C41: =C32*C$21 -> #REF! | E41: calculated | F41: =SUM(C41:D41) -> #REF! | K41: attr_mu | L41: =LN((C40^2)/SQRT(C45^2+C40^2)) -> #REF! | O41: lognormal | R41: LoB 2 UW Expenses | S41: =IFERROR(IF(D74="Gross Premium",D73*S29,D73*S38),"") | W41: uw_exp_basis | X41: =C74 -> Gross Premium | Y41: =D74 -> 0
B42: CAT (Non-Weather) EL | C42: =IF(C43=0,C33*C21,0) -> #REF! | E42: calculated | F42: =SUM(C42:D42) -> #REF! | K42: attr_sigma | L42: =SQRT(LN(1+(C45^2)/(1+C40^2))) -> #REF! | O42: lognormal | W42: pc_perc | X42: =C75 -> 0.2 | Y42: =D75 -> 0 | AA42: LoB 1 | AB42: LoB 2
B43: CAT (Weather) EL | C43: =IF(AND(C30="Experience",#REF!="RMS"),C33*C$21,0) -> #REF! | E43: calculated | F43: =SUM(C43:D43) -> #REF! | K43: lrg_alpha | L43: =1+(C41/C46) -> #REF! | O43: pareto | R43: LoB 1 Expected Losses | S43: =IF($S$27="Years",IF($U$27="Incurred",SUM(OFFSET(#REF!,0,0,-'PC (BBT)'!$T$27)),SUM(OFFSET(#REF!,0,0,-'PC (BBT)'!$T$27))),"") | AA43: 1 | AB43: ='PC (BBT)'!D65 -> 0
K44: lrg_beta | L44: =(C41*(L43-1))/L43 -> #REF! | O44: pareto | R44: LoB 2 Expected Losses | S44: =IF($S$27="Years",IF($U$27="Incurred",SUM(OFFSET(#REF!,0,0,-'PC (BBT)'!$T$27)),SUM(OFFSET(#REF!,0,0,-'PC (BBT)'!$T$27))),"") | AA44: ='PC (BBT)'!C66 -> 0 | AB44: 1
B45: Attritional SD | C45: =C40*C36 -> #REF! | E45: calculated | F45: =SUM(C45:D45) -> #REF! | K45: cat_alpha | L45: =IFERROR(1+SQRT(1+(C42/C47)^2),"") | O45: pareto | W45: PC structure sliding 1
B46: Large SD | C46: =C41*C37 -> #REF! | E46: calculated | F46: =SUM(C46:D46) -> #REF! | K46: cat_beta | L46: =IFERROR(((L45-1)*C42)/L45,"") | O46: pareto | R46: LoB 1 P/L | S46: =IF($S$27="Years",S37-S40-S43,$T$27) -> 10000
B47: CAT (Non-Weather) SD | C47: =C42*C38 -> #REF! | E47: calculated | F47: =SUM(C47:D47) -> #REF! | K47: cat_w_p1 | L47: {=EXP(INDEX(LINEST(LN(#REF!),SQRT(#REF!)),1,2))} -> #REF! | O47: exponential | R47: LoB 2 P/L | S47: =IF($S$27="Years",S38-S41-S44,$T$27) -> 10000 | W47: option | X47: lob_1 | Y47: lob_2
B48: CAT (Weather) SD | C48: =C43*C38 -> #REF! | E48: calculated | F48: =SUM(C48:D48) -> #REF! | K48: cat_w_p2 | L48: {=INDEX(LINEST(LN(#REF!),SQRT(#REF!)),1)} -> #REF! | O48: exponential | W48: ew_exp | X48: =C79 -> 0.15 | Y48: =X48 -> 0.15
R49: LoB 1 Beazley Share | S49: {=IF(AND($E$4="$ Amount",$C$9="Total Contract"),1,SUMPRODUCT(#REF!,#REF!,--($C$19=#REF!))/SUMPRODUCT(#REF!,--($C$19=#REF!)))} -> 1 | W49: uw_exp_basis | X49: =C80 -> Gross Premium | Y49: =X49 -> Gross Premium
R50: LoB 2 Beazley Share | S50: {=IF(AND($E$4="$ Amount",$C$9="Total Contract"),1,SUMPRODUCT(#REF!,#REF!,--($D$19=#REF!))/SUMPRODUCT(#REF!,--($D$19=#REF!)))} -> 1
R52: LoB 1 DCF | S52: =IF($S$27="None",0,IF($S$27="$ Amount",-S46,IF(S46>0,0,S46)))*IF(S27="$ Amount",(C21/SUM(C21:D21)),1)*S49 -> #REF! | W52: PC structure sliding 2
R53: LoB 2 DCF | S53: =IF($S$27="None",0,IF($S$27="$ Amount",-S47,IF(S47>0,0,S47)))*IF(S27="$ Amount",(D21/SUM(C21:D21)),1)*S50 -> #REF!
...

Sheet OLD>>

Sheet Final Selections - wide
C7: Business Plan | D7: ULR Apportionment
AJ9: Excluding anti-selection, uncertainty and recessionary charge | AQ9: HIDE / UNHIDE THIS SECTION (IF DETAILS WANTD)
B10: Facility LoB Summary | H10: calculated | I10: calculated | J10: calculated | K10: calculated | L10: Input | M10: Input | N10: Input | O10: Input | P10: Input | Q10: Input | R10: Input | S10: Input | AB10: (-10% to +10%) | AY10: =AX13*AW13*(1-AU13) -> 0 | BA10: ULR apportionment | BF10: Attritional / Large / Cat
C11: calculated | D11: calculated | E11: calculated | F11: calculated | G11: calculated | H11: Methodology 1 | I11: Methodology 2 | J11: Methodology 3 | K11: Methodology 4 | L11: Methodology 5 | M11: Methodology 6 | N11: Weighting 1 | O11: Weighting 2 | P11: Weighting 3 | Q11: Weighting 4 | R11: Weighting 5 | S11: Weighting 6 | T11: calculated | U11: calculated | V11: calculated | W11: calculated | X11: calculated | Y11: calculated | Z11: Input | AA11: calculated | AB11: Input | AC11: calculated | AD11: calculated | AE11: calculated | AF11: calculated | AG11: calculated | AJ11: calculated | AK11: calculated | AL11: calculated | AM11: calculated | AN11: calculated
C12: Tracker Class | D12: Grouped Line of Business | E12: Line of Business | F12: 2025 GN Premium | G12: % of Portfolio | H12: Own Experience GN ULR % | I12: Lloyd's Risk Code GN ULR % | J12: Beazley Own Projections GN ULR % | K12: Business Plan GN ULR % | L12: Beazley 623 Pricing GN ULR % | M12: Case Pricing GN ULR % | N12: Own Experience GN ULR % | O12: Lloyd's Risk Code GN ULR % | P12: Beazley Own Projections GN ULR % | Q12: Business Plan GN ULR % | R12: Beazley 623 Pricing GN ULR % | S12: Case Pricing GN ULR % | T12: Weighting Check | U12: Best Estimate GN ULR % (Pre-Loading) | V12: Climate Change Loading % | W12: NMP Loading % | X12: Anti-Selection Charge % | Y12: Uncertainty Charge % | Z12: Recessionary Charge % | AA12: Best Estimate GN ULR % (Pre UW Adj) | AB12: UW Adjustment | AC12: Best Estimate GN ULR % (Post UW Adj) | AD12: PC % Impact on GN ULR | AE12: Best Estimate GN ULR % | AF12: BPI | AG12: TPI | AH12: RoC | AJ12: Best Estimate GN ULR % (Post UW Adj) | AK12: PC % Impact on GN ULR | AL12: Best Estimate GN ULR % | AM12: BPI | AN12: TPI | AO12: RoC | AQ12: EL | AR12: EL (Excl. Anti-selection load, after PC) | AS12: Net Expense/ GN Premium | AT12: Investment Income / NN Premium | AU12: RI Premium/GN Premium | AV12: RI Recoveries/ GN Premium | AW12: Capital Required / NN Premium | AX12: Target RoC | AY12: Technical Premium | AZ12: Technical Premium (exl. Loads) | BA12: Attritional | BB12: Large | BC12: Attritional + Large | BD12: Cat | BF12: Attritional | BG12: Large | BH12: Attritional + Large | BI12: Cat
B13: 1 | C13: =INDEX(#REF!,MATCH($E13,#REF!,0)) -> #REF! | D13: =INDEX(#REF!,MATCH($E13,#REF!,0)) -> #REF! | E13: {=_xlfn.UNIQUE(#REF!)} -> #REF! | F13: =SUMIFS(#REF!,_xlfn.ANCHORARRAY(#REF!),E13) -> #REF! | G13: =F13/$F$29 -> #REF! | H13: 0.93474633 | I13: 0.81989532 | J13: 0.43638317 | K13: 0.95308398 | L13: 0.23317539 | M13: 0.66451085 | N13: 0.5 | O13: 0.5 | P13: 0 | Q13: 0 | R13: 0 | S13: 0 | T13: =SUM(N13:S13)=1 -> TRUE | U13: =SUMPRODUCT(H13:M13,N13:S13) -> 0.87732082 | V13: =INDEX(#REF!,MATCH($E13,_xlfn.ANCHORARRAY(#REF!),0)) -> #REF! | W13: =INDEX(#REF!,MATCH($E13,_xlfn.ANCHORARRAY(#REF!),0))+INDEX(#REF!,MATCH($E13,_xlfn.ANCHORARRAY(#REF!),0)) -> #REF! | X13: 0.0125 | Y13: 0 | Z13: 0 | AA13: =U13*BC13+U13*BD13*(1+V13)+SUM(W13:Z13) -> #REF! | AB13: 0 | AC13: =AA13+AB13 -> #REF! | AD13: 0.012 | AE13: =AC13+AD13 -> #REF! | AF13: =0.7/AE13 -> #REF! | AG13: =IFERROR(F13/AY13,0) -> 0 | AH13: =(1-AE13-($AU13-$AV13)+($AT13*(1-$AU13))-$AS13)/(($AX13*$AW13*(1-$AU13))/$AX13) -> #REF! | AJ13: =AC13-SUM(X13:Z13) -> #REF! | AK13: 0.013 | AL13: =AJ13+AK13 -> #REF! | AM13: =0.7/AL13 -> #REF! | AN13: =IFERROR(F13/AZ13,0) -> 0 | AO13: =(1-AL13-($AU13-$AV13)+($AT13*(1-$AU13))-$AS13)/(($AX13*$AW13*(1-$AU13))/$AX13) -> #REF! | AQ13: =F13*AE13 -> #REF! | AR13: =F13*AL13 -> #REF! | AS13: 0 | AT13: 0 | AU13: 0 | AV13: 0 | AW13: 0 | AX13: 0 | AY13: =AQ13/(1-AS13-(AU13-AV13)+AT13*(1-AU13)-AX13*AW13*(1-AU13)) -> #REF! | AZ13: =AR13/(1-AS13-(AU13-AV13)+AT13*(1-AU13)-AX13*AW13*(1-AU13)) -> #REF! | BA13: =IF($C$7="Business Plan",0,"placeholder") -> 0 | BB13: =IF($C$7="Business Plan",0,"placeholder") -> 0 | BC13: =IF($C$7="Business Plan",INDEX(#REF!,MATCH($E13,_xlfn.ANCHORARRAY(#REF!),0))/(INDEX(#REF!,MATCH($E13,_xlfn.ANCHORARRAY(#REF!),0))+INDEX(#REF!,MATCH($E13,_xlfn.ANCHORARRAY(#REF!),0))),BA13+BB13) -> #REF! | BD13: =IF($C$7="Business Plan",1-BC13,0) -> #REF! | BF13: =BA13*$AE13 -> #REF! | BG13: =BB13*$AE13 -> #REF! | BH13: =BC13*$AE13 -> #REF! | BI13: =BD13*$AE13 -> #REF!
B14: =1+B13 -> 2 | C14: =INDEX(#REF!,MATCH($E14,#REF!,0)) -> #REF! | D14: =INDEX(#REF!,MATCH($E14,#REF!,0)) -> #REF! | F14: =SUMIFS(#REF!,_xlfn.ANCHORARRAY(#REF!),E14) -> #REF! | G14: =F14/$F$29 -> #REF! | H14: 0.49068832 | I14: 0.26743869 | J14: 0.48952564 | K14: 0.5232361 | L14: 0.7892051 | M14: 0.86205085 | N14: 0.5 | O14: 0.5 | P14: 0 | Q14: 0 | R14: 0 | S14: 0 | T14: =SUM(N14:S14)=1 -> TRUE | U14: =SUMPRODUCT(H14:M14,N14:S14) -> 0.3790635 | V14: =INDEX(#REF!,MATCH($E14,_xlfn.ANCHORARRAY(#REF!),0)) -> #REF! | W14: =INDEX(#REF!,MATCH($E14,_xlfn.ANCHORARRAY(#REF!),0))+INDEX(#REF!,MATCH($E14,_xlfn.ANCHORARRAY(#REF!),0)) -> #REF! | X14: 0.0125 | Y14: 0 | Z14: 0 | AA14: =U14*BC14+U14*BD14*(1+V14)+SUM(W14:Z14) -> #REF! | AB14: 0 | AC14: =AA14+AB14 -> #REF! | AD14: 0.012 | AE14: =AC14+AD14 -> #REF! | AF14: =0.7/AE14 -> #REF! | AG14: =IFERROR(F14/AY14,0) -> 0 | AH14: =(1-AE14-($AU14-$AV14)+($AT14*(1-$AU14))-$AS14)/(($AX14*$AW14*(1-$AU14))/$AX14) -> #REF! | AJ14: =AC14-SUM(X14:Z14) -> #REF! | AK14: 0.013 | AL14: =AJ14+AK14 -> #REF! | AM14: =0.7/AL14 -> #REF! | AN14: =IFERROR(F14/AZ14,0) -> 0 | AO14: =(1-AL14-($AU14-$AV14)+($AT14*(1-$AU14))-$AS14)/(($AX14*$AW14*(1-$AU14))/$AX14) -> #REF! | AQ14: =F14*AE14 -> #REF! | AR14: =F14*AL14 -> #REF! | AS14: 0 | AT14: 0 | AU14: 0 | AV14: 0 | AW14: 0 | AX14: 0 | AY14: =AQ14/(1-AS14-(AU14-AV14)+AT14*(1-AU14)-AX14*AW14*(1-AU14)) -> #REF! | AZ14: =AR14/(1-AS14-(AU14-AV14)+AT14*(1-AU14)-AX14*AW14*(1-AU14)) -> #REF! | BA14: =IF($C$7="Business Plan",0,"placeholder") -> 0 | BB14: =IF($C$7="Business Plan",0,"placeholder") -> 0 | BC14: =IF($C$7="Business Plan",INDEX(#REF!,MATCH($E14,_xlfn.ANCHORARRAY(#REF!),0))/(INDEX(#REF!,MATCH($E14,_xlfn.ANCHORARRAY(#REF!),0))+INDEX(#REF!,MATCH($E14,_xlfn.ANCHORARRAY(#REF!),0))),BA14+BB14) -> #REF! | BD14: =IF($C$7="Business Plan",1-BC14,0) -> #REF! | BF14: =BA14*$AE14 -> #REF! | BG14: =BB14*$AE14 -> #REF! | BH14: =BC14*$AE14 -> #REF! | BI14: =BD14*$AE14 -> #REF!
B15: =1+B14 -> 3 | C15: =INDEX(#REF!,MATCH($E15,#REF!,0)) -> #REF! | D15: =INDEX(#REF!,MATCH($E15,#REF!,0)) -> #REF! | F15: =SUMIFS(#REF!,_xlfn.ANCHORARRAY(#REF!),E15) -> #REF! | G15: =F15/$F$29 -> #REF! | H15: 0.84362686 | I15: 0.59321658 | J15: 0.066182925 | K15: 0.69554769 | L15: 0.01907216 | M15: 0.64527096 | N15: 0.5 | O15: 0.5 | P15: 0 | Q15: 0 | R15: 0 | S15: 0 | T15: =SUM(N15:S15)=1 -> TRUE | U15: =SUMPRODUCT(H15:M15,N15:S15) -> 0.71842172 | V15: =INDEX(#REF!,MATCH($E15,_xlfn.ANCHORARRAY(#REF!),0)) -> #REF! | W15: =INDEX(#REF!,MATCH($E15,_xlfn.ANCHORARRAY(#REF!),0))+INDEX(#REF!,MATCH($E15,_xlfn.ANCHORARRAY(#REF!),0)) -> #REF! | X15: 0.0125 | Y15: 0 | Z15: 0 | AA15: =U15*BC15+U15*BD15*(1+V15)+SUM(W15:Z15) -> #REF! | AB15: 0 | AC15: =AA15+AB15 -> #REF! | AD15: 0.012 | AE15: =AC15+AD15 -> #REF! | AF15: =0.7/AE15 -> #REF! | AG15: =IFERROR(F15/AY15,0) -> 0 | AH15: =(1-AE15-($AU15-$AV15)+($AT15*(1-$AU15))-$AS15)/(($AX15*$AW15*(1-$AU15))/$AX15) -> #REF! | AJ15: =AC15-SUM(X15:Z15) -> #REF! | AK15: 0.013 | AL15: =AJ15+AK15 -> #REF! | AM15: =0.7/AL15 -> #REF! | AN15: =IFERROR(F15/AZ15,0) -> 0 | AO15: =(1-AL15-($AU15-$AV15)+($AT15*(1-$AU15))-$AS15)/(($AX15*$AW15*(1-$AU15))/$AX15) -> #REF! | AQ15: =F15*AE15 -> #REF! | AR15: =F15*AL15 -> #REF! | AS15: 0 | AT15: 0 | AU15: 0 | AV15: 0 | AW15: 0 | AX15: 0 | AY15: =AQ15/(1-AS15-(AU15-AV15)+AT15*(1-AU15)-AX15*AW15*(1-AU15)) -> #REF! | AZ15: =AR15/(1-AS15-(AU15-AV15)+AT15*(1-AU15)-AX15*AW15*(1-AU15)) -> #REF! | BA15: =IF($C$7="Business Plan",0,"placeholder") -> 0 | BB15: =IF($C$7="Business Plan",0,"placeholder") -> 0 | BC15: =IF($C$7="Business Plan",INDEX(#REF!,MATCH($E15,_xlfn.ANCHORARRAY(#REF!),0))/(INDEX(#REF!,MATCH($E15,_xlfn.ANCHORARRAY(#REF!),0))+INDEX(#REF!,MATCH($E15,_xlfn.ANCHORARRAY(#REF!),0))),BA15+BB15) -> #REF! | BD15: =IF($C$7="Business Plan",1-BC15,0) -> #REF! | BF15: =BA15*$AE15 -> #REF! | BG15: =BB15*$AE15 -> #REF! | BH15: =BC15*$AE15 -> #REF! | BI15: =BD15*$AE15 -> #REF!
B16: =1+B15 -> 4 | C16: =INDEX(#REF!,MATCH($E16,#REF!,0)) -> #REF! | D16: =INDEX(#REF!,MATCH($E16,#REF!,0)) -> #REF! | F16: =SUMIFS(#REF!,_xlfn.ANCHORARRAY(#REF!),E16) -> #REF! | G16: =F16/$F$29 -> #REF! | H16: 0.50624371 | I16: 0.7992696 | J16: 0.65949517 | K16: 0.58486715 | L16: 0.027589592 | M16: 0.71970193 | N16: 0.5 | O16: 0.5 | P16: 0 | Q16: 0 | R16: 0 | S16: 0 | T16: =SUM(N16:S16)=1 -> TRUE | U16: =SUMPRODUCT(H16:M16,N16:S16) -> 0.65275665 | V16: =INDEX(#REF!,MATCH($E16,_xlfn.ANCHORARRAY(#REF!),0)) -> #REF! | W16: =INDEX(#REF!,MATCH($E16,_xlfn.ANCHORARRAY(#REF!),0))+INDEX(#REF!,MATCH($E16,_xlfn.ANCHORARRAY(#REF!),0)) -> #REF! | X16: 0.0125 | Y16: 0 | Z16: 0 | AA16: =U16*BC16+U16*BD16*(1+V16)+SUM(W16:Z16) -> #REF! | AB16: 0 | AC16: =AA16+AB16 -> #REF! | AD16: 0.012 | AE16: =AC16+AD16 -> #REF! | AF16: =0.7/AE16 -> #REF! | AG16: =IFERROR(F16/AY16,0) -> 0 | AH16: =(1-AE16-($AU16-$AV16)+($AT16*(1-$AU16))-$AS16)/(($AX16*$AW16*(1-$AU16))/$AX16) -> #REF! | AJ16: =AC16-SUM(X16:Z16) -> #REF! | AK16: 0.013 | AL16: =AJ16+AK16 -> #REF! | AM16: =0.7/AL16 -> #REF! | AN16: =IFERROR(F16/AZ16,0) -> 0 | AO16: =(1-AL16-($AU16-$AV16)+($AT16*(1-$AU16))-$AS16)/(($AX16*$AW16*(1-$AU16))/$AX16) -> #REF! | AQ16: =F16*AE16 -> #REF! | AR16: =F16*AL16 -> #REF! | AS16: 0 | AT16: 0 | AU16: 0 | AV16: 0 | AW16: 0 | AX16: 0 | AY16: =AQ16/(1-AS16-(AU16-AV16)+AT16*(1-AU16)-AX16*AW16*(1-AU16)) -> #REF! | AZ16: =AR16/(1-AS16-(AU16-AV16)+AT16*(1-AU16)-AX16*AW16*(1-AU16)) -> #REF! | BA16: =IF($C$7="Business Plan",0,"placeholder") -> 0 | BB16: =IF($C$7="Business Plan",0,"placeholder") -> 0 | BC16: =IF($C$7="Business Plan",INDEX(#REF!,MATCH($E16,_xlfn.ANCHORARRAY(#REF!),0))/(INDEX(#REF!,MATCH($E16,_xlfn.ANCHORARRAY(#REF!),0))+INDEX(#REF!,MATCH($E16,_xlfn.ANCHORARRAY(#REF!),0))),BA16+BB16) -> #REF! | BD16: =IF($C$7="Business Plan",1-BC16,0) -> #REF! | BF16: =BA16*$AE16 -> #REF! | BG16: =BB16*$AE16 -> #REF! | BH16: =BC16*$AE16 -> #REF! | BI16: =BD16*$AE16 -> #REF!
B17: =1+B16 -> 5 | C17: =INDEX(#REF!,MATCH($E17,#REF!,0)) -> #REF! | D17: =INDEX(#REF!,MATCH($E17,#REF!,0)) -> #REF! | F17: =SUMIFS(#REF!,_xlfn.ANCHORARRAY(#REF!),E17) -> #REF! | G17: =F17/$F$29 -> #REF! | H17: 0.63713272 | I17: 0.65704101 | J17: 0.57358046 | K17: 0.46666842 | L17: 0.19349556 | M17: 0.71627394 | N17: 0.5 | O17: 0.5 | P17: 0 | Q17: 0 | R17: 0 | S17: 0 | T17: =SUM(N17:S17)=1 -> TRUE | U17: =SUMPRODUCT(H17:M17,N17:S17) -> 0.64708686 | V17: =INDEX(#REF!,MATCH($E17,_xlfn.ANCHORARRAY(#REF!),0)) -> #REF! | W17: =INDEX(#REF!,MATCH($E17,_xlfn.ANCHORARRAY(#REF!),0))+INDEX(#REF!,MATCH($E17,_xlfn.ANCHORARRAY(#REF!),0)) -> #REF! | X17: 0.0125 | Y17: 0 | Z17: 0 | AA17: =U17*BC17+U17*BD17*(1+V17)+SUM(W17:Z17) -> #REF! | AB17: 0 | AC17: =AA17+AB17 -> #REF! | AD17: 0.012 | AE17: =AC17+AD17 -> #REF! | AF17: =0.7/AE17 -> #REF! | AG17: =IFERROR(F17/AY17,0) -> 0 | AH17: =(1-AE17-($AU17-$AV17)+($AT17*(1-$AU17))-$AS17)/(($AX17*$AW17*(1-$AU17))/$AX17) -> #REF! | AJ17: =AC17-SUM(X17:Z17) -> #REF! | AK17: 0.013 | AL17: =AJ17+AK17 -> #REF! | AM17: =0.7/AL17 -> #REF! | AN17: =IFERROR(F17/AZ17,0) -> 0 | AO17: =(1-AL17-($AU17-$AV17)+($AT17*(1-$AU17))-$AS17)/(($AX17*$AW17*(1-$AU17))/$AX17) -> #REF! | AQ17: =F17*AE17 -> #REF! | AR17: =F17*AL17 -> #REF! | AS17: 0 | AT17: 0 | AU17: 0 | AV17: 0 | AW17: 0 | AX17: 0 | AY17: =AQ17/(1-AS17-(AU17-AV17)+AT17*(1-AU17)-AX17*AW17*(1-AU17)) -> #REF! | AZ17: =AR17/(1-AS17-(AU17-AV17)+AT17*(1-AU17)-AX17*AW17*(1-AU17)) -> #REF! | BA17: =IF($C$7="Business Plan",0,"placeholder") -> 0 | BB17: =IF($C$7="Business Plan",0,"placeholder") -> 0 | BC17: =IF($C$7="Business Plan",INDEX(#REF!,MATCH($E17,_xlfn.ANCHORARRAY(#REF!),0))/(INDEX(#REF!,MATCH($E17,_xlfn.ANCHORARRAY(#REF!),0))+INDEX(#REF!,MATCH($E17,_xlfn.ANCHORARRAY(#REF!),0))),BA17+BB17) -> #REF! | BD17: =IF($C$7="Business Plan",1-BC17,0) -> #REF! | BF17: =BA17*$AE17 -> #REF! | BG17: =BB17*$AE17 -> #REF! | BH17: =BC17*$AE17 -> #REF! | BI17: =BD17*$AE17 -> #REF!
B18: =1+B17 -> 6 | C18: =INDEX(#REF!,MATCH($E18,#REF!,0)) -> #REF! | D18: =INDEX(#REF!,MATCH($E18,#REF!,0)) -> #REF! | F18: =SUMIFS(#REF!,_xlfn.ANCHORARRAY(#REF!),E18) -> #REF! | G18: =F18/$F$29 -> #REF! | H18: 0.0042186091 | I18: 0.94192651 | J18: 0.0883427 | K18: 0.46457897 | L18: 0.018058164 | M18: 0.38704387 | N18: 0.5 | O18: 0.5 | P18: 0 | Q18: 0 | R18: 0 | S18: 0 | T18: =SUM(N18:S18)=1 -> TRUE | U18: =SUMPRODUCT(H18:M18,N18:S18) -> 0.47307256 | V18: =INDEX(#REF!,MATCH($E18,_xlfn.ANCHORARRAY(#REF!),0)) -> #REF! | W18: =INDEX(#REF!,MATCH($E18,_xlfn.ANCHORARRAY(#REF!),0))+INDEX(#REF!,MATCH($E18,_xlfn.ANCHORARRAY(#REF!),0)) -> #REF! | X18: 0.0125 | Y18: 0 | Z18: 0 | AA18: =U18*BC18+U18*BD18*(1+V18)+SUM(W18:Z18) -> #REF! | AB18: 0 | AC18: =AA18+AB18 -> #REF! | AD18: 0.012 | AE18: =AC18+AD18 -> #REF! | AF18: =0.7/AE18 -> #REF! | AG18: =IFERROR(F18/AY18,0) -> 0 | AH18: =(1-AE18-($AU18-$AV18)+($AT18*(1-$AU18))-$AS18)/(($AX18*$AW18*(1-$AU18))/$AX18) -> #REF! | AJ18: =AC18-SUM(X18:Z18) -> #REF! | AK18: 0.013 | AL18: =AJ18+AK18 -> #REF! | AM18: =0.7/AL18 -> #REF! | AN18: =IFERROR(F18/AZ18,0) -> 0 | AO18: =(1-AL18-($AU18-$AV18)+($AT18*(1-$AU18))-$AS18)/(($AX18*$AW18*(1-$AU18))/$AX18) -> #REF! | AQ18: =F18*AE18 -> #REF! | AR18: =F18*AL18 -> #REF! | AS18: 0 | AT18: 0 | AU18: 0 | AV18: 0 | AW18: 0 | AX18: 0 | AY18: =AQ18/(1-AS18-(AU18-AV18)+AT18*(1-AU18)-AX18*AW18*(1-AU18)) -> #REF! | AZ18: =AR18/(1-AS18-(AU18-AV18)+AT18*(1-AU18)-AX18*AW18*(1-AU18)) -> #REF! | BA18: =IF($C$7="Business Plan",0,"placeholder") -> 0 | BB18: =IF($C$7="Business Plan",0,"placeholder") -> 0 | BC18: =IF($C$7="Business Plan",INDEX(#REF!,MATCH($E18,_xlfn.ANCHORARRAY(#REF!),0))/(INDEX(#REF!,MATCH($E18,_xlfn.ANCHORARRAY(#REF!),0))+INDEX(#REF!,MATCH($E18,_xlfn.ANCHORARRAY(#REF!),0))),BA18+BB18) -> #REF! | BD18: =IF($C$7="Business Plan",1-BC18,0) -> #REF! | BF18: =BA18*$AE18 -> #REF! | BG18: =BB18*$AE18 -> #REF! | BH18: =BC18*$AE18 -> #REF! | BI18: =BD18*$AE18 -> #REF!
B19: =1+B18 -> 7 | C19: =INDEX(#REF!,MATCH($E19,#REF!,0)) -> #REF! | D19: =INDEX(#REF!,MATCH($E19,#REF!,0)) -> #REF! | F19: =SUMIFS(#REF!,_xlfn.ANCHORARRAY(#REF!),E19) -> #REF! | G19: =F19/$F$29 -> #REF! | H19: 0.42659245 | I19: 0.27785508 | J19: 0.7519618 | K19: 0.31242525 | L19: 0.052955392 | M19: 0.7842719 | N19: 0.5 | O19: 0.5 | P19: 0 | Q19: 0 | R19: 0 | S19: 0 | T19: =SUM(N19:S19)=1 -> TRUE | U19: =SUMPRODUCT(H19:M19,N19:S19) -> 0.35222377 | V19: =INDEX(#REF!,MATCH($E19,_xlfn.ANCHORARRAY(#REF!),0)) -> #REF! | W19: =INDEX(#REF!,MATCH($E19,_xlfn.ANCHORARRAY(#REF!),0))+INDEX(#REF!,MATCH($E19,_xlfn.ANCHORARRAY(#REF!),0)) -> #REF! | X19: 0.0125 | Y19: 0 | Z19: 0 | AA19: =U19*BC19+U19*BD19*(1+V19)+SUM(W19:Z19) -> #REF! | AB19: 0 | AC19: =AA19+AB19 -> #REF! | AD19: 0.012 | AE19: =AC19+AD19 -> #REF! | AF19: =0.7/AE19 -> #REF! | AG19: =IFERROR(F19/AY19,0) -> 0 | AH19: =(1-AE19-($AU19-$AV19)+($AT19*(1-$AU19))-$AS19)/(($AX19*$AW19*(1-$AU19))/$AX19) -> #REF! | AJ19: =AC19-SUM(X19:Z19) -> #REF! | AK19: 0.013 | AL19: =AJ19+AK19 -> #REF! | AM19: =0.7/AL19 -> #REF! | AN19: =IFERROR(F19/AZ19,0) -> 0 | AO19: =(1-AL19-($AU19-$AV19)+($AT19*(1-$AU19))-$AS19)/(($AX19*$AW19*(1-$AU19))/$AX19) -> #REF! | AQ19: =F19*AE19 -> #REF! | AR19: =F19*AL19 -> #REF! | AS19: 0 | AT19: 0 | AU19: 0 | AV19: 0 | AW19: 0 | AX19: 0 | AY19: =AQ19/(1-AS19-(AU19-AV19)+AT19*(1-AU19)-AX19*AW19*(1-AU19)) -> #REF! | AZ19: =AR19/(1-AS19-(AU19-AV19)+AT19*(1-AU19)-AX19*AW19*(1-AU19)) -> #REF! | BA19: =IF($C$7="Business Plan",0,"placeholder") -> 0 | BB19: =IF($C$7="Business Plan",0,"placeholder") -> 0 | BC19: =IF($C$7="Business Plan",INDEX(#REF!,MATCH($E19,_xlfn.ANCHORARRAY(#REF!),0))/(INDEX(#REF!,MATCH($E19,_xlfn.ANCHORARRAY(#REF!),0))+INDEX(#REF!,MATCH($E19,_xlfn.ANCHORARRAY(#REF!),0))),BA19+BB19) -> #REF! | BD19: =IF($C$7="Business Plan",1-BC19,0) -> #REF! | BF19: =BA19*$AE19 -> #REF! | BG19: =BB19*$AE19 -> #REF! | BH19: =BC19*$AE19 -> #REF! | BI19: =BD19*$AE19 -> #REF!
B20: =1+B19 -> 8 | C20: =INDEX(#REF!,MATCH($E20,#REF!,0)) -> #REF! | D20: =INDEX(#REF!,MATCH($E20,#REF!,0)) -> #REF! | F20: =SUMIFS(#REF!,_xlfn.ANCHORARRAY(#REF!),E20) -> #REF! | G20: =F20/$F$29 -> #REF! | H20: 0.52204155 | I20: 0.63754796 | J20: 0.013224759 | K20: 0.85222253 | L20: 0.31789589 | M20: 0.98967945 | N20: 0.5 | O20: 0.5 | P20: 0 | Q20: 0 | R20: 0 | S20: 0 | T20: =SUM(N20:S20)=1 -> TRUE | U20: =SUMPRODUCT(H20:M20,N20:S20) -> 0.57979476 | V20: =INDEX(#REF!,MATCH($E20,_xlfn.ANCHORARRAY(#REF!),0)) -> #REF! | W20: =INDEX(#REF!,MATCH($E20,_xlfn.ANCHORARRAY(#REF!),0))+INDEX(#REF!,MATCH($E20,_xlfn.ANCHORARRAY(#REF!),0)) -> #REF! | X20: 0.0125 | Y20: 0 | Z20: 0 | AA20: =U20*BC20+U20*BD20*(1+V20)+SUM(W20:Z20) -> #REF! | AB20: 0 | AC20: =AA20+AB20 -> #REF! | AD20: 0.012 | AE20: =AC20+AD20 -> #REF! | AF20: =0.7/AE20 -> #REF! | AG20: =IFERROR(F20/AY20,0) -> 0 | AH20: =(1-AE20-($AU20-$AV20)+($AT20*(1-$AU20))-$AS20)/(($AX20*$AW20*(1-$AU20))/$AX20) -> #REF! | AJ20: =AC20-SUM(X20:Z20) -> #REF! | AK20: 0.013 | AL20: =AJ20+AK20 -> #REF! | AM20: =0.7/AL20 -> #REF! | AN20: =IFERROR(F20/AZ20,0) -> 0 | AO20: =(1-AL20-($AU20-$AV20)+($AT20*(1-$AU20))-$AS20)/(($AX20*$AW20*(1-$AU20))/$AX20) -> #REF! | AQ20: =F20*AE20 -> #REF! | AR20: =F20*AL20 -> #REF! | AS20: 0 | AT20: 0 | AU20: 0 | AV20: 0 | AW20: 0 | AX20: 0 | AY20: =AQ20/(1-AS20-(AU20-AV20)+AT20*(1-AU20)-AX20*AW20*(1-AU20)) -> #REF! | AZ20: =AR20/(1-AS20-(AU20-AV20)+AT20*(1-AU20)-AX20*AW20*(1-AU20)) -> #REF! | BA20: =IF($C$7="Business Plan",0,"placeholder") -> 0 | BB20: =IF($C$7="Business Plan",0,"placeholder") -> 0 | BC20: =IF($C$7="Business Plan",INDEX(#REF!,MATCH($E20,_xlfn.ANCHORARRAY(#REF!),0))/(INDEX(#REF!,MATCH($E20,_xlfn.ANCHORARRAY(#REF!),0))+INDEX(#REF!,MATCH($E20,_xlfn.ANCHORARRAY(#REF!),0))),BA20+BB20) -> #REF! | BD20: =IF($C$7="Business Plan",1-BC20,0) -> #REF! | BF20: =BA20*$AE20 -> #REF! | BG20: =BB20*$AE20 -> #REF! | BH20: =BC20*$AE20 -> #REF! | BI20: =BD20*$AE20 -> #REF!
B21: =1+B20 -> 9 | C21: =INDEX(#REF!,MATCH($E21,#REF!,0)) -> #REF! | D21: =INDEX(#REF!,MATCH($E21,#REF!,0)) -> #REF! | F21: =SUMIFS(#REF!,_xlfn.ANCHORARRAY(#REF!),E21) -> #REF! | G21: =F21/$F$29 -> #REF! | H21: 0.09559264 | I21: 0.7273133 | J21: 0.10365666 | K21: 0.28208612 | L21: 0.40005888 | M21: 0.26163835 | N21: 0.5 | O21: 0.5 | P21: 0 | Q21: 0 | R21: 0 | S21: 0 | T21: =SUM(N21:S21)=1 -> TRUE | U21: =SUMPRODUCT(H21:M21,N21:S21) -> 0.41145297 | V21: =INDEX(#REF!,MATCH($E21,_xlfn.ANCHORARRAY(#REF!),0)) -> #REF! | W21: =INDEX(#REF!,MATCH($E21,_xlfn.ANCHORARRAY(#REF!),0))+INDEX(#REF!,MATCH($E21,_xlfn.ANCHORARRAY(#REF!),0)) -> #REF! | X21: 0.0125 | Y21: 0 | Z21: 0 | AA21: =U21*BC21+U21*BD21*(1+V21)+SUM(W21:Z21) -> #REF! | AB21: 0 | AC21: =AA21+AB21 -> #REF! | AD21: 0.012 | AE21: =AC21+AD21 -> #REF! | AF21: =0.7/AE21 -> #REF! | AG21: =IFERROR(F21/AY21,0) -> 0 | AH21: =(1-AE21-($AU21-$AV21)+($AT21*(1-$AU21))-$AS21)/(($AX21*$AW21*(1-$AU21))/$AX21) -> #REF! | AJ21: =AC21-SUM(X21:Z21) -> #REF! | AK21: 0.013 | AL21: =AJ21+AK21 -> #REF! | AM21: =0.7/AL21 -> #REF! | AN21: =IFERROR(F21/AZ21,0) -> 0 | AO21: =(1-AL21-($AU21-$AV21)+($AT21*(1-$AU21))-$AS21)/(($AX21*$AW21*(1-$AU21))/$AX21) -> #REF! | AQ21: =F21*AE21 -> #REF! | AR21: =F21*AL21 -> #REF! | AS21: 0 | AT21: 0 | AU21: 0 | AV21: 0 | AW21: 0 | AX21: 0 | AY21: =AQ21/(1-AS21-(AU21-AV21)+AT21*(1-AU21)-AX21*AW21*(1-AU21)) -> #REF! | AZ21: =AR21/(1-AS21-(AU21-AV21)+AT21*(1-AU21)-AX21*AW21*(1-AU21)) -> #REF! | BA21: =IF($C$7="Business Plan",0,"placeholder") -> 0 | BB21: =IF($C$7="Business Plan",0,"placeholder") -> 0 | BC21: =IF($C$7="Business Plan",INDEX(#REF!,MATCH($E21,_xlfn.ANCHORARRAY(#REF!),0))/(INDEX(#REF!,MATCH($E21,_xlfn.ANCHORARRAY(#REF!),0))+INDEX(#REF!,MATCH($E21,_xlfn.ANCHORARRAY(#REF!),0))),BA21+BB21) -> #REF! | BD21: =IF($C$7="Business Plan",1-BC21,0) -> #REF! | BF21: =BA21*$AE21 -> #REF! | BG21: =BB21*$AE21 -> #REF! | BH21: =BC21*$AE21 -> #REF! | BI21: =BD21*$AE21 -> #REF!
B22: =1+B21 -> 10 | C22: =INDEX(#REF!,MATCH($E22,#REF!,0)) -> #REF! | D22: =INDEX(#REF!,MATCH($E22,#REF!,0)) -> #REF! | F22: =SUMIFS(#REF!,_xlfn.ANCHORARRAY(#REF!),E22) -> #REF! | G22: =F22/$F$29 -> #REF! | H22: 0.22762355 | I22: 0.023743624 | J22: 0.42840363 | K22: 0.13686879 | L22: 0.27549434 | M22: 0.35271026 | N22: 0.5 | O22: 0.5 | P22: 0 | Q22: 0 | R22: 0 | S22: 0 | T22: =SUM(N22:S22)=1 -> TRUE | U22: =SUMPRODUCT(H22:M22,N22:S22) -> 0.12568359 | V22: =INDEX(#REF!,MATCH($E22,_xlfn.ANCHORARRAY(#REF!),0)) -> #REF! | W22: =INDEX(#REF!,MATCH($E22,_xlfn.ANCHORARRAY(#REF!),0))+INDEX(#REF!,MATCH($E22,_xlfn.ANCHORARRAY(#REF!),0)) -> #REF! | X22: 0.0125 | Y22: 0 | Z22: 0 | AA22: =U22*BC22+U22*BD22*(1+V22)+SUM(W22:Z22) -> #REF! | AB22: 0 | AC22: =AA22+AB22 -> #REF! | AD22: 0.012 | AE22: =AC22+AD22 -> #REF! | AF22: =0.7/AE22 -> #REF! | AG22: =IFERROR(F22/AY22,0) -> 0 | AH22: =(1-AE22-($AU22-$AV22)+($AT22*(1-$AU22))-$AS22)/(($AX22*$AW22*(1-$AU22))/$AX22) -> #REF! | AJ22: =AC22-SUM(X22:Z22) -> #REF! | AK22: 0.013 | AL22: =AJ22+AK22 -> #REF! | AM22: =0.7/AL22 -> #REF! | AN22: =IFERROR(F22/AZ22,0) -> 0 | AO22: =(1-AL22-($AU22-$AV22)+($AT22*(1-$AU22))-$AS22)/(($AX22*$AW22*(1-$AU22))/$AX22) -> #REF! | AQ22: =F22*AE22 -> #REF! | AR22: =F22*AL22 -> #REF! | AS22: 0 | AT22: 0 | AU22: 0 | AV22: 0 | AW22: 0 | AX22: 0 | AY22: =AQ22/(1-AS22-(AU22-AV22)+AT22*(1-AU22)-AX22*AW22*(1-AU22)) -> #REF! | AZ22: =AR22/(1-AS22-(AU22-AV22)+AT22*(1-AU22)-AX22*AW22*(1-AU22)) -> #REF! | BA22: =IF($C$7="Business Plan",0,"placeholder") -> 0 | BB22: =IF($C$7="Business Plan",0,"placeholder") -> 0 | BC22: =IF($C$7="Business Plan",INDEX(#REF!,MATCH($E22,_xlfn.ANCHORARRAY(#REF!),0))/(INDEX(#REF!,MATCH($E22,_xlfn.ANCHORARRAY(#REF!),0))+INDEX(#REF!,MATCH($E22,_xlfn.ANCHORARRAY(#REF!),0))),BA22+BB22) -> #REF! | BD22: =IF($C$7="Business Plan",1-BC22,0) -> #REF! | BF22: =BA22*$AE22 -> #REF! | BG22: =BB22*$AE22 -> #REF! | BH22: =BC22*$AE22 -> #REF! | BI22: =BD22*$AE22 -> #REF!
B23: =1+B22 -> 11 | C23: =INDEX(#REF!,MATCH($E23,#REF!,0)) -> #REF! | D23: =INDEX(#REF!,MATCH($E23,#REF!,0)) -> #REF! | F23: =SUMIFS(#REF!,_xlfn.ANCHORARRAY(#REF!),E23) -> #REF! | G23: =F23/$F$29 -> #REF! | H23: 0.59962889 | I23: 0.54105462 | J23: 0.11030512 | K23: 0.3989057 | L23: 0.84258574 | M23: 0.49930302 | N23: 0.5 | O23: 0.5 | P23: 0 | Q23: 0 | R23: 0 | S23: 0 | T23: =SUM(N23:S23)=1 -> TRUE | U23: =SUMPRODUCT(H23:M23,N23:S23) -> 0.57034175 | V23: =INDEX(#REF!,MATCH($E23,_xlfn.ANCHORARRAY(#REF!),0)) -> #REF! | W23: =INDEX(#REF!,MATCH($E23,_xlfn.ANCHORARRAY(#REF!),0))+INDEX(#REF!,MATCH($E23,_xlfn.ANCHORARRAY(#REF!),0)) -> #REF! | X23: 0.0125 | Y23: 0 | Z23: 0 | AA23: =U23*BC23+U23*BD23*(1+V23)+SUM(W23:Z23) -> #REF! | AB23: 0 | AC23: =AA23+AB23 -> #REF! | AD23: 0.012 | AE23: =AC23+AD23 -> #REF! | AF23: =0.7/AE23 -> #REF! | AG23: =IFERROR(F23/AY23,0) -> 0 | AH23: =(1-AE23-($AU23-$AV23)+($AT23*(1-$AU23))-$AS23)/(($AX23*$AW23*(1-$AU23))/$AX23) -> #REF! | AJ23: =AC23-SUM(X23:Z23) -> #REF! | AK23: 0.013 | AL23: =AJ23+AK23 -> #REF! | AM23: =0.7/AL23 -> #REF! | AN23: =IFERROR(F23/AZ23,0) -> 0 | AO23: =(1-AL23-($AU23-$AV23)+($AT23*(1-$AU23))-$AS23)/(($AX23*$AW23*(1-$AU23))/$AX23) -> #REF! | AQ23: =F23*AE23 -> #REF! | AR23: =F23*AL23 -> #REF! | AS23: 0 | AT23: 0 | AU23: 0 | AV23: 0 | AW23: 0 | AX23: 0 | AY23: =AQ23/(1-AS23-(AU23-AV23)+AT23*(1-AU23)-AX23*AW23*(1-AU23)) -> #REF! | AZ23: =AR23/(1-AS23-(AU23-AV23)+AT23*(1-AU23)-AX23*AW23*(1-AU23)) -> #REF! | BA23: =IF($C$7="Business Plan",0,"placeholder") -> 0 | BB23: =IF($C$7="Business Plan",0,"placeholder") -> 0 | BC23: =IF($C$7="Business Plan",INDEX(#REF!,MATCH($E23,_xlfn.ANCHORARRAY(#REF!),0))/(INDEX(#REF!,MATCH($E23,_xlfn.ANCHORARRAY(#REF!),0))+INDEX(#REF!,MATCH($E23,_xlfn.ANCHORARRAY(#REF!),0))),BA23+BB23) -> #REF! | BD23: =IF($C$7="Business Plan",1-BC23,0) -> #REF! | BF23: =BA23*$AE23 -> #REF! | BG23: =BB23*$AE23 -> #REF! | BH23: =BC23*$AE23 -> #REF! | BI23: =BD23*$AE23 -> #REF!
B24: =1+B23 -> 12 | C24: =INDEX(#REF!,MATCH($E24,#REF!,0)) -> #REF! | D24: =INDEX(#REF!,MATCH($E24,#REF!,0)) -> #REF! | F24: =SUMIFS(#REF!,_xlfn.ANCHORARRAY(#REF!),E24) -> #REF! | G24: =F24/$F$29 -> #REF! | H24: 0.91025018 | I24: 0.6660594 | J24: 0.10090556 | K24: 0.64816096 | L24: 0.38602254 | M24: 0.85713058 | N24: 0.5 | O24: 0.5 | P24: 0 | Q24: 0 | R24: 0 | S24: 0 | T24: =SUM(N24:S24)=1 -> TRUE | U24: =SUMPRODUCT(H24:M24,N24:S24) -> 0.78815479 | V24: =INDEX(#REF!,MATCH($E24,_xlfn.ANCHORARRAY(#REF!),0)) -> #REF! | W24: =INDEX(#REF!,MATCH($E24,_xlfn.ANCHORARRAY(#REF!),0))+INDEX(#REF!,MATCH($E24,_xlfn.ANCHORARRAY(#REF!),0)) -> #REF! | X24: 0.0125 | Y24: 0 | Z24: 0 | AA24: =U24*BC24+U24*BD24*(1+V24)+SUM(W24:Z24) -> #REF! | AB24: 0 | AC24: =AA24+AB24 -> #REF! | AD24: 0.012 | AE24: =AC24+AD24 -> #REF! | AF24: =0.7/AE24 -> #REF! | AG24: =IFERROR(F24/AY24,0) -> 0 | AH24: =(1-AE24-($AU24-$AV24)+($AT24*(1-$AU24))-$AS24)/(($AX24*$AW24*(1-$AU24))/$AX24) -> #REF! | AJ24: =AC24-SUM(X24:Z24) -> #REF! | AK24: 0.013 | AL24: =AJ24+AK24 -> #REF! | AM24: =0.7/AL24 -> #REF! | AN24: =IFERROR(F24/AZ24,0) -> 0 | AO24: =(1-AL24-($AU24-$AV24)+($AT24*(1-$AU24))-$AS24)/(($AX24*$AW24*(1-$AU24))/$AX24) -> #REF! | AQ24: =F24*AE24 -> #REF! | AR24: =F24*AL24 -> #REF! | AS24: 0 | AT24: 0 | AU24: 0 | AV24: 0 | AW24: 0 | AX24: 0 | AY24: =AQ24/(1-AS24-(AU24-AV24)+AT24*(1-AU24)-AX24*AW24*(1-AU24)) -> #REF! | AZ24: =AR24/(1-AS24-(AU24-AV24)+AT24*(1-AU24)-AX24*AW24*(1-AU24)) -> #REF! | BA24: =IF($C$7="Business Plan",0,"placeholder") -> 0 | BB24: =IF($C$7="Business Plan",0,"placeholder") -> 0 | BC24: =IF($C$7="Business Plan",INDEX(#REF!,MATCH($E24,_xlfn.ANCHORARRAY(#REF!),0))/(INDEX(#REF!,MATCH($E24,_xlfn.ANCHORARRAY(#REF!),0))+INDEX(#REF!,MATCH($E24,_xlfn.ANCHORARRAY(#REF!),0))),BA24+BB24) -> #REF! | BD24: =IF($C$7="Business Plan",1-BC24,0) -> #REF! | BF24: =BA24*$AE24 -> #REF! | BG24: =BB24*$AE24 -> #REF! | BH24: =BC24*$AE24 -> #REF! | BI24: =BD24*$AE24 -> #REF!
B25: =1+B24 -> 13 | C25: =INDEX(#REF!,MATCH($E25,#REF!,0)) -> #REF! | D25: =INDEX(#REF!,MATCH($E25,#REF!,0)) -> #REF! | F25: =SUMIFS(#REF!,_xlfn.ANCHORARRAY(#REF!),E25) -> #REF! | G25: =F25/$F$29 -> #REF! | H25: 0.95703344 | I25: 0.89377708 | J25: 0.55490265 | K25: 0.013589204 | L25: 0.19233823 | M25: 0.3824693 | N25: 0.5 | O25: 0.5 | P25: 0 | Q25: 0 | R25: 0 | S25: 0 | T25: =SUM(N25:S25)=1 -> TRUE | U25: =SUMPRODUCT(H25:M25,N25:S25) -> 0.92540526 | V25: =INDEX(#REF!,MATCH($E25,_xlfn.ANCHORARRAY(#REF!),0)) -> #REF! | W25: =INDEX(#REF!,MATCH($E25,_xlfn.ANCHORARRAY(#REF!),0))+INDEX(#REF!,MATCH($E25,_xlfn.ANCHORARRAY(#REF!),0)) -> #REF! | X25: 0.0125 | Y25: 0 | Z25: 0 | AA25: =U25*BC25+U25*BD25*(1+V25)+SUM(W25:Z25) -> #REF! | AB25: 0 | AC25: =AA25+AB25 -> #REF! | AD25: 0.012 | AE25: =AC25+AD25 -> #REF! | AF25: =0.7/AE25 -> #REF! | AG25: =IFERROR(F25/AY25,0) -> 0 | AH25: =(1-AE25-($AU25-$AV25)+($AT25*(1-$AU25))-$AS25)/(($AX25*$AW25*(1-$AU25))/$AX25) -> #REF! | AJ25: =AC25-SUM(X25:Z25) -> #REF! | AK25: 0.013 | AL25: =AJ25+AK25 -> #REF! | AM25: =0.7/AL25 -> #REF! | AN25: =IFERROR(F25/AZ25,0) -> 0 | AO25: =(1-AL25-($AU25-$AV25)+($AT25*(1-$AU25))-$AS25)/(($AX25*$AW25*(1-$AU25))/$AX25) -> #REF! | AQ25: =F25*AE25 -> #REF! | AR25: =F25*AL25 -> #REF! | AS25: 0 | AT25: 0 | AU25: 0 | AV25: 0 | AW25: 0 | AX25: 0 | AY25: =AQ25/(1-AS25-(AU25-AV25)+AT25*(1-AU25)-AX25*AW25*(1-AU25)) -> #REF! | AZ25: =AR25/(1-AS25-(AU25-AV25)+AT25*(1-AU25)-AX25*AW25*(1-AU25)) -> #REF! | BA25: =IF($C$7="Business Plan",0,"placeholder") -> 0 | BB25: =IF($C$7="Business Plan",0,"placeholder") -> 0 | BC25: =IF($C$7="Business Plan",INDEX(#REF!,MATCH($E25,_xlfn.ANCHORARRAY(#REF!),0))/(INDEX(#REF!,MATCH($E25,_xlfn.ANCHORARRAY(#REF!),0))+INDEX(#REF!,MATCH($E25,_xlfn.ANCHORARRAY(#REF!),0))),BA25+BB25) -> #REF! | BD25: =IF($C$7="Business Plan",1-BC25,0) -> #REF! | BF25: =BA25*$AE25 -> #REF! | BG25: =BB25*$AE25 -> #REF! | BH25: =BC25*$AE25 -> #REF! | BI25: =BD25*$AE25 -> #REF!
... B28: =1+B27 -> 16 | C28: =INDEX(#REF!,MATCH($E28,#REF!,0)) -> #REF! | D28: =INDEX(#REF!,MATCH($E28,#REF!,0)) -> #REF! | F28: =SUMIFS(#REF!,_xlfn.ANCHORARRAY(#REF!),E28) -> #REF! | G28: =F28/$F$29 -> #REF! | H28: 0.61556683 | I28: 0.4025456 | J28: 0.30532662 | K28: 0.59523475 | L28: 0.21903932 | M28: 0.12859678 | N28: 0.5 | O28: 0.5 | P28: 0 | Q28: 0 | R28: 0 | S28: 0 | T28: =SUM(N28:S28)=1 -> TRUE | U28: =SUMPRODUCT(H28:M28,N28:S28) -> 0.50905621 | V28: =INDEX(#REF!,MATCH($E28,_xlfn.ANCHORARRAY(#REF!),0)) -> #REF! | W28: =INDEX(#REF!,MATCH($E28,_xlfn.ANCHORARRAY(#REF!),0))+INDEX(#REF!,MATCH($E28,_xlfn.ANCHORARRAY(#REF!),0)) -> #REF! | X28: 0.0125 | Y28: 0 | Z28: 0 | AA28: =U28*BC28+U28*BD28*(1+V28)+SUM(W28:Z28) -> #REF! | AB28: 0 | AC28: =AA28+AB28 -> #REF! | AD28: 0.012 | AE28: =AC28+AD28 -> #REF! | AF28: =0.7/AE28 -> #REF! | AG28: =IFERROR(F28/AY28,0) -> 0 | AH28: =(1-AE28-($AU28-$AV28)+($AT28*(1-$AU28))-$AS28)/(($AX28*$AW28*(1-$AU28))/$AX28) -> #REF! | AJ28: =AC28-SUM(X28:Z28) -> #REF! | AK28: 0.013 | AL28: =AJ28+AK28 -> #REF! | AM28: =0.7/AL28 -> #REF! | AN28: =IFERROR(F28/AZ28,0) -> 0 | AO28: =(1-AL28-($AU28-$AV28)+($AT28*(1-$AU28))-$AS28)/(($AX28*$AW28*(1-$AU28))/$AX28) -> #REF! | AQ28: =F28*AE28 -> #REF! | AR28: =F28*AL28 -> #REF! | AS28: 0 | AT28: 0 | AU28: 0 | AV28: 0 | AW28: 0 | AX28: 0 | AY28: =AQ28/(1-AS28-(AU28-AV28)+AT28*(1-AU28)-AX28*AW28*(1-AU28)) -> #REF! | AZ28: =AR28/(1-AS28-(AU28-AV28)+AT28*(1-AU28)-AX28*AW28*(1-AU28)) -> #REF! | BA28: =IF($C$7="Business Plan",0,"placeholder") -> 0 | BB28: =IF($C$7="Business Plan",0,"placeholder") -> 0 | BC28: =IF($C$7="Business Plan",INDEX(#REF!,MATCH($E28,_xlfn.ANCHORARRAY(#REF!),0))/(INDEX(#REF!,MATCH($E28,_xlfn.ANCHORARRAY(#REF!),0))+INDEX(#REF!,MATCH($E28,_xlfn.ANCHORARRAY(#REF!),0))),BA28+BB28) -> #REF! | BD28: =IF($C$7="Business Plan",1-BC28,0) -> #REF! | BF28: =BA28*$AE28 -> #REF! | BG28: =BB28*$AE28 -> #REF! | BH28: =BC28*$AE28 -> #REF! | BI28: =BD28*$AE28 -> #REF!
B29: TOTAL | F29: =SUM(F13:F28) -> #REF! | G29: =SUM(G13:G28) -> #REF! | H29: =SUMPRODUCT($G$13:$G$28,H$13:H$28) -> #REF! | I29: =SUMPRODUCT($G$13:$G$28,I$13:I$28) -> #REF! | J29: =SUMPRODUCT($G$13:$G$28,J$13:J$28) -> #REF! | K29: =SUMPRODUCT($G$13:$G$28,K$13:K$28) -> #REF! | L29: =SUMPRODUCT($G$13:$G$28,L$13:L$28) -> #REF! | M29: =SUMPRODUCT($G$13:$G$28,M$13:M$28) -> #REF! | U29: =SUMPRODUCT($G$13:$G$28,U$13:U$28) -> #REF! | V29: =SUMPRODUCT($G$13:$G$28,V$13:V$28) -> #REF! | W29: =SUMPRODUCT($G$13:$G$28,W$13:W$28) -> #REF! | X29: =SUMPRODUCT($G$13:$G$28,X$13:X$28) -> #REF! | Y29: =SUMPRODUCT($G$13:$G$28,Y$13:Y$28) -> #REF! | Z29: =SUMPRODUCT($G$13:$G$28,Z$13:Z$28) -> #REF! | AA29: =SUMPRODUCT($G$13:$G$28,AA$13:AA$28) -> #REF! | AB29: =SUMPRODUCT($G$13:$G$28,AB$13:AB$28) -> #REF! | ... AE29: =SUMPRODUCT($G$13:$G$28,AE$13:AE$28) -> #REF! | AF29: =0.7/AE29 -> #REF! | AG29: =IFERROR(F29/AY29,0) -> 0 | AH29: =(1-AE29-($AU29-$AV29)+($AT29*(1-$AU29))-$AS29)/(($AX29*$AW29*(1-$AU29))/$AX29) -> #REF! | AJ29: =SUMPRODUCT($G$13:$G$28,AJ$13:AJ$28) -> #REF! | AK29: =SUMPRODUCT($G$13:$G$28,AK$13:AK$28) -> #REF! | AL29: =SUMPRODUCT($G$13:$G$28,AL$13:AL$28) -> #REF! | AM29: 1 | AN29: =IFERROR(F29/AZ29,0) -> 0 | AO29: =(1-AL29-($AU29-$AV29)+($AT29*(1-$AU29))-$AS29)/(($AX29*$AW29*(1-$AU29))/$AX29) -> #REF! | AQ29: =SUM(AQ13:AQ28) -> #REF! | AR29: =SUM(AR13:AR28) -> #REF! | AS29: =SUMPRODUCT($G$13:$G$28,AS$13:AS$28) -> #REF! | AT29: =SUMPRODUCT($G$13:$G$28,AT$13:AT$28) -> #REF! | AU29: =SUMPRODUCT($G$13:$G$28,AU$13:AU$28) -> #REF! | AV29: =SUMPRODUCT($G$13:$G$28,AV$13:AV$28) -> #REF! | AW29: =SUMPRODUCT($G$13:$G$28,AW$13:AW$28) -> #REF! | AX29: =SUMPRODUCT($G$13:$G$28,AX$13:AX$28) -> #REF! | AY29: =AQ29/(1-AS29-(AU29-AV29)+AT29*(1-AU29)-AX29*AW29*(1-AU29)) -> #REF! | AZ29: =AR29/(1-AS29-(AU29-AV29)+AT29*(1-AU29)-AX29*AW29*(1-AU29)) -> #REF! | BA29: =SUMPRODUCT($G$13:$G$28,BA$13:BA$28) -> #REF! | BB29: =SUMPRODUCT($G$13:$G$28,BB$13:BB$28) -> #REF! | BC29: =SUMPRODUCT($G$13:$G$28,BC$13:BC$28) -> #REF! | BD29: =SUMPRODUCT($G$13:$G$28,BD$13:BD$28) -> #REF! | BF29: =SUMPRODUCT($G$13:$G$28,BF$13:BF$28) -> #REF! | BG29: =SUMPRODUCT($G$13:$G$28,BG$13:BG$28) -> #REF! | BH29: =SUMPRODUCT($G$13:$G$28,BH$13:BH$28) -> #REF! | BI29: =SUMPRODUCT($G$13:$G$28,BI$13:BI$28) -> #REF!
B32: Grouped LoB | H32: calculated | I32: calculated | J32: calculated | K32: calculated | L32: Input | M32: Input | N32: Input | O32: Input | P32: Input | Q32: Input | R32: Input | S32: Input | BA32: ULR apportionment | BF32: Attritional / Large / Cat
C33: calculated | D33: calculated | E33: calculated | F33: calculated | G33: calculated | H33: Methodology 1 | I33: Methodology 2 | J33: Methodology 3 | K33: Methodology 4 | L33: Methodology 5 | M33: Methodology 6 | N33: Weighting 1 | O33: Weighting 2 | P33: Weighting 3 | Q33: Weighting 4 | R33: Weighting 5 | S33: Weighting 6 | T33: calculated | U33: calculated | V33: calculated | W33: calculated | X33: calculated | Y33: calculated | Z33: Input | AA33: calculated | AB33: Input | AC33: calculated | AD33: calculated | AE33: calculated | AF33: calculated | AG33: calculated | AJ33: calculated | AK33: calculated | AL33: calculated | AM33: calculated | AN33: calculated
C34: Tracker Class | D34: Grouped Line of Business | E34: Line of Business | F34: 2025 GN Premium | G34: % of Portfolio | H34: Own Experience GN ULR % | I34: Lloyd's Risk Code GN ULR % | J34: Beazley Own Projections GN ULR % | K34: Business Plan GN ULR % | L34: Beazley 623 Pricing GN ULR % | M34: Case Pricing GN ULR % | N34: Own Experience GN ULR % | O34: Lloyd's Risk Code GN ULR % | P34: Beazley Own Projections GN ULR % | Q34: Business Plan GN ULR % | R34: Beazley 623 Pricing GN ULR % | S34: Case Pricing GN ULR % | T34: Weighting Check | U34: Best Estimate GN ULR % (Pre-Loading) | V34: Climate Change Loading % | W34: NMP Loading % | X34: Anti-Selection Charge % | Y34: Uncertainty Charge % | Z34: Recessionary Charge % | AA34: Best Estimate GN ULR % (Pre UW Adj) | AB34: UW Adj. (-10% to +10%) | AC34: Best Estimate GN ULR % (Post UW Adj) | AD34: PC % Impact on GN ULR | AE34: Best Estimate GN ULR % | AF34: BPI | AG34: TPI | AH34: RoC | AJ34: Best Estimate GN ULR % (Post UW Adj) | AK34: PC % Impact on GN ULR | AL34: Best Estimate GN ULR % | AM34: BPI | AN34: TPI | AO34: RoC | AQ34: EL | AR34: EL (Excl. Anti-selection load, after PC) | AS34: Net Expense/ GN Premium | AT34: Investment Income / NN Premium | AU34: RI Premium/GN Premium | AV34: RI Recoveries/ GN Premium | AW34: Capital Required / NN Premium | AX34: Target RoC | AY34: Technical Premium | AZ34: Technical Premium (exl. Loads) | BA34: Attritional | BB34: Large | BC34: Attritional + Large | BD34: Cat | BF34: Attritional | BG34: Large | BH34: Attritional + Large | BI34: Cat
B35: 1 | C35: =INDEX($C$13:$C$28,MATCH(D35,$D$13:$D$28,0)) -> #REF! | D35: {=_xlfn.UNIQUE(D13:D28)} -> #REF! | F35: =SUMIFS(#REF!,#REF!,D35) -> #REF! | G35: =F35/$F$43 -> #REF! | H35: 0.78110923 | I35: 0.63219195 | J35: 0.43335978 | K35: 0.7875556 | L35: 0.23317539 | M35: 0.66451085 | N35: 0.5 | O35: 0.5 | P35: 0 | Q35: 0 | R35: 0 | S35: 0 | T35: =SUM(N35:S35)=1 -> TRUE | U35: =SUMPRODUCT(H35:M35,N35:S35) -> 0.70665059 | V35: =INDEX(#REF!,MATCH($D35,_xlfn.ANCHORARRAY(#REF!),0)) -> #REF! | W35: =INDEX(#REF!,MATCH($D35,_xlfn.ANCHORARRAY(#REF!),0))+INDEX(#REF!,MATCH($D35,_xlfn.ANCHORARRAY(#REF!),0)) -> #REF! | X35: 0.0125 | Y35: 0 | Z35: 0 | AA35: =U35*BC35+U35*BD35*(1+V35)+SUM(W35:Z35) -> #REF! | AB35: 0 | AC35: =AA35+AB35 -> #REF! | AD35: 0.012 | AE35: =AC35+AD35 -> #REF! | AF35: =0.7/AE35 -> #REF! | AG35: =IFERROR(F35/AY35,0) -> 0 | AH35: =(1-AE35-($AU35-$AV35)+($AT35*(1-$AU35))-$AS35)/(($AX35*$AW35*(1-$AU35))/$AX35) -> #REF! | AJ35: {=IFERROR(SUMPRODUCT(AJ$13:AJ$28,$G$13:$G$28,--($D35=$D$13:$D$28))/$G35,0)} -> 0 | AK35: {=IFERROR(SUMPRODUCT(AK$13:AK$28,$G$13:$G$28,--($D35=$D$13:$D$28))/$G35,0)} -> 0 | AL35: 0.788 | AM35: =0.7/AL35 -> 0.88832487 | AN35: =IFERROR(F35/AZ35,0) -> 0 | AO35: =(1-AL35-($AU35-$AV35)+($AT35*(1-$AU35))-$AS35)/(($AX35*$AW35*(1-$AU35))/$AX35) -> #DIV/0! | AQ35: =F35*AE35 -> #REF! | AR35: =F35*AL35 -> #REF! | AS35: =IFERROR(INDEX(#REF!,MATCH($C35,#REF!,0)),0) -> 0 | AT35: =IFERROR(INDEX(#REF!,MATCH($C35,#REF!,0)),0) -> 0 | AU35: =IFERROR(INDEX(#REF!,MATCH($C35,#REF!,0)),0) -> 0 | AV35: =IFERROR(INDEX(#REF!,MATCH($C35,#REF!,0)),0) -> 0 | AW35: =IFERROR(INDEX(#REF!,MATCH($C35,#REF!,0)),0) -> 0 | AX35: =IFERROR(INDEX(#REF!,MATCH($C35,#REF!,0)),0) -> 0 | AY35: =AQ35/(1-AS35-(AU35-AV35)+AT35*(1-AU35)-AX35*AW35*(1-AU35)) -> #REF! | AZ35: =AR35/(1-AS35-(AU35-AV35)+AT35*(1-AU35)-AX35*AW35*(1-AU35)) -> #REF! | BA35: =IF($C$7="Business Plan",0,"placeholder") -> 0 | BB35: =IF($C$7="Business Plan",0,"placeholder") -> 0 | BC35: =IF($C$7="Business Plan",INDEX(#REF!,MATCH($D35,_xlfn.ANCHORARRAY(#REF!),0))/(INDEX(#REF!,MATCH($D35,_xlfn.ANCHORARRAY(#REF!),0))+INDEX(#REF!,MATCH($D35,_xlfn.ANCHORARRAY(#REF!),0))),BA35+BB35) -> #REF! | BD35: =IF($C$7="Business Plan",1-BC35,0) -> #REF! | BF35: =BA35*$AE35 -> #REF! | BG35: =BB35*$AE35 -> #REF! | BH35: =BC35*$AE35 -> #REF! | BI35: =BD35*$AE35 -> #REF!
B36: =1+B35 -> 2 | C36: =INDEX($C$13:$C$28,MATCH(D36,$D$13:$D$28,0)) -> #N/A | F36: =SUMIFS(#REF!,#REF!,D36) -> #REF! | G36: =F36/$F$43 -> #REF! | H36: 0.39546096 | I36: 0.79104886 | J36: 0.50913942 | K36: 0.50651758 | L36: 0.7892051 | M36: 0.86205085 | N36: 0.5 | O36: 0.5 | P36: 0 | Q36: 0 | R36: 0 | S36: 0 | T36: =SUM(N36:S36)=1 -> TRUE | U36: =SUMPRODUCT(H36:M36,N36:S36) -> 0.59325491 | V36: =INDEX(#REF!,MATCH($D36,_xlfn.ANCHORARRAY(#REF!),0)) -> #REF! | W36: =INDEX(#REF!,MATCH($D36,_xlfn.ANCHORARRAY(#REF!),0))+INDEX(#REF!,MATCH($D36,_xlfn.ANCHORARRAY(#REF!),0)) -> #REF! | X36: 0.0125 | Y36: 0 | Z36: 0 | AA36: =U36*BC36+U36*BD36*(1+V36)+SUM(W36:Z36) -> #REF! | AB36: 0 | AC36: =AA36+AB36 -> #REF! | AD36: 0.012 | AE36: =AC36+AD36 -> #REF! | AF36: =0.7/AE36 -> #REF! | AG36: =IFERROR(F36/AY36,0) -> 0 | AH36: =(1-AE36-($AU36-$AV36)+($AT36*(1-$AU36))-$AS36)/(($AX36*$AW36*(1-$AU36))/$AX36) -> #REF! | AJ36: {=IFERROR(SUMPRODUCT(AJ$13:AJ$28,$G$13:$G$28,--($D36=$D$13:$D$28))/$G36,0)} -> 0 | AK36: {=IFERROR(SUMPRODUCT(AK$13:AK$28,$G$13:$G$28,--($D36=$D$13:$D$28))/$G36,0)} -> 0 | AL36: {=IFERROR(SUMPRODUCT(AL$13:AL$28,$G$13:$G$28,--($D36=$D$13:$D$28))/$G36,0)} -> 0 | AM36: =0.7/AL36 -> #DIV/0! | AN36: =IFERROR(F36/AZ36,0) -> 0 | AO36: =(1-AL36-($AU36-$AV36)+($AT36*(1-$AU36))-$AS36)/(($AX36*$AW36*(1-$AU36))/$AX36) -> #DIV/0! | AQ36: =F36*AE36 -> #REF! | AR36: =F36*AL36 -> #REF! | AS36: =IFERROR(INDEX(#REF!,MATCH($C36,#REF!,0)),0) -> 0 | AT36: =IFERROR(INDEX(#REF!,MATCH($C36,#REF!,0)),0) -> 0 | AU36: =IFERROR(INDEX(#REF!,MATCH($C36,#REF!,0)),0) -> 0 | AV36: =IFERROR(INDEX(#REF!,MATCH($C36,#REF!,0)),0) -> 0 | AW36: =IFERROR(INDEX(#REF!,MATCH($C36,#REF!,0)),0) -> 0 | AX36: =IFERROR(INDEX(#REF!,MATCH($C36,#REF!,0)),0) -> 0 | AY36: =AQ36/(1-AS36-(AU36-AV36)+AT36*(1-AU36)-AX36*AW36*(1-AU36)) -> #REF! | AZ36: =AR36/(1-AS36-(AU36-AV36)+AT36*(1-AU36)-AX36*AW36*(1-AU36)) -> #REF! | BA36: =IF($C$7="Business Plan",0,"placeholder") -> 0 | BB36: {=IFERROR(SUMPRODUCT(BB$13:BB$28,$G$13:$G$28,--($D36=$D$13:$D$28))/$G36,0)} -> 0 | BC36: =IF($C$7="Business Plan",INDEX(#REF!,MATCH($D36,_xlfn.ANCHORARRAY(#REF!),0))/(INDEX(#REF!,MATCH($D36,_xlfn.ANCHORARRAY(#REF!),0))+INDEX(#REF!,MATCH($D36,_xlfn.ANCHORARRAY(#REF!),0))),BA36+BB36) -> #REF! | BD36: {=IFERROR(SUMPRODUCT(BD$13:BD$28,$G$13:$G$28,--($D36=$D$13:$D$28))/$G36,0)} -> 0 | BF36: =BA36*$AE36 -> #REF! | BG36: =BB36*$AE36 -> #REF! | BH36: =BC36*$AE36 -> #REF! | BI36: =BD36*$AE36 -> #REF!
